Workbook

Sheet Cover
B1: Pernod Ricard SA — Equity Research Summary
A3: Company | B3: Pernod Ricard SA
A4: Ticker | B4: RI FP (Euronext Paris)
A5: Sector | B5: Spirits & Wine
A6: Valuation date | B6: =TODAY() -> 46196
A7: Recommendation | B7: BUY
A8: Current price (€) | B8: =WACC!B14 -> 64.14
A9: Target price (€) | B9: =B16 -> 107.90737
A10: Upside / (downside) | B10: =B9/B8-1 -> 0.68237243
A11: TARGET PRICE METHODOLOGY
A12: DCF (avg Gordon/Exit) | B12: =(Bridge!B10+Bridge!C10)/2 -> 93.938556 | C12: 0.5
A13: Trading Comps (median) | B13: =Trading_Comps!B25 -> 105.05704 | C13: 0.35
A14: Precedent Transactions (median) | B14: =Precedent_Transactions!B21 -> 161.12085 | C14: 0.15
A15: Weights check | B15: =SUM(C12:C14) -> 1
A16: Target price (€) | B16: =SUMPRODUCT(B12:B14,C12:C14) -> 107.90737
A17: VALUATION SUMMARY (€/share)
A18: DCF — Gordon | B18: =Bridge!B10 -> 88.463227
A19: DCF — Exit | B19: =Bridge!C10 -> 99.413885
A20: Trading Comps (median) | B20: =Trading_Comps!B25 -> 105.05704
A21: Precedent Transactions (median) | B21: =Precedent_Transactions!B21 -> 161.12085
A22: 52-week low / high | B22: =Data!B6 -> 58.6 | C22: =Data!B7 -> 107.45
A23: Analyst consensus | B23: 86.5
A24: KEY STATISTICS
A25: Market cap (€m) | B25: =WACC!B16 -> 16136.983
A26: Net debt (€m) | B26: =WACC!B17 -> 11168
A27: Enterprise value (€m) | B27: =B25+B26 -> 27304.983
A28: Shares outstanding (m) | B28: =WACC!B15 -> 251.59
A29: Disclaimer | B29: Educational use only — not investment advice. Built on public filings.

Sheet Data
A1: field | B1: value | C1: unit | D1: currency | E1: as_of_date | F1: source | G1: auto
A2: share_price | B2: 64.14 | C2: per_share | D2: EUR | E2: 46192 | F2: PR IR - Share & Debt | G2: Y
A3: shares_outstanding | B3: 251.59 | C3: million | F3: URD | G3: N
A4: isin | B4: FR0000120693 | E4: 46192 | F4: PR IR - Share & Debt | G4: N
A5: ticker_bbg | B5: RI FP | F5: PR IR - Share & Debt | G5: N
A6: 52w_low | B6: 58.6 | C6: per_share | D6: EUR | E6: 46192 | F6: market | G6: Y
A7: 52w_high | B7: 107.45 | C7: per_share | D7: EUR | E7: 46192 | F7: market | G7: Y
A8: beta_raw | B8: 0.38 | E8: 46192 | F8: market | G8: Y
A9: dps_fy25 | B9: 4.7 | C9: per_share | D9: EUR | E9: FY25 | F9: H1 FY26 release | G9: N
A10: net_debt | B10: 11168 | C10: million | D10: EUR | E10: 46022 | F10: H1 FY26 release | G10: N
A11: cost_of_debt_avg | B11: 3.2 | C11: % | E11: FY25 | F11: consolidated FS | G11: N
A12: cost_of_debt_marginal | B12: 3.25-3.75 | C12: % | E12: 2025-11 | F12: bond table | G12: N
A13: risk_free_rate | B13: 3.74 | C13: % | E13: 46192 | F13: OAT 10Y France | G13: Y
A14: erp_france | B14: 5.5 | C14: % | E14: 2026-06 | F14: damodaran | G14: Y
A15: effective_tax_rate | C15: % | E15: FY25 | F15: URD | G15: N
A16: credit_rating_sp | B16: BBB+ | E16: 45838 | F16: PRIF FS | G16: N
A17: credit_rating_moodys | B17: Baa1 | E17: 45838 | F17: PRIF FS | G17: N

Sheet Assumptions
B1: Pernod Ricard SA — Key Assumptions
A3: Driver | B3: FY26E | C3: FY27E | D3: FY28E | E3: FY29E | F3: FY30E
A4: Revenue growth — organic (% YoY)
A5: Americas growth % | B5: -0.09 | C5: 0.02 | D5: 0.04 | E5: 0.05 | F5: 0.04
A6: Asia / Rest of World growth % | B6: -0.01 | C6: 0.03 | D6: 0.05 | E6: 0.06 | F6: 0.05
A7: Europe growth % | B7: -0.01 | C7: 0.01 | D7: 0.02 | E7: 0.02 | F7: 0.02
A8: Profitability (% of net sales)
A9: Gross margin % | B9: 0.59 | C9: 0.59 | D9: 0.595 | E9: 0.595 | F9: 0.6
A10: A&P % of sales | B10: 0.16 | C10: 0.16 | D10: 0.16 | E10: 0.16 | F10: 0.16
A11: Structure costs % of sales | B11: 0.16 | C11: 0.157 | D11: 0.155 | E11: 0.152 | F11: 0.15
A12: Cash flow drivers
A13: D&A % of sales | B13: 0.038 | C13: 0.038 | D13: 0.038 | E13: 0.038 | F13: 0.038
A14: Capex % of sales | B14: 0.055 | C14: 0.053 | D14: 0.05 | E14: 0.05 | F14: 0.05
A15: Change in NWC % of sales | B15: -0.025 | C15: -0.025 | D15: -0.02 | E15: -0.02 | F15: -0.02
A16: Tax rate (normalised) % | B16: 0.25 | C16: 0.25 | D16: 0.25 | E16: 0.25 | F16: 0.25
A17: Terminal value
A18: Perpetuity growth rate g % | B18: 0.015
A19: Exit EV/EBITDA multiple | B19: 11

Sheet Income_Statement
B1: Pernod Ricard SA - Consolidated Income Statement (€m, FYE 30 June)
A3: € millions | B3: FY23 | C3: FY24 | D3: FY25
A4: Net sales | B4: 12137 | C4: 11598 | D4: 10959
A5: Cost of sales | B5: -4891 | C5: -4623 | D5: -4443
A6: Gross margin after logistics | B6: =B4+B5 -> 7246 | C6: =C4+C5 -> 6975 | D6: =D4+D5 -> 6516
A7: Advertising & promotion | B7: -1939 | C7: -1872 | D7: -1679
A8: Contribution after A&P | B8: =B6+B7 -> 5307 | C8: =C6+C7 -> 5103 | D8: =D6+D7 -> 4837
A9: Structure costs | B9: -1959 | C9: -1987 | D9: -1886
A10: Profit from recurring operations | B10: =B8+B9 -> 3348 | C10: =C8+C9 -> 3116 | D10: =D8+D9 -> 2951
A11: Other operating income/(expenses) | B11: -83 | C11: -392 | D11: -208
A12: Operating profit (reported) | B12: =B10+B11 -> 3265 | C12: =C10+C11 -> 2724 | D12: =D10+D11 -> 2743
A13: Financial income/(expenses) | B13: -327 | C13: -437 | D13: -492
A14: Corporate income tax | B14: -651 | C14: -766 | D14: -574
A15: Share of associates | B15: -4 | C15: -7 | D15: -3
A16: Net profit | B16: =B12+B13+B14+B15 -> 2283 | C16: =C12+C13+C14+C15 -> 1514 | D16: =D12+D13+D14+D15 -> 1674
A17: o/w non-controlling interests | B17: 21 | C17: 38 | D17: 48
A18: Group share of net profit | B18: =B16-B17 -> 2262 | C18: =C16-C17 -> 1476 | D18: =D16-D17 -> 1626
A19: Diluted shares (m) | B19: 256.878 | C19: 253.188 | D19: 252.011
A20: Diluted EPS (€) | B20: =B18/B19 -> 8.8057366 | C20: =C18/C19 -> 5.8296602 | D20: =D18/D19 -> 6.4520993
A22: Depreciation of fixed assets | B22: 417 | C22: 441 | D22: 422
A23: EBITDA (= PRO + D&A) | B23: =B10+B22 -> 3765 | C23: =C10+C22 -> 3557 | D23: =D10+D22 -> 3373
A24: Net sales growth % | C24: =C4/B4-1 -> -0.044409656 | D24: =D4/C4-1 -> -0.055095706
A25: Gross margin % | B25: =B6/B4 -> 0.59701738 | C25: =C6/C4 -> 0.60139679 | D25: =D6/D4 -> 0.5945798
A26: PRO margin % | B26: =B10/B4 -> 0.2758507 | C26: =C10/C4 -> 0.26866701 | D26: =D10/D4 -> 0.26927639
A27: EBITDA margin % | B27: =B23/B4 -> 0.31020845 | C27: =C23/C4 -> 0.30669081 | D27: =D23/D4 -> 0.30778356
A28: Effective tax rate % | B28: =-B14/(B12+B13) -> 0.22157931 | C28: =-C14/(C12+C13) -> 0.3349366 | D28: =-D14/(D12+D13) -> 0.25499778

Sheet DCF
B1: Pernod Ricard SA — DCF Model
A3: €m | B3: FY25A | C3: FY26E | D3: FY27E | E3: FY28E | F3: FY29E | G3: FY30E
A4: Net sales by region — reported FY25
A5: Americas | B5: 3154
A6: Asia / Rest of World | B6: 4635
A7: Europe | B7: 3170
A8: Total reported | B8: =SUM(B5:B7) -> 10959
A9: Disposal rebasing (Wines & Imperial Blue)
A10: Disposal adjustment % | B10: -0.048
A11: Net sales — continuing & projected
A12: Americas | B12: =B5*(1+$B$10) -> 3002.608 | C12: =B12*(1+Assumptions!B5) -> 2732.3733 | D12: =C12*(1+Assumptions!C5) -> 2787.0207 | E12: =D12*(1+Assumptions!D5) -> 2898.5016 | F12: =E12*(1+Assumptions!E5) -> 3043.4267 | G12: =F12*(1+Assumptions!F5) -> 3165.1637
A13: Asia / Rest of World | B13: =B6*(1+$B$10) -> 4412.52 | C13: =B13*(1+Assumptions!B6) -> 4368.3948 | D13: =C13*(1+Assumptions!C6) -> 4499.4466 | E13: =D13*(1+Assumptions!D6) -> 4724.419 | F13: =E13*(1+Assumptions!E6) -> 5007.8841 | G13: =F13*(1+Assumptions!F6) -> 5258.2783
A14: Europe | B14: =B7*(1+$B$10) -> 3017.84 | C14: =B14*(1+Assumptions!B7) -> 2987.6616 | D14: =C14*(1+Assumptions!C7) -> 3017.5382 | E14: =D14*(1+Assumptions!D7) -> 3077.889 | F14: =E14*(1+Assumptions!E7) -> 3139.4468 | G14: =F14*(1+Assumptions!F7) -> 3202.2357
A15: Total net sales | B15: =SUM(B12,B13,B14) -> 10432.968 | C15: =SUM(C12,C13,C14) -> 10088.43 | D15: =SUM(D12,D13,D14) -> 10304.006 | E15: =SUM(E12,E13,E14) -> 10700.81 | F15: =SUM(F12,F13,F14) -> 11190.758 | G15: =SUM(G12,G13,G14) -> 11625.678
A17: Net sales | C17: =C15 -> 10088.43 | D17: =D15 -> 10304.006 | E17: =E15 -> 10700.81 | F17: =F15 -> 11190.758 | G17: =G15 -> 11625.678
A18: Gross margin | C18: =C17*Assumptions!B9 -> 5952.1735 | D18: =D17*Assumptions!C9 -> 6079.3633 | E18: =E17*Assumptions!D9 -> 6366.9817 | F18: =F17*Assumptions!E9 -> 6658.5007 | G18: =G17*Assumptions!F9 -> 6975.4066
A19: A&P | C19: =-C17*Assumptions!B10 -> -1614.1487 | D19: =-D17*Assumptions!C10 -> -1648.6409 | E19: =-E17*Assumptions!D10 -> -1712.1295 | F19: =-F17*Assumptions!E10 -> -1790.5212 | G19: =-G17*Assumptions!F10 -> -1860.1084
A20: Structure costs | C20: =-C17*Assumptions!B11 -> -1614.1487 | D20: =-D17*Assumptions!C11 -> -1617.7289 | E20: =-E17*Assumptions!D11 -> -1658.6255 | F20: =-F17*Assumptions!E11 -> -1700.9951 | G20: =-G17*Assumptions!F11 -> -1743.8517
A21: PRO (EBIT) | C21: =C18+C19+C20 -> 2723.876 | D21: =D18+D19+D20 -> 2812.9935 | E21: =E18+E19+E20 -> 2996.2267 | F21: =F18+F19+F20 -> 3166.9844 | G21: =G18+G19+G20 -> 3371.4465
A23: NOPAT | C23: =C21*(1-Assumptions!B16) -> 2042.907 | D23: =D21*(1-Assumptions!C16) -> 2109.7451 | E23: =E21*(1-Assumptions!D16) -> 2247.17 | F23: =F21*(1-Assumptions!E16) -> 2375.2383 | G23: =G21*(1-Assumptions!F16) -> 2528.5849
A24: (+) D&A | C24: =C17*Assumptions!B13 -> 383.36033 | D24: =D17*Assumptions!C13 -> 391.55221 | E24: =E17*Assumptions!D13 -> 406.63076 | F24: =F17*Assumptions!E13 -> 425.24879 | G24: =G17*Assumptions!F13 -> 441.77575
A25: (−) Capex | C25: =-C17*Assumptions!B14 -> -554.86363 | D25: =-D17*Assumptions!C14 -> -546.1123 | E25: =-E17*Assumptions!D14 -> -535.04048 | F25: =-F17*Assumptions!E14 -> -559.53788 | G25: =-G17*Assumptions!F14 -> -581.28389
A26: (+/−) Change in NWC | C26: =C17*Assumptions!B15 -> -252.21074 | D26: =D17*Assumptions!C15 -> -257.60014 | E26: =E17*Assumptions!D15 -> -214.01619 | F26: =F17*Assumptions!E15 -> -223.81515 | G26: =G17*Assumptions!F15 -> -232.51355
A27: Unlevered FCF | C27: =C23+C24+C25+C26 -> 1619.193 | D27: =D23+D24+D25+D26 -> 1697.5849 | E27: =E23+E24+E25+E26 -> 1904.7441 | F27: =F23+F24+F25+F26 -> 2017.134 | G27: =G23+G24+G25+G26 -> 2156.5632
A29: Discount period (n) | C29: 1 | D29: 2 | E29: 3 | F29: 4 | G29: 5
A30: Discount factor | C30: =1/(1+WACC!$B$21)^C29 -> 0.93235759 | D30: =1/(1+WACC!$B$21)^D29 -> 0.86929067 | E30: =1/(1+WACC!$B$21)^E29 -> 0.81048975 | F30: =1/(1+WACC!$B$21)^F29 -> 0.75566627 | G30: =1/(1+WACC!$B$21)^G29 -> 0.70455118
A31: PV of FCF | C31: =C27*C30 -> 1509.6668 | D31: =D27*D30 -> 1475.6947 | E31: =E27*E30 -> 1543.7756 | F31: =F27*F30 -> 1524.2802 | G31: =G27*G30 -> 1519.4092
A33: PV of explicit FCF | B33: =SUM(C31:G31) -> 7572.8265
A34: Terminal value (Gordon) | B34: =G27*(1+Assumptions!B$18)/(WACC!B21-Assumptions!B$18) -> 38035.047
A35: EBITDA FY30 | B35: =G21+G24 -> 3813.2223
A36: Terminal value (exit) | B36: =B35*Assumptions!B19 -> 41945.445
A37: Enterprise Value (Gordon) | B37: =B33+B34*G30 -> 34370.463
A38: Enterprise Value (Exit) | B38: =B33+B36*G30 -> 37125.539
A41: Year | B41: FY23 | C41: FY24 | D41: FY25 | E41: FY26E | F41: FY27E | G41: FY28E | H41: FY29E | I41: FY30E
A42: Revenue | B42: =Income_Statement!B4 -> 12137 | C42: =Income_Statement!C4 -> 11598 | D42: =Income_Statement!D4 -> 10959 | E42: =C15 -> 10088.43 | F42: =D15 -> 10304.006 | G42: =E15 -> 10700.81 | H42: =F15 -> 11190.758 | I42: =G15 -> 11625.678
A43: PRO | B43: =Income_Statement!B10 -> 3348 | C43: =Income_Statement!C10 -> 3116 | D43: =Income_Statement!D10 -> 2951 | E43: =C21 -> 2723.876 | F43: =D21 -> 2812.9935 | G43: =E21 -> 2996.2267 | H43: =F21 -> 3166.9844 | I43: =G21 -> 3371.4465
A44: PRO margin | B44: =B43/B42 -> 0.2758507 | C44: =C43/C42 -> 0.26866701 | D44: =D43/D42 -> 0.26927639 | E44: =E43/E42 -> 0.27 | F44: =F43/F42 -> 0.273 | G44: =G43/G42 -> 0.28 | H44: =H43/H42 -> 0.283 | I44: =I43/I42 -> 0.29
A52: Year | E52: =E41 -> FY26E | F52: =F41 -> FY27E | G52: =G41 -> FY28E | H52: =H41 -> FY29E | I52: =I41 -> FY30E
A53: Net debt (opening) | E53: =WACC!B17 -> 11168 | F53: =E57 -> 10731.28 | G53: =F57 -> 10216.168 | H53: =G57 -> 9493.897 | I53: =H57 -> 8659.236
A54: (-) Free cash flow | E54: =-C27 -> -1619.193 | F54: =-D27 -> -1697.5849 | G54: =-E27 -> -1904.7441 | H54: =-F27 -> -2017.134 | I54: =-G27 -> -2156.5632
...

Sheet WACC
B1: Pernod Ricard SA — WACC Model
A3: Label | B3: Value
A4: Cost of equity
A5: Risk-free rate (rf) | B5: =Data!B13/100 -> 0.0374
A6: Equity risk premium (ERP) | B6: =Data!B14/100 -> 0.055
A7: Beta (β) | B7: 1.25
A8: Cost of equity (Ke) | B8: =B5+B7*B6 -> 0.10615
A9: Cost of debt
A10: Pre-tax cost of debt (Kd) | B10: =Data!B11/100 -> 0.032
A11: Tax rate | B11: 0.25
A12: After-tax cost of debt | B12: =B10*(1-B11) -> 0.024
A13: Capital structure
A14: Share price (€) | B14: 64.14
A15: Shares outstanding (m) | B15: 251.59
A16: Market cap (E) | B16: =B14*B15 -> 16136.983
A17: Net debt (D) | B17: 11168
A18: Total capital (V) | B18: =B16+B17 -> 27304.983
A19: Equity weight (E/V) | B19: =B16/B18 -> 0.5909904
A20: Debt weight (D/V) | B20: =B17/B18 -> 0.4090096
A21: WACC | B21: =B19*B8+B20*B12 -> 0.072549861

Sheet Bridge
B1: Pernod Ricard SA — EV to Equity Bridge
A3: €m | B3: Gordon Growth | C3: Exit Multiple
A4: Enterprise Value | B4: =DCF!B37 -> 34370.463 | C4: =DCF!B38 -> 37125.539
A5: (-) Net debt | B5: =-WACC!B17 -> -11168 | C5: =B5 -> -11168
A6: (-) Minority interest | B6: -1014 | C6: =B6 -> -1014
A7: (+) Investments in associates | B7: 68 | C7: =B7 -> 68
A8: Equity Value | B8: =SUM(B4:B7) -> 22256.463 | C8: =SUM(C4:C7) -> 25011.539
A9: Diluted shares (m) | B9: =WACC!B15 -> 251.59 | C9: =B9 -> 251.59
A10: Implied share price (€) | B10: =B8/B9 -> 88.463227 | C10: =C8/C9 -> 99.413885
A11: Current share price (€) | B11: =WACC!B14 -> 64.14 | C11: =B11 -> 64.14
A12: Implied upside/(downside) | B12: =B10/B11-1 -> 0.37922088 | C12: =C10/C11-1 -> 0.54995143

Sheet Sensitivity
B1: Pernod Ricard SA — DCF Sensitivity
A3: Implied share price (€) — Gordon | C3: Perpetuity growth (g) →
B4: WACC \ g | C4: 0.01 | D4: 0.015 | E4: 0.02 | F4: 0.025 | G4: 0.03
B5: 0.055 | C5: {=(SUMPRODUCT(DCF!$C$27:$G$27,(1+$B5)^(-DCF!$C$29:$G$29))+DCF!$G$27*(1+C$4)/($B5-C$4)*(1+$B5)^(-5)-WACC!$B$17+Bridge!$B$6+Bridge!$B$7)/WACC!$B$15} -> 130.69321 | D5: {=(SUMPRODUCT(DCF!$C$27:$G$27,(1+$B5)^(-DCF!$C$29:$G$29))+DCF!$G$27*(1+D$4)/($B5-D$4)*(1+$B5)^(-5)-WACC!$B$17+Bridge!$B$6+Bridge!$B$7)/WACC!$B$15} -> 149.91334 | E5: {=(SUMPRODUCT(DCF!$C$27:$G$27,(1+$B5)^(-DCF!$C$29:$G$29))+DCF!$G$27*(1+E$4)/($B5-E$4)*(1+$B5)^(-5)-WACC!$B$17+Bridge!$B$6+Bridge!$B$7)/WACC!$B$15} -> 174.62495 | F5: {=(SUMPRODUCT(DCF!$C$27:$G$27,(1+$B5)^(-DCF!$C$29:$G$29))+DCF!$G$27*(1+F$4)/($B5-F$4)*(1+$B5)^(-5)-WACC!$B$17+Bridge!$B$6+Bridge!$B$7)/WACC!$B$15} -> 207.57376 | G5: {=(SUMPRODUCT(DCF!$C$27:$G$27,(1+$B5)^(-DCF!$C$29:$G$29))+DCF!$G$27*(1+G$4)/($B5-G$4)*(1+$B5)^(-5)-WACC!$B$17+Bridge!$B$6+Bridge!$B$7)/WACC!$B$15} -> 253.70208
B6: 0.06 | C6: {=(SUMPRODUCT(DCF!$C$27:$G$27,(1+$B6)^(-DCF!$C$29:$G$29))+DCF!$G$27*(1+C$4)/($B6-C$4)*(1+$B6)^(-5)-WACC!$B$17+Bridge!$B$6+Bridge!$B$7)/WACC!$B$15} -> 112.42659 | D6: {=(SUMPRODUCT(DCF!$C$27:$G$27,(1+$B6)^(-DCF!$C$29:$G$29))+DCF!$G$27*(1+D$4)/($B6-D$4)*(1+$B6)^(-5)-WACC!$B$17+Bridge!$B$6+Bridge!$B$7)/WACC!$B$15} -> 127.51463 | E6: {=(SUMPRODUCT(DCF!$C$27:$G$27,(1+$B6)^(-DCF!$C$29:$G$29))+DCF!$G$27*(1+E$4)/($B6-E$4)*(1+$B6)^(-5)-WACC!$B$17+Bridge!$B$6+Bridge!$B$7)/WACC!$B$15} -> 146.37468 | F6: {=(SUMPRODUCT(DCF!$C$27:$G$27,(1+$B6)^(-DCF!$C$29:$G$29))+DCF!$G$27*(1+F$4)/($B6-F$4)*(1+$B6)^(-5)-WACC!$B$17+Bridge!$B$6+Bridge!$B$7)/WACC!$B$15} -> 170.62332 | G6: {=(SUMPRODUCT(DCF!$C$27:$G$27,(1+$B6)^(-DCF!$C$29:$G$29))+DCF!$G$27*(1+G$4)/($B6-G$4)*(1+$B6)^(-5)-WACC!$B$17+Bridge!$B$6+Bridge!$B$7)/WACC!$B$15} -> 202.95483
B7: 0.065 | C7: {=(SUMPRODUCT(DCF!$C$27:$G$27,(1+$B7)^(-DCF!$C$29:$G$29))+DCF!$G$27*(1+C$4)/($B7-C$4)*(1+$B7)^(-5)-WACC!$B$17+Bridge!$B$6+Bridge!$B$7)/WACC!$B$15} -> 97.487544 | D7: {=(SUMPRODUCT(DCF!$C$27:$G$27,(1+$B7)^(-DCF!$C$29:$G$29))+DCF!$G$27*(1+D$4)/($B7-D$4)*(1+$B7)^(-5)-WACC!$B$17+Bridge!$B$6+Bridge!$B$7)/WACC!$B$15} -> 109.60211 | E7: {=(SUMPRODUCT(DCF!$C$27:$G$27,(1+$B7)^(-DCF!$C$29:$G$29))+DCF!$G$27*(1+E$4)/($B7-E$4)*(1+$B7)^(-5)-WACC!$B$17+Bridge!$B$6+Bridge!$B$7)/WACC!$B$15} -> 124.40879 | F7: {=(SUMPRODUCT(DCF!$C$27:$G$27,(1+$B7)^(-DCF!$C$29:$G$29))+DCF!$G$27*(1+F$4)/($B7-F$4)*(1+$B7)^(-5)-WACC!$B$17+Bridge!$B$6+Bridge!$B$7)/WACC!$B$15} -> 142.91715 | G7: {=(SUMPRODUCT(DCF!$C$27:$G$27,(1+$B7)^(-DCF!$C$29:$G$29))+DCF!$G$27*(1+G$4)/($B7-G$4)*(1+$B7)^(-5)-WACC!$B$17+Bridge!$B$6+Bridge!$B$7)/WACC!$B$15} -> 166.71361
B8: 0.07 | C8: {=(SUMPRODUCT(DCF!$C$27:$G$27,(1+$B8)^(-DCF!$C$29:$G$29))+DCF!$G$27*(1+C$4)/($B8-C$4)*(1+$B8)^(-5)-WACC!$B$17+Bridge!$B$6+Bridge!$B$7)/WACC!$B$15} -> 85.044042 | D8: {=(SUMPRODUCT(DCF!$C$27:$G$27,(1+$B8)^(-DCF!$C$29:$G$29))+DCF!$G$27*(1+D$4)/($B8-D$4)*(1+$B8)^(-5)-WACC!$B$17+Bridge!$B$6+Bridge!$B$7)/WACC!$B$15} -> 94.952128 | E8: {=(SUMPRODUCT(DCF!$C$27:$G$27,(1+$B8)^(-DCF!$C$29:$G$29))+DCF!$G$27*(1+E$4)/($B8-E$4)*(1+$B8)^(-5)-WACC!$B$17+Bridge!$B$6+Bridge!$B$7)/WACC!$B$15} -> 106.84183 | F8: {=(SUMPRODUCT(DCF!$C$27:$G$27,(1+$B8)^(-DCF!$C$29:$G$29))+DCF!$G$27*(1+F$4)/($B8-F$4)*(1+$B8)^(-5)-WACC!$B$17+Bridge!$B$6+Bridge!$B$7)/WACC!$B$15} -> 121.37369 | G8: {=(SUMPRODUCT(DCF!$C$27:$G$27,(1+$B8)^(-DCF!$C$29:$G$29))+DCF!$G$27*(1+G$4)/($B8-G$4)*(1+$B8)^(-5)-WACC!$B$17+Bridge!$B$6+Bridge!$B$7)/WACC!$B$15} -> 139.53852
B9: 0.075 | C9: {=(SUMPRODUCT(DCF!$C$27:$G$27,(1+$B9)^(-DCF!$C$29:$G$29))+DCF!$G$27*(1+C$4)/($B9-C$4)*(1+$B9)^(-5)-WACC!$B$17+Bridge!$B$6+Bridge!$B$7)/WACC!$B$15} -> 74.520062 | D9: {=(SUMPRODUCT(DCF!$C$27:$G$27,(1+$B9)^(-DCF!$C$29:$G$29))+DCF!$G$27*(1+D$4)/($B9-D$4)*(1+$B9)^(-5)-WACC!$B$17+Bridge!$B$6+Bridge!$B$7)/WACC!$B$15} -> 82.748935 | E9: {=(SUMPRODUCT(DCF!$C$27:$G$27,(1+$B9)^(-DCF!$C$29:$G$29))+DCF!$G$27*(1+E$4)/($B9-E$4)*(1+$B9)^(-5)-WACC!$B$17+Bridge!$B$6+Bridge!$B$7)/WACC!$B$15} -> 92.473967 | F9: {=(SUMPRODUCT(DCF!$C$27:$G$27,(1+$B9)^(-DCF!$C$29:$G$29))+DCF!$G$27*(1+F$4)/($B9-F$4)*(1+$B9)^(-5)-WACC!$B$17+Bridge!$B$6+Bridge!$B$7)/WACC!$B$15} -> 104.144 | G9: {=(SUMPRODUCT(DCF!$C$27:$G$27,(1+$B9)^(-DCF!$C$29:$G$29))+DCF!$G$27*(1+G$4)/($B9-G$4)*(1+$B9)^(-5)-WACC!$B$17+Bridge!$B$6+Bridge!$B$7)/WACC!$B$15} -> 118.40738
B10: 0.08 | C10: {=(SUMPRODUCT(DCF!$C$27:$G$27,(1+$B10)^(-DCF!$C$29:$G$29))+DCF!$G$27*(1+C$4)/($B10-C$4)*(1+$B10)^(-5)-WACC!$B$17+Bridge!$B$6+Bridge!$B$7)/WACC!$B$15} -> 65.504164 | D10: {=(SUMPRODUCT(DCF!$C$27:$G$27,(1+$B10)^(-DCF!$C$29:$G$29))+DCF!$G$27*(1+D$4)/($B10-D$4)*(1+$B10)^(-5)-WACC!$B$17+Bridge!$B$6+Bridge!$B$7)/WACC!$B$15} -> 72.427771 | E10: {=(SUMPRODUCT(DCF!$C$27:$G$27,(1+$B10)^(-DCF!$C$29:$G$29))+DCF!$G$27*(1+E$4)/($B10-E$4)*(1+$B10)^(-5)-WACC!$B$17+Bridge!$B$6+Bridge!$B$7)/WACC!$B$15} -> 80.505313 | F10: {=(SUMPRODUCT(DCF!$C$27:$G$27,(1+$B10)^(-DCF!$C$29:$G$29))+DCF!$G$27*(1+F$4)/($B10-F$4)*(1+$B10)^(-5)-WACC!$B$17+Bridge!$B$6+Bridge!$B$7)/WACC!$B$15} -> 90.051498 | G10: {=(SUMPRODUCT(DCF!$C$27:$G$27,(1+$B10)^(-DCF!$C$29:$G$29))+DCF!$G$27*(1+G$4)/($B10-G$4)*(1+$B10)^(-5)-WACC!$B$17+Bridge!$B$6+Bridge!$B$7)/WACC!$B$15} -> 101.50692
B11: 0.085 | C11: {=(SUMPRODUCT(DCF!$C$27:$G$27,(1+$B11)^(-DCF!$C$29:$G$29))+DCF!$G$27*(1+C$4)/($B11-C$4)*(1+$B11)^(-5)-WACC!$B$17+Bridge!$B$6+Bridge!$B$7)/WACC!$B$15} -> 57.69463 | D11: {=(SUMPRODUCT(DCF!$C$27:$G$27,(1+$B11)^(-DCF!$C$29:$G$29))+DCF!$G$27*(1+D$4)/($B11-D$4)*(1+$B11)^(-5)-WACC!$B$17+Bridge!$B$6+Bridge!$B$7)/WACC!$B$15} -> 63.585244 | E11: {=(SUMPRODUCT(DCF!$C$27:$G$27,(1+$B11)^(-DCF!$C$29:$G$29))+DCF!$G$27*(1+E$4)/($B11-E$4)*(1+$B11)^(-5)-WACC!$B$17+Bridge!$B$6+Bridge!$B$7)/WACC!$B$15} -> 70.382107 | F11: {=(SUMPRODUCT(DCF!$C$27:$G$27,(1+$B11)^(-DCF!$C$29:$G$29))+DCF!$G$27*(1+F$4)/($B11-F$4)*(1+$B11)^(-5)-WACC!$B$17+Bridge!$B$6+Bridge!$B$7)/WACC!$B$15} -> 78.311779 | G11: {=(SUMPRODUCT(DCF!$C$27:$G$27,(1+$B11)^(-DCF!$C$29:$G$29))+DCF!$G$27*(1+G$4)/($B11-G$4)*(1+$B11)^(-5)-WACC!$B$17+Bridge!$B$6+Bridge!$B$7)/WACC!$B$15} -> 87.683211
A13: Implied share price (€) — Exit | C13: Exit EV/EBITDA →
B14: WACC \ x | C14: 10 | D14: 11 | E14: 12 | F14: 13 | G14: 14
B15: 0.055 | C15: {=(SUMPRODUCT(DCF!$C$27:$G$27,(1+$B15)^(-DCF!$C$29:$G$29))+DCF!$B$35*C$14*(1+$B15)^(-5)-WACC!$B$17+Bridge!$B$6+Bridge!$B$7)/WACC!$B$15} -> 99.458183 | D15: {=(SUMPRODUCT(DCF!$C$27:$G$27,(1+$B15)^(-DCF!$C$29:$G$29))+DCF!$B$35*D$14*(1+$B15)^(-5)-WACC!$B$17+Bridge!$B$6+Bridge!$B$7)/WACC!$B$15} -> 111.05494 | E15: {=(SUMPRODUCT(DCF!$C$27:$G$27,(1+$B15)^(-DCF!$C$29:$G$29))+DCF!$B$35*E$14*(1+$B15)^(-5)-WACC!$B$17+Bridge!$B$6+Bridge!$B$7)/WACC!$B$15} -> 122.65169 | F15: {=(SUMPRODUCT(DCF!$C$27:$G$27,(1+$B15)^(-DCF!$C$29:$G$29))+DCF!$B$35*F$14*(1+$B15)^(-5)-WACC!$B$17+Bridge!$B$6+Bridge!$B$7)/WACC!$B$15} -> 134.24845 | G15: {=(SUMPRODUCT(DCF!$C$27:$G$27,(1+$B15)^(-DCF!$C$29:$G$29))+DCF!$B$35*G$14*(1+$B15)^(-5)-WACC!$B$17+Bridge!$B$6+Bridge!$B$7)/WACC!$B$15} -> 145.8452
B16: 0.06 | C16: {=(SUMPRODUCT(DCF!$C$27:$G$27,(1+$B16)^(-DCF!$C$29:$G$29))+DCF!$B$35*C$14*(1+$B16)^(-5)-WACC!$B$17+Bridge!$B$6+Bridge!$B$7)/WACC!$B$15} -> 96.297662 | D16: {=(SUMPRODUCT(DCF!$C$27:$G$27,(1+$B16)^(-DCF!$C$29:$G$29))+DCF!$B$35*D$14*(1+$B16)^(-5)-WACC!$B$17+Bridge!$B$6+Bridge!$B$7)/WACC!$B$15} -> 107.62348 | E16: {=(SUMPRODUCT(DCF!$C$27:$G$27,(1+$B16)^(-DCF!$C$29:$G$29))+DCF!$B$35*E$14*(1+$B16)^(-5)-WACC!$B$17+Bridge!$B$6+Bridge!$B$7)/WACC!$B$15} -> 118.94929 | F16: {=(SUMPRODUCT(DCF!$C$27:$G$27,(1+$B16)^(-DCF!$C$29:$G$29))+DCF!$B$35*F$14*(1+$B16)^(-5)-WACC!$B$17+Bridge!$B$6+Bridge!$B$7)/WACC!$B$15} -> 130.2751 | G16: {=(SUMPRODUCT(DCF!$C$27:$G$27,(1+$B16)^(-DCF!$C$29:$G$29))+DCF!$B$35*G$14*(1+$B16)^(-5)-WACC!$B$17+Bridge!$B$6+Bridge!$B$7)/WACC!$B$15} -> 141.60092
B17: 0.065 | C17: {=(SUMPRODUCT(DCF!$C$27:$G$27,(1+$B17)^(-DCF!$C$29:$G$29))+DCF!$B$35*C$14*(1+$B17)^(-5)-WACC!$B$17+Bridge!$B$6+Bridge!$B$7)/WACC!$B$15} -> 93.22262 | D17: {=(SUMPRODUCT(DCF!$C$27:$G$27,(1+$B17)^(-DCF!$C$29:$G$29))+DCF!$B$35*D$14*(1+$B17)^(-5)-WACC!$B$17+Bridge!$B$6+Bridge!$B$7)/WACC!$B$15} -> 104.28505 | E17: {=(SUMPRODUCT(DCF!$C$27:$G$27,(1+$B17)^(-DCF!$C$29:$G$29))+DCF!$B$35*E$14*(1+$B17)^(-5)-WACC!$B$17+Bridge!$B$6+Bridge!$B$7)/WACC!$B$15} -> 115.34749 | F17: {=(SUMPRODUCT(DCF!$C$27:$G$27,(1+$B17)^(-DCF!$C$29:$G$29))+DCF!$B$35*F$14*(1+$B17)^(-5)-WACC!$B$17+Bridge!$B$6+Bridge!$B$7)/WACC!$B$15} -> 126.40992 | G17: {=(SUMPRODUCT(DCF!$C$27:$G$27,(1+$B17)^(-DCF!$C$29:$G$29))+DCF!$B$35*G$14*(1+$B17)^(-5)-WACC!$B$17+Bridge!$B$6+Bridge!$B$7)/WACC!$B$15} -> 137.47236
B18: 0.07 | C18: {=(SUMPRODUCT(DCF!$C$27:$G$27,(1+$B18)^(-DCF!$C$29:$G$29))+DCF!$B$35*C$14*(1+$B18)^(-5)-WACC!$B$17+Bridge!$B$6+Bridge!$B$7)/WACC!$B$15} -> 90.230331 | D18: {=(SUMPRODUCT(DCF!$C$27:$G$27,(1+$B18)^(-DCF!$C$29:$G$29))+DCF!$B$35*D$14*(1+$B18)^(-5)-WACC!$B$17+Bridge!$B$6+Bridge!$B$7)/WACC!$B$15} -> 101.0367 | E18: {=(SUMPRODUCT(DCF!$C$27:$G$27,(1+$B18)^(-DCF!$C$29:$G$29))+DCF!$B$35*E$14*(1+$B18)^(-5)-WACC!$B$17+Bridge!$B$6+Bridge!$B$7)/WACC!$B$15} -> 111.84307 | F18: {=(SUMPRODUCT(DCF!$C$27:$G$27,(1+$B18)^(-DCF!$C$29:$G$29))+DCF!$B$35*F$14*(1+$B18)^(-5)-WACC!$B$17+Bridge!$B$6+Bridge!$B$7)/WACC!$B$15} -> 122.64944 | G18: {=(SUMPRODUCT(DCF!$C$27:$G$27,(1+$B18)^(-DCF!$C$29:$G$29))+DCF!$B$35*G$14*(1+$B18)^(-5)-WACC!$B$17+Bridge!$B$6+Bridge!$B$7)/WACC!$B$15} -> 133.45581
B19: 0.075 | C19: {=(SUMPRODUCT(DCF!$C$27:$G$27,(1+$B19)^(-DCF!$C$29:$G$29))+DCF!$B$35*C$14*(1+$B19)^(-5)-WACC!$B$17+Bridge!$B$6+Bridge!$B$7)/WACC!$B$15} -> 87.31817 | D19: {=(SUMPRODUCT(DCF!$C$27:$G$27,(1+$B19)^(-DCF!$C$29:$G$29))+DCF!$B$35*D$14*(1+$B19)^(-5)-WACC!$B$17+Bridge!$B$6+Bridge!$B$7)/WACC!$B$15} -> 97.875557 | E19: {=(SUMPRODUCT(DCF!$C$27:$G$27,(1+$B19)^(-DCF!$C$29:$G$29))+DCF!$B$35*E$14*(1+$B19)^(-5)-WACC!$B$17+Bridge!$B$6+Bridge!$B$7)/WACC!$B$15} -> 108.43294 | F19: {=(SUMPRODUCT(DCF!$C$27:$G$27,(1+$B19)^(-DCF!$C$29:$G$29))+DCF!$B$35*F$14*(1+$B19)^(-5)-WACC!$B$17+Bridge!$B$6+Bridge!$B$7)/WACC!$B$15} -> 118.99033 | G19: {=(SUMPRODUCT(DCF!$C$27:$G$27,(1+$B19)^(-DCF!$C$29:$G$29))+DCF!$B$35*G$14*(1+$B19)^(-5)-WACC!$B$17+Bridge!$B$6+Bridge!$B$7)/WACC!$B$15} -> 129.54772
B20: 0.08 | C20: {=(SUMPRODUCT(DCF!$C$27:$G$27,(1+$B20)^(-DCF!$C$29:$G$29))+DCF!$B$35*C$14*(1+$B20)^(-5)-WACC!$B$17+Bridge!$B$6+Bridge!$B$7)/WACC!$B$15} -> 84.483605 | D20: {=(SUMPRODUCT(DCF!$C$27:$G$27,(1+$B20)^(-DCF!$C$29:$G$29))+DCF!$B$35*D$14*(1+$B20)^(-5)-WACC!$B$17+Bridge!$B$6+Bridge!$B$7)/WACC!$B$15} -> 94.79886 | E20: {=(SUMPRODUCT(DCF!$C$27:$G$27,(1+$B20)^(-DCF!$C$29:$G$29))+DCF!$B$35*E$14*(1+$B20)^(-5)-WACC!$B$17+Bridge!$B$6+Bridge!$B$7)/WACC!$B$15} -> 105.11411 | F20: {=(SUMPRODUCT(DCF!$C$27:$G$27,(1+$B20)^(-DCF!$C$29:$G$29))+DCF!$B$35*F$14*(1+$B20)^(-5)-WACC!$B$17+Bridge!$B$6+Bridge!$B$7)/WACC!$B$15} -> 115.42937 | G20: {=(SUMPRODUCT(DCF!$C$27:$G$27,(1+$B20)^(-DCF!$C$29:$G$29))+DCF!$B$35*G$14*(1+$B20)^(-5)-WACC!$B$17+Bridge!$B$6+Bridge!$B$7)/WACC!$B$15} -> 125.74463
B21: 0.085 | C21: {=(SUMPRODUCT(DCF!$C$27:$G$27,(1+$B21)^(-DCF!$C$29:$G$29))+DCF!$B$35*C$14*(1+$B21)^(-5)-WACC!$B$17+Bridge!$B$6+Bridge!$B$7)/WACC!$B$15} -> 81.724197 | D21: {=(SUMPRODUCT(DCF!$C$27:$G$27,(1+$B21)^(-DCF!$C$29:$G$29))+DCF!$B$35*D$14*(1+$B21)^(-5)-WACC!$B$17+Bridge!$B$6+Bridge!$B$7)/WACC!$B$15} -> 91.803954 | E21: {=(SUMPRODUCT(DCF!$C$27:$G$27,(1+$B21)^(-DCF!$C$29:$G$29))+DCF!$B$35*E$14*(1+$B21)^(-5)-WACC!$B$17+Bridge!$B$6+Bridge!$B$7)/WACC!$B$15} -> 101.88371 | F21: {=(SUMPRODUCT(DCF!$C$27:$G$27,(1+$B21)^(-DCF!$C$29:$G$29))+DCF!$B$35*F$14*(1+$B21)^(-5)-WACC!$B$17+Bridge!$B$6+Bridge!$B$7)/WACC!$B$15} -> 111.96347 | G21: {=(SUMPRODUCT(DCF!$C$27:$G$27,(1+$B21)^(-DCF!$C$29:$G$29))+DCF!$B$35*G$14*(1+$B21)^(-5)-WACC!$B$17+Bridge!$B$6+Bridge!$B$7)/WACC!$B$15} -> 122.04322

Sheet Trading_Comps
B1: Pernod Ricard SA — Trading Comparables
A3: Company | B3: Share price | C3: Shares (m) | D3: Market cap | E3: Net debt | F3: EV | G3: EBITDA | H3: Revenue | I3: Net income | J3: EV/EBITDA | K3: EV/Sales | L3: P/E | M3: Devise
A4: Diageo | B4: 80.45 | C4: 555.9 | D4: =B4*C4 -> 44722.155 | E4: 22080 | F4: =D4+E4 -> 66802.155 | G4: 6180 | H4: 19800 | I4: 2410 | J4: =F4/G4 -> 10.80941 | K4: =F4/H4 -> 3.3738462 | L4: =D4/I4 -> 18.556911 | M4: USD
A5: Rémy Cointreau | B5: 44.52 | C5: 52.37 | D5: =B5*C5 -> 2331.5124 | E5: 690 | F5: =D5+E5 -> 3021.5124 | G5: 200 | H5: 930 | I5: 70 | J5: =F5/G5 -> 15.107562 | K5: =F5/H5 -> 3.2489381 | L5: =D5/I5 -> 33.30732 | M5: EUR
A6: Campari (Davide Campari-Milano) | B6: 5.46 | C6: 1160 | D6: =B6*C6 -> 6333.6 | E6: 2600 | F6: =D6+E6 -> 8933.6 | G6: 700 | H6: 3000 | I6: 350 | J6: =F6/G6 -> 12.762286 | K6: =F6/H6 -> 2.9778667 | L6: =D6/I6 -> 18.096 | M6: EUR
A7: Brown-Forman | B7: 26.64 | C7: 459 | D7: =B7*C7 -> 12227.76 | E7: 2350 | F7: =D7+E7 -> 14577.76 | G7: 1210 | H7: 3920 | I7: 800 | J7: =F7/G7 -> 12.047736 | K7: =F7/H7 -> 3.7188163 | L7: =D7/I7 -> 15.2847 | M7: USD
A8: Becle (Jose Cuervo) | B8: 35 | C8: 3590 | D8: =B8*C8 -> 125650 | E8: 15000 | F8: =D8+E8 -> 140650 | G8: 8000 | H8: 40000 | I8: 5000 | J8: =F8/G8 -> 17.58125 | K8: =F8/H8 -> 3.51625 | L8: =D8/I8 -> 25.13 | M8: MXN
A9: Constellation Brands | B9: 140.61 | C9: 172.8 | D9: =B9*C9 -> 24297.408 | E9: 10470 | F9: =D9+E9 -> 34767.408 | G9: 3280 | H9: 9140 | I9: 1690 | J9: =F9/G9 -> 10.59982 | K9: =F9/H9 -> 3.803874 | L9: =D9/I9 -> 14.377164 | M9: USD
A10: Pernod Ricard (self) | B10: 64.14 | C10: 251.8 | D10: =B10*C10 -> 16150.452 | E10: 11200 | F10: =D10+E10 -> 27350.452 | G10: 3373 | H10: 10040 | I10: 1410 | J10: =F10/G10 -> 8.1086428 | K10: =F10/H10 -> 2.7241486 | L10: =D10/I10 -> 11.454221 | M10: EUR
A13: Median peers | J13: =MEDIAN(J4:J9) -> 12.405011 | K13: =MEDIAN(K4:K9) -> 3.4450481 | L13: =MEDIAN(L4:L9) -> 18.326455
A14: Mean | J14: =AVERAGE(J4:J9) -> 13.151344 | K14: =AVERAGE(K4:K9) -> 3.4399319 | L14: =AVERAGE(L4:L9) -> 20.792016
A15: Q1 | J15: =QUARTILE(J4:J9,1) -> 11.118992 | K15: =QUARTILE(K4:K9,1) -> 3.2801651 | L15: =QUARTILE(L4:L9,1) -> 15.987525
A16: Q3 | J16: =QUARTILE(J4:J9,3) -> 14.521243 | K16: =QUARTILE(K4:K9,3) -> 3.6681747 | L16: =QUARTILE(L4:L9,3) -> 23.486728
A19: Pernod EBITDA (FY26E) | B19: =DCF!C21+DCF!C24 -> 3107.2363
A20: Applied EV/EBITDA (median) | B20: =J13 -> 12.405011
A21: Implied EV | B21: =B19*B20 -> 38545.3
A22: (-) Net debt | B22: =-WACC!B17 -> -11168
A23: (-) Minorities (+) associates | B23: =Bridge!B6+Bridge!B7 -> -946
A24: Implied equity value | B24: =B21+B22+B23 -> 26431.3
A25: Implied share price (€) | B25: =B24/WACC!B15 -> 105.05704
A26: Implied price — Q1 | B26: =(B19*J15-WACC!B17+Bridge!B6+Bridge!B7)/WACC!B15 -> 89.17419
A27: Implied price — Q3 | B27: =(B19*J16-WACC!B17+Bridge!B6+Bridge!B7)/WACC!B15 -> 131.19335

Sheet Precedent_Transactions
B1: Pernod Ricard SA — Precedent Transactions
A3: Date | B3: Acquirer | C3: Target | D3: Deal EV | E3: Target EBITDA | F3: EV/EBITDA
A4: 2024 | B4: Campari | C4: Courvoisier (de Beam Suntory) | D4: 1220 | E4: 72 | F4: =D4/E4 -> 16.944444
A5: 2017 | B5: Diageo | C5: Casamigos
A6: 2016 | B6: Campari | C6: Grand Marnier | D6: 652 | E6: 47.4 | F6: =D6/E6 -> 13.755274
A7: 2014 | B7: Suntory | C7: Beam Inc. | D7: 16000 | E7: 780 | F7: =D7/E7 -> 20.512821
A8: 2008 | B8: Pernod Ricard | C8: Vin&Sprit (Absolut) | D8: 5690 | E8: 285 | F8: =D8/E8 -> 19.964912
A9: 2005 | B9: Pernod Ricard | C9: Allied Domecq | D9: 10700 | E9: 890 | F9: =D9/E9 -> 12.022472
A10: 2023 | B10: Campari | C10: Wilderness Trail
A12: Median | B12: =MEDIAN(F4:F10) -> 16.944444
A13: Mean | B13: =AVERAGE(F4:F10) -> 16.639985
A15: Pernod EBITDA (FY26E) | B15: =DCF!C21+DCF!C24 -> 3107.2363
A16: Applied EV/EBITDA (median) | B16: =B12 -> 16.944444
A17: Implied EV | B17: =B15*B16 -> 52650.394
A18: (-) Net debt | B18: =-WACC!B17 -> -11168
A19: (-) Minorities (+) associates | B19: =Bridge!B6+Bridge!B7 -> -946
A20: Implied equity value | B20: =B17+B18+B19 -> 40536.394
A21: Implied share price (€) | B21: =B20/WACC!B15 -> 161.12085

Sheet Football_Field
B1: Pernod Ricard SA — Valuation Summary
A3: Methodology | B3: Low | C3: High
A4: DCF — Gordon | B4: =Sensitivity!D9 -> 82.748935 | C4: =Sensitivity!D8 -> 94.952128
A5: DCF — Exit multiple | B5: =Sensitivity!D19 -> 97.875557 | C5: =Sensitivity!D18 -> 101.0367
A6: Trading Comps (EV/EBITDA) | B6: =Trading_Comps!B26 -> 89.17419 | C6: =Trading_Comps!B27 -> 131.19335
A7: Precedent Transactions | B7: =Precedent_Transactions!B21*0.85 -> 136.95272 | C7: =Precedent_Transactions!B21*1.15 -> 185.28897
A8: 52-week trading range | B8: =Data!B6 -> 58.6 | C8: =Data!B7 -> 107.45
A9: Analyst consensus | B9: 75 | C9: 100
