Workbook

Sheet Cover
B1: BNP Paribas SA - Equity Research Summary
A3: Company | B3: BNP Paribas SA
A4: Ticker | B4: BNP FP (Euronext Paris)
A5: Sector | B5: Banks (diversified European universal bank)
A6: Pricing date | B6: 46322
A7: Recommendation | B7: =IF(B10>=0.15,"BUY",IF(B10<=-0.1,"SELL","HOLD")) -> BUY
A8: Current price (EUR) | B8: =Data!$B$2 -> 83.52
A9: Target price (EUR, 12-month) | B9: =B16 -> 112.51651
A10: Upside / (downside) | B10: =B9/B8-1 -> 0.3471804
A11: TARGET PRICE METHODOLOGY | B11: EUR / share | C11: Weight
A12: Dividend discount (average excess-capital DDM / Gordon P/TBV) | B12: =(Bridge!B9+Bridge!C9)/2 -> 118.90303 | C12: 0.5
A13: Trading comps - P/TBV vs RoTE, French-adjusted | B13: =Trading_Comps!B32 -> 102.65555 | C13: 0.35
A14: Precedent transactions - P/TBV per RoTE point | B14: =Precedent_Transactions!B24 -> 114.23699 | C14: 0.15
A15: Weights check | B15: =SUM(C12:C14) -> 1
A16: Target price (EUR) | B16: =SUMPRODUCT(B12:B14,C12:C14) -> 112.51651
A17: VALUATION SUMMARY (EUR / share)
A18: Excess-capital DDM | B18: =Bridge!B9 -> 120.51859
A19: Gordon justified P/TBV | B19: =Bridge!C9 -> 117.28748
A20: Trading comps (base / full SocGen discount / no discount) | B20: =Trading_Comps!B32 -> 102.65555 | C20: =Trading_Comps!B33 -> 91.131756 | D20: =Trading_Comps!B34 -> 117.63648
A21: Precedent transactions (median / Q1 / Q3) | B21: =Precedent_Transactions!B24 -> 114.23699 | C21: =Precedent_Transactions!B25 -> 107.20702 | D21: =Precedent_Transactions!B26 -> 156.51141
A22: 2026 trading range (low / high) | B22: =Data!$B$7 -> 78.83 | C22: =Data!$B$8 -> 113.82
A23: Analyst consensus (avg / low / high) | B23: =Data!$B$40 -> 118.06 | C23: =Data!$B$41 -> 100 | D23: =Data!$B$42 -> 136
A24: Bear / bull scenario (DDM leg) | B24: =Sensitivity!F35 -> 97.144037 | C24: =Sensitivity!F37 -> 133.89384
A25: KEY STATISTICS
A26: Market cap (EUR m) | B26: =Data!$B$2*Data!$B$3 -> 91880.352
A27: P/TBV (Jun-26 TBVPS) | B27: =Cost_of_Equity!B23 -> 0.84878049
A28: P/E FY26E | B28: =B8/DDM!C39 -> 7.1214686
A29: P/E FY27E | B29: =B8/DDM!D39 -> 6.6550308
A30: Dividend yield FY26E (cash dividend only) | B30: =DDM!C41/B8 -> 0.070207046
A31: Total distribution yield FY27E (dividend + buyback) | B31: =DDM!D34/B26 -> 0.10981898
A32: RoTE FY26E / FY28E | B32: =DDM!C49 -> 0.12502485 | C32: =DDM!E49 -> 0.13668125
A33: Cost of equity (CAPM on OAT) | B33: =Cost_of_Equity!B9 -> 0.1179345
A34: Cost of equity implied by the share price | B34: =Cost_of_Equity!B14 -> 0.15942055
A35: CET1 ratio / requirement (Jun-26) | B35: =Data!$B$29 -> 0.13 | C35: =Data!$B$30 -> 0.1043
A36: Next catalyst | B36: 3Q26 results, 28-Oct-2026
A38: Disclaimer | B38: Educational use only - not investment advice. Built on public filings and consensus data as of 27-Oct-2026, before the 3Q26 release.
A39: Colour code | B39: Blue = hard-coded inputs | Green = links to other tabs | Black = formulas

Sheet Data
A1: field | B1: value | C1: unit | D1: currency | E1: as_of_date | F1: source | G1: auto
A2: share_price | B2: 83.52 | C2: per_share | D2: EUR | E2: 46322 | F2: Euronext Paris close 27-Oct-2026 (InvestSMART / Euronext) | G2: Y
A3: shares_current | B3: 1100.1 | C3: million | E3: 46265 | F3: BNP Paribas share capital disclosure Aug-2026: shares outstanding excl. treasury | G3: N
A4: shares_dec25 | B4: 1100 | C4: million | E4: 46022 | F4: BNP Paribas 4Q25 results: shares outstanding excl. treasury (1,117m issued) | G4: N
A5: isin | B5: FR0000131104 | F5: Euronext | G5: N
A6: ticker_bbg | B6: BNP FP | F6: Bloomberg | G6: N
A7: range_low_2026 | B7: 78.83 | C7: per_share | D7: EUR | E7: 46322 | F7: 2026 year-to-date low (Investing.com) | G7: Y
A8: range_high_2026 | B8: 113.82 | C8: per_share | D8: EUR | E8: 46322 | F8: 2026 year-to-date high, Aug-2026 (Investing.com) | G8: Y
A9: beta_raw | B9: 1.37 | E9: 46199 | F9: ABC Bourse: 1-year beta vs CAC 40 | G9: Y
A10: oat_10y | B10: 0.0493 | C10: % | E10: 46321 | F10: Banque de France: French OAT 10Y benchmark yield | G10: Y
A11: bund_10y | B11: 0.0337 | C11: % | E11: 46321 | F11: Bundesbank: German Bund 10Y yield (memo) | G11: Y
A12: erp | B12: 0.055 | C12: % | E12: 46296 | F12: Mature-market ERP + France premium (Damodaran), same as Pernod / LVMH models | G12: N
A13: eps_fy24 | B13: 9.57 | C13: per_share | D13: EUR | E13: 45657 | F13: BNP Paribas FY24 results (net of AT1 coupons) | G13: N
A14: eps_fy25 | B14: 10.29 | C14: per_share | D14: EUR | E14: 46022 | F14: BNP Paribas 4Q25 results (3-Feb-2026) | G14: N
A15: eps_h1_26 | B15: 6.45 | C15: per_share | D15: EUR | E15: 46203 | F15: BNP Paribas 2Q26 results (24-Jul-2026) | G15: N
A16: dps_fy25 | B16: 5.16 | C16: per_share | D16: EUR | E16: 46022 | F16: 2.59 interim (Oct-25) + 2.57 final (May-26) | G16: N
A17: interim_dps_fy26 | B17: 3.23 | C17: per_share | D17: EUR | E17: 46293 | F17: Interim = 50% of H1-26 EPS, paid 28-Sep-2026 | G17: N
A18: buyback_fy25 | B18: 1150 | C18: million | D18: EUR | E18: 46010 | F18: Share buyback on 2025 results, completed 19-Dec-2025 | G18: N
A19: at1_coupons_fy25 | B19: 711 | C19: million | D19: EUR | E19: 46022 | F19: Derived: net income 12,225 - EPS 10.29 x 1,119m average shares | G19: N
A20: tbvps_dec24 | B20: 93.7 | C20: per_share | D20: EUR | E20: 45657 | F20: Net tangible book value per share, 4Q24 slides | G20: N
A21: tbvps_dec25 | B21: 93.5 | C21: per_share | D21: EUR | E21: 46022 | F21: Net tangible book value per share, 4Q25 slides | G21: N
A22: tbvps_jun26 | B22: 98.4 | C22: per_share | D22: EUR | E22: 46203 | F22: Net tangible book value per share, 2Q26 slides | G22: N
A23: bvps_dec25 | B23: 104.3 | C23: per_share | D23: EUR | E23: 46022 | F23: Net book value per share, 4Q25 slides | G23: N
A24: te_rote_dec25 | B24: 100065 | C24: million | D24: EUR | E24: 46022 | F24: Tangible equity used for RoTE (net of distribution), 4Q25 slides | G24: N
A25: rote_fy24 | B25: 0.109 | C25: % | E25: 45657 | F25: Reported RoTE 2024 | G25: N
A26: rote_fy25 | B26: 0.116 | C26: % | E26: 46022 | F26: Reported RoTE 2025 | G26: N
A27: rote_q2_26 | B27: 0.133 | C27: % | E27: 46203 | F27: Reported RoTE 2Q26 | G27: N
A28: cet1_dec25 | B28: 0.126 | C28: % | E28: 46022 | F28: CET1 ratio, 4Q25 | G28: N
A29: cet1_jun26 | B29: 0.13 | C29: % | E29: 46203 | F29: CET1 ratio, 2Q26 | G29: N
A30: srep_cet1 | B30: 0.1043 | C30: % | E30: 46203 | F30: CET1 requirement (SREP + buffers), 2Q26 slides | G30: N
A31: leverage_jun26 | B31: 0.044 | C31: % | E31: 46203 | F31: Leverage ratio, 2Q26 | G31: N
A32: lcr_jun26 | B32: 1.49 | C32: % | E32: 46203 | F32: Liquidity coverage ratio, 2Q26 | G32: N
A33: rwa_dec25 | B33: 779 | C33: billion | D33: EUR | E33: 46022 | F33: Risk-weighted assets, 4Q25 | G33: N
A34: cor_q2_26_bp | B34: 39 | C34: bp | E34: 46203 | F34: Cost of risk in bp of customer loans, 2Q26 | G34: N
A35: france_rev_share | B35: 0.26 | C35: % | E35: 46266 | F35: France share of group revenues (RBC Capital Markets) | G35: N
A36: france_pbt_share | B36: 0.104 | C36: % | E36: 46022 | F36: France share of 2025 pre-tax income (BNP pre-3Q26 information note) | G36: N
A37: french_sov_exposure | B37: 20 | C37: billion | D37: EUR | E37: 46203 | F37: French sovereign bonds ~EUR 20bn, of which EUR 16bn at amortised cost (pre-3Q26 note) | G37: N
A38: guidance_rote_2026 | B38: 0.12 | C38: % | E38: 46227 | F38: 2026 guidance: RoTE ~12%, C/I ~60%, cost of risk < 40bp | G38: N
A39: guidance_rote_2028 | B39: 0.13 | C39: % | E39: 46056 | F39: 2028 targets: RoTE > 13%, C/I < 56%, NI CAGR 2025-28 > 10%, CET1 13% | G39: N
A40: consensus_tp_avg | B40: 118.06 | C40: per_share | D40: EUR | E40: 46295 | F40: Investing.com consensus target price (average) | G40: Y
...

Sheet Assumptions
B1: BNP Paribas - Key Assumptions
A3: Driver | B3: FY26E | C3: FY27E | D3: FY28E | E3: FY29E | F3: FY30E | G3: FY31E | H3: Rationale / source
A4: FY26E revenue build: H1-26 actual x full-year factor
A5: CPBS full-year factor (x H1-26) | B5: 2.01 | H5: French retail NII repricing offsets lighter Q4 fees; FY25 H2 slightly above H1
A6: IPS full-year factor (x H1-26) | B6: 2 | H6: Athlon consolidated from 31-Jul-26 offsets softer markets in Q3
A7: CIB full-year factor (x H1-26) | B7: 1.9 | H7: CIB H2 seasonally ~10% below a strong H1-26 (Q4 lighter in Global Markets)
A8: Corporate Centre H2-26E revenues (EUR m) | B8: -450 | H8: 2026 guidance: Corporate Centre GOI ~ -EUR 1.2bn; H1-26 revenues -96
A9: Revenue growth by division (% YoY) - FY26E column implied by the build above
A10: CPBS revenue growth | B10: =DDM!C5/DDM!B5-1 -> 0.037989669 | C10: 0.045 | D10: 0.045 | E10: 0.04 | F10: 0.035 | G10: 0.035 | H10: Deposit repricing, BNL / Belgium / Luxembourg, Personal Finance turnaround; consensus revenue CAGR 26-29E ~4.4%
A11: IPS revenue growth | B11: =DDM!C6/DDM!B6-1 -> 0.13205369 | C11: 0.06 | D11: 0.06 | E11: 0.05 | F11: 0.05 | G11: 0.045 | H11: AXA IM integration synergies, Cardif and wealth inflows
A12: CIB revenue growth | B12: =DDM!C7/DDM!B7-1 -> 0.052566195 | C12: 0.04 | D12: 0.04 | E12: 0.04 | F12: 0.035 | G12: 0.035 | H12: Financing and Global Markets share gains; below the 2022-25 trend
A13: Corporate Centre revenues (EUR m) | B13: =DDM!C8 -> -546 | C13: -500 | D13: -500 | E13: -500 | F13: -500 | G13: -500 | H13: Holding costs, treasury and eliminations held flat
A14: Operating leverage, risk and below-the-line items
A15: Cost / income ratio | B15: 0.595 | C15: 0.58 | D15: 0.563 | E15: 0.553 | F15: 0.545 | G15: 0.54 | H15: Guidance ~60% in 2026 and < 56% in 2028; Axone haircuts the 2028 target by ~30bp
A16: Customer loans, FY26E (EUR bn) | B16: 960 | H16: Calibrated so that 39bp = H1-26 annualised cost of risk (EUR 3.74bn)
A17: Loan growth | C17: 0.035 | D17: 0.035 | E17: 0.035 | F17: 0.035 | G17: 0.035 | H17: Nominal GDP plus modest share gains
A18: Cost of risk (bp of customer loans) | B18: 39 | C18: 40 | D18: 40 | E18: 40 | F18: 40 | G18: 40 | H18: Guidance < 40bp in 2026; Q2-26 39bp; through-the-cycle 40bp thereafter
A19: Other net losses (litigation), EUR m | B19: -444 | C19: -100 | D19: -100 | E19: -100 | F19: -100 | G19: -100 | H19: H1-26 -344; normalised -100 p.a. (Sudan litigation not provisioned, see risks)
A20: Non-operating items, EUR m | B20: 1835 | C20: 850 | D20: 850 | E20: 850 | F20: 850 | G20: 850 | H20: H1-26 1,435 incl. EUR 858m one-off gain; associates ~EUR 850m p.a.
A21: Effective tax rate | B21: 0.28 | C21: 0.275 | D21: 0.27 | E21: 0.27 | F21: 0.27 | G21: 0.27 | H21: 2026 guidance slightly above 27-28% (Q3 ~30%); French surtax assumed to fade from 2028
A22: Minority interests, EUR m | B22: 520 | C22: 541 | D22: 562 | E22: 585 | F22: 608 | G22: 633 | H22: FY25 633, H1-26 238; +4% p.a.
A23: AT1 coupons, EUR m | B23: 930 | C23: 950 | D23: 950 | E23: 950 | F23: 950 | G23: 950 | H23: H1-26 ~467 (7,562 - 6.45 x 1,100m) annualised; FY25 711
A24: Capital and distribution
A25: Risk-weighted assets, FY26E (EUR bn) | B25: 795 | H25: Jun-26 divisional RWA 774.5bn + Corporate Centre; Athlon -15bp and BMCI +15bp broadly offset
A26: RWA growth | C26: 0.035 | D26: 0.03 | E26: 0.03 | F26: 0.03 | G26: 0.03 | H26: Balance-sheet growth plus residual Basel IV / FRTB inflation
A27: CET1 target ratio | B27: 0.13 | C27: 0.13 | D27: 0.13 | E27: 0.13 | F27: 0.13 | G27: 0.13 | H27: 2028 plan target 13%; requirement 10.43%
A28: FY26E distribution (% of NI to ordinary shareholders) | B28: 0.6 | H28: 2026 results: 50% cash dividend + 10% buyback (BNP policy); minimum 60% from 2027
A29: Cash dividend payout (% of NI to ordinary shareholders) | B29: 0.5 | C29: 0.5 | D29: 0.5 | E29: 0.5 | F29: 0.5 | G29: 0.5 | H29: Policy floor; excess capital above the 13% CET1 target returned through buybacks
A30: Buyback execution price (x TBVPS) | B30: =Data!$B$2/Data!$B$22 -> 0.84878049 | H30: Buybacks executed at today's P/TBV (accretive to TBVPS while below 1.0x)
A31: Valuation
A32: Valuation date | B32: 46387 | H32: FY26E remaining distribution taken at t = 0; FY27E-FY31E distributions discounted at n = 1..5
A33: Long-term RoTE (terminal) | B33: 0.135 | H33: 2028 target > 13%; consensus 2029E 13.8%; fades from our FY31E 15%
A34: Long-term growth g | B34: 0.02 | H34: Nominal euro-area growth, long run
A35: FY26 interim dividend already paid (EUR / share) | B35: =Data!$B$17 -> 3.23 | H35: Paid 28-Sep-2026: excluded from the value (the share already trades ex-interim)
A37: Blue = hard-coded input (edit these). Green = link to another tab. Black = formula. Grey fill = key scenario levers.

Sheet Income_Statement
B1: BNP Paribas - Group Income Statement (EUR m, reported)
A3: EUR millions | B3: FY24A | C3: FY25A | D3: H1-25A | E3: H1-26A | F3: Source / comment
A4: Revenues | B4: 48831 | C4: 51223 | D4: 25541 | E4: 28147 | F4: Reported revenues
A5: Operating expenses and D&A | B5: -30193 | C5: -31374 | D5: -15489 | E5: -16696 | F5: Incl. restructuring (2026 guidance ~EUR 800m, 392 in H1-26)
A6: Gross operating income | B6: =B4+B5 -> 18638 | C6: =C4+C5 -> 19849 | D6: =D4+D5 -> 10052 | E6: =E4+E5 -> 11451
A7: Cost of risk | B7: -2999 | C7: -3350 | D7: -1650 | E7: -1871 | F7: Q2-26: 39bp of customer loans
A8: Other net losses for risk on financial instruments | B8: -202 | C8: -203 | D8: -115 | E8: -344 | F8: Mainly litigation
A9: Operating income | B9: =B6+B7+B8 -> 15437 | C9: =C6+C7+C8 -> 16296 | D9: =D6+D7+D8 -> 8287 | E9: =E6+E7+E8 -> 9236
A10: Non-operating items | B10: 751 | C10: 769 | D10: 510 | E10: 1435 | F10: H1-26: 459 associates + 976 gains (incl. EUR 858m Ageas / AGI)
A11: Pre-tax income | B11: =B9+B10 -> 16188 | C11: =C9+C10 -> 17065 | D11: =D9+D10 -> 8797 | E11: =E9+E10 -> 10671
A12: Corporate income tax | B12: -4001 | C12: -4207 | D12: -2288 | E12: -2871
A13: Net income attributable to minority interests | B13: -499 | C13: -633 | D13: -300 | E13: -238 | F13: FY figures derived (pre-tax - tax - group share)
A14: Net income, group share | B14: =B11+B12+B13 -> 11688 | C14: =C11+C12+C13 -> 12225 | D14: =D11+D12+D13 -> 6209 | E14: =E11+E12+E13 -> 7562
A15: Reported net income, group share (check) | B15: 11688 | C15: 12225 | D15: 6209 | E15: 7562 | F15: Press releases
A16: Difference (should be 0) | B16: =B14-B15 -> 0 | C16: =C14-C15 -> 0 | D16: =D14-D15 -> 0 | E16: =E14-E15 -> 0
A17: EPS, reported (EUR) | B17: 9.57 | C17: 10.29 | D17: 5.18 | E17: 6.45 | F17: Net of AT1 coupons
A19: Key ratios
A20: Revenue growth (YoY) | C20: =C4/B4-1 -> 0.048985276 | E20: =E4/D4-1 -> 0.10203203
A21: Cost / income ratio | B21: =-B5/B4 -> 0.61831623 | C21: =-C5/C4 -> 0.61249829 | D21: =-D5/D4 -> 0.60643671 | E21: =-E5/E4 -> 0.59317156
A22: Effective tax rate | B22: =-B12/B11 -> 0.24715839 | C22: =-C12/C11 -> 0.24652798 | D22: =-D12/D11 -> 0.26008867 | E22: =-E12/E11 -> 0.26904695
A23: RoTE, reported | B23: =Data!$B$25 -> 0.109 | C23: =Data!$B$26 -> 0.116 | F23: Q2-26 RoTE 13.3% (quarter)
A25: Revenues by division (EUR m)
A26: Division | B26: FY24A | C26: FY25A | E26: H1-26A | F26: Comment
A27: Commercial, Personal Banking & Services (CPBS) | B27: 26050 | C27: 26717 | E27: 13797 | F27: FY on Feb-26 published basis; H1-26 on Mar-26 restated basis
A28: Investment & Protection Services (IPS) | B28: 5793 | C28: 6929 | E28: 3922
A29: Corporate & Institutional Banking (CIB) | B29: 17993 | C29: 18997 | E29: 10524
A30: Corporate Centre & eliminations (residual) | B30: =B4-SUM(B27:B29) -> -1005 | C30: =C4-SUM(C27:C29) -> -1420 | E30: =E4-SUM(E27:E29) -> -96
A32: Pre-tax income by division (EUR m)
A33: Division | B33: FY24A | C33: FY25A | E33: H1-26A | F33: Comment
A34: Commercial, Personal Banking & Services (CPBS) | B34: 7047 | C34: 7805 | E34: 3821
A35: Investment & Protection Services (IPS) | B35: 2324 | C35: 3089 | E35: 1605
A36: Corporate & Institutional Banking (CIB) | B36: 7418 | C36: 7506 | E36: 4593
A37: Corporate Centre & eliminations (residual) | B37: =B11-SUM(B34:B36) -> -601 | C37: =C11-SUM(C34:C36) -> -1335 | E37: =E11-SUM(E34:E36) -> 652 | F37: Corporate Centre H1-26 includes the EUR 858m Ageas / AGI gain
A39: Allocated RWA (EUR bn) and return on notional equity (RONE)
A40: Division | B40: RWA Dec-25 | C40: RWA Jun-26 | D40: RONE FY25 | E40: RONE Q2-26 | F40: Comment
A41: Commercial, Personal Banking & Services (CPBS) | B41: 435.9 | C41: 440.1 | D41: 0.139 | E41: 0.148
A42: Investment & Protection Services (IPS) | B42: 61.6 | C42: 65.1 | D42: 0.228 | E42: 0.247
A43: Corporate & Institutional Banking (CIB) | B43: 258.2 | C43: 269.3 | D43: 0.213 | E43: 0.266
A44: Total divisions | B44: =SUM(B41:B43) -> 755.7 | C44: =SUM(C41:C43) -> 774.5 | F44: Group RWA Dec-25: EUR 779bn (divisions + Corporate Centre)
A46: Analysts' consensus compiled by BNP Paribas (pre-2Q26, 10-Jul-2026)
...

Sheet DDM
B1: BNP Paribas - Earnings Projections and Dividend Discount Model (EUR m, valuation at 31-Dec-2026)
A3: EUR m | B3: FY25A | C3: FY26E | D3: FY27E | E3: FY28E | F3: FY29E | G3: FY30E | H3: FY31E
A4: Revenues by division
A5: CPBS | B5: =Income_Statement!C27 -> 26717 | C5: =Income_Statement!E27*Assumptions!$B$5 -> 27731.97 | D5: =C5*(1+Assumptions!C10) -> 28979.909 | E5: =D5*(1+Assumptions!D10) -> 30284.005 | F5: =E5*(1+Assumptions!E10) -> 31495.365 | G5: =F5*(1+Assumptions!F10) -> 32597.702 | H5: =G5*(1+Assumptions!G10) -> 33738.622
A6: IPS | B6: =Income_Statement!C28 -> 6929 | C6: =Income_Statement!E28*Assumptions!$B$6 -> 7844 | D6: =C6*(1+Assumptions!C11) -> 8314.64 | E6: =D6*(1+Assumptions!D11) -> 8813.5184 | F6: =E6*(1+Assumptions!E11) -> 9254.1943 | G6: =F6*(1+Assumptions!F11) -> 9716.904 | H6: =G6*(1+Assumptions!G11) -> 10154.165
A7: CIB | B7: =Income_Statement!C29 -> 18997 | C7: =Income_Statement!E29*Assumptions!$B$7 -> 19995.6 | D7: =C7*(1+Assumptions!C12) -> 20795.424 | E7: =D7*(1+Assumptions!D12) -> 21627.241 | F7: =E7*(1+Assumptions!E12) -> 22492.331 | G7: =F7*(1+Assumptions!F12) -> 23279.562 | H7: =G7*(1+Assumptions!G12) -> 24094.347
A8: Corporate Centre | B8: =Income_Statement!C30 -> -1420 | C8: =Income_Statement!E30+Assumptions!$B$8 -> -546 | D8: =Assumptions!C13 -> -500 | E8: =Assumptions!D13 -> -500 | F8: =Assumptions!E13 -> -500 | G8: =Assumptions!F13 -> -500 | H8: =Assumptions!G13 -> -500
A9: Revenues | B9: =SUM(B5:B8) -> 51223 | C9: =SUM(C5:C8) -> 55025.57 | D9: =SUM(D5:D8) -> 57589.973 | E9: =SUM(E5:E8) -> 60224.764 | F9: =SUM(F5:F8) -> 62741.89 | G9: =SUM(G5:G8) -> 65094.169 | H9: =SUM(H5:H8) -> 67487.134
A10: Revenue growth | C10: =C9/B9-1 -> 0.074235597 | D10: =D9/C9-1 -> 0.046603836 | E10: =E9/D9-1 -> 0.045750868 | F10: =F9/E9-1 -> 0.041795527 | G10: =G9/F9-1 -> 0.037491364 | H10: =H9/G9-1 -> 0.036761587
A12: Profit & loss
A13: Operating expenses and D&A | B13: =Income_Statement!C5 -> -31374 | C13: =-C9*Assumptions!B15 -> -32740.214 | D13: =-D9*Assumptions!C15 -> -33402.184 | E13: =-E9*Assumptions!D15 -> -33906.542 | F13: =-F9*Assumptions!E15 -> -34696.265 | G13: =-G9*Assumptions!F15 -> -35476.322 | H13: =-H9*Assumptions!G15 -> -36443.052
A14: Gross operating income | B14: =B9+B13 -> 19849 | C14: =C9+C13 -> 22285.356 | D14: =D9+D13 -> 24187.789 | E14: =E9+E13 -> 26318.222 | F14: =F9+F13 -> 28045.625 | G14: =G9+G13 -> 29617.847 | H14: =H9+H13 -> 31044.081
A15: Cost / income ratio | B15: =-B13/B9 -> 0.61249829 | C15: =-C13/C9 -> 0.595 | D15: =-D13/D9 -> 0.58 | E15: =-E13/E9 -> 0.563 | F15: =-F13/F9 -> 0.553 | G15: =-G13/G9 -> 0.545 | H15: =-H13/H9 -> 0.54
A16: Customer loans (EUR bn) | C16: =Assumptions!$B$16 -> 960 | D16: =C16*(1+Assumptions!C17) -> 993.6 | E16: =D16*(1+Assumptions!D17) -> 1028.376 | F16: =E16*(1+Assumptions!E17) -> 1064.3692 | G16: =F16*(1+Assumptions!F17) -> 1101.6221 | H16: =G16*(1+Assumptions!G17) -> 1140.1789
A17: Cost of risk (bp) | C17: =Assumptions!B18 -> 39 | D17: =Assumptions!C18 -> 40 | E17: =Assumptions!D18 -> 40 | F17: =Assumptions!E18 -> 40 | G17: =Assumptions!F18 -> 40 | H17: =Assumptions!G18 -> 40
A18: Cost of risk | B18: =Income_Statement!C7 -> -3350 | C18: =-C16*C17/10 -> -3744 | D18: =-D16*D17/10 -> -3974.4 | E18: =-E16*E17/10 -> -4113.504 | F18: =-F16*F17/10 -> -4257.4766 | G18: =-G16*G17/10 -> -4406.4883 | H18: =-H16*H17/10 -> -4560.7154
A19: Other net losses (litigation) | B19: =Income_Statement!C8 -> -203 | C19: =Assumptions!B19 -> -444 | D19: =Assumptions!C19 -> -100 | E19: =Assumptions!D19 -> -100 | F19: =Assumptions!E19 -> -100 | G19: =Assumptions!F19 -> -100 | H19: =Assumptions!G19 -> -100
A20: Operating income | B20: =B14+B18+B19 -> 16296 | C20: =C14+C18+C19 -> 18097.356 | D20: =D14+D18+D19 -> 20113.389 | E20: =E14+E18+E19 -> 22104.718 | F20: =F14+F18+F19 -> 23688.148 | G20: =G14+G18+G19 -> 25111.358 | H20: =H14+H18+H19 -> 26383.366
A21: Non-operating items | B21: =Income_Statement!C10 -> 769 | C21: =Assumptions!B20 -> 1835 | D21: =Assumptions!C20 -> 850 | E21: =Assumptions!D20 -> 850 | F21: =Assumptions!E20 -> 850 | G21: =Assumptions!F20 -> 850 | H21: =Assumptions!G20 -> 850
A22: Pre-tax income | B22: =B20+B21 -> 17065 | C22: =C20+C21 -> 19932.356 | D22: =D20+D21 -> 20963.389 | E22: =E20+E21 -> 22954.718 | F22: =F20+F21 -> 24538.148 | G22: =G20+G21 -> 25961.358 | H22: =H20+H21 -> 27233.366
A23: Corporate income tax | B23: =Income_Statement!C12 -> -4207 | C23: =-C22*Assumptions!B21 -> -5581.0596 | D23: =-D22*Assumptions!C21 -> -5764.9318 | E23: =-E22*Assumptions!D21 -> -6197.7738 | F23: =-F22*Assumptions!E21 -> -6625.3 | G23: =-G22*Assumptions!F21 -> -7009.5668 | H23: =-H22*Assumptions!G21 -> -7353.0088
A24: Effective tax rate | B24: =-B23/B22 -> 0.24652798 | C24: =-C23/C22 -> 0.28 | D24: =-D23/D22 -> 0.275 | E24: =-E23/E22 -> 0.27 | F24: =-F23/F22 -> 0.27 | G24: =-G23/G22 -> 0.27 | H24: =-H23/H22 -> 0.27
A25: Minority interests | B25: =Income_Statement!C13 -> -633 | C25: =-Assumptions!B22 -> -520 | D25: =-Assumptions!C22 -> -541 | E25: =-Assumptions!D22 -> -562 | F25: =-Assumptions!E22 -> -585 | G25: =-Assumptions!F22 -> -608 | H25: =-Assumptions!G22 -> -633
A26: Net income, group share | B26: =B22+B23+B25 -> 12225 | C26: =C22+C23+C25 -> 13831.296 | D26: =D22+D23+D25 -> 14657.457 | E26: =E22+E23+E25 -> 16194.944 | F26: =F22+F23+F25 -> 17327.848 | G26: =G22+G23+G25 -> 18343.792 | H26: =H22+H23+H25 -> 19247.357
A27: Net income growth | C27: =C26/B26-1 -> 0.13139437 | D27: =D26/C26-1 -> 0.059731239 | E27: =E26/D26-1 -> 0.10489455 | F27: =F26/E26-1 -> 0.069954181 | G27: =G26/F26-1 -> 0.058630685 | H27: =H26/G26-1 -> 0.049257296
A28: AT1 coupons | B28: =-Data!$B$19 -> -711 | C28: =-Assumptions!B23 -> -930 | D28: =-Assumptions!C23 -> -950 | E28: =-Assumptions!D23 -> -950 | F28: =-Assumptions!E23 -> -950 | G28: =-Assumptions!F23 -> -950 | H28: =-Assumptions!G23 -> -950
A29: Net income to ordinary shareholders | B29: =B26+B28 -> 11514 | C29: =C26+C28 -> 12901.296 | D29: =D26+D28 -> 13707.457 | E29: =E26+E28 -> 15244.944 | F29: =F26+F28 -> 16377.848 | G29: =G26+G28 -> 17393.792 | H29: =H26+H28 -> 18297.357
A31: Capital, distributions and per-share data
A32: Risk-weighted assets (EUR bn) | B32: =Data!$B$33 -> 779 | C32: =Assumptions!$B$25 -> 795 | D32: =C32*(1+Assumptions!C26) -> 822.825 | E32: =D32*(1+Assumptions!D26) -> 847.50975 | F32: =E32*(1+Assumptions!E26) -> 872.93504 | G32: =F32*(1+Assumptions!F26) -> 899.12309 | H32: =G32*(1+Assumptions!G26) -> 926.09679
A33: Capital retained for RWA growth at target CET1 | C33: =(C32-B32)*Assumptions!B27*1000 -> 2080 | D33: =(D32-C32)*Assumptions!C27*1000 -> 3617.25 | E33: =(E32-D32)*Assumptions!D27*1000 -> 3209.0175 | F33: =(F32-E32)*Assumptions!E27*1000 -> 3305.288 | G33: =(G32-F32)*Assumptions!F27*1000 -> 3404.4467 | H33: =(H32-G32)*Assumptions!G27*1000 -> 3506.5801
A34: Total distribution (dividend + buyback) | C34: =Assumptions!$B$28*C29 -> 7740.7777 | D34: =D29-D33 -> 10090.207 | E34: =E29-E33 -> 12035.927 | F34: =F29-F33 -> 13072.56 | G34: =G29-G33 -> 13989.345 | H34: =H29-H33 -> 14790.777
A35: Payout ratio (% of NI to ordinary) | C35: =C34/C29 -> 0.6 | D35: =D34/D29 -> 0.73611078 | E35: =E34/E29 -> 0.78950283 | F35: =F34/F29 -> 0.79818545 | G35: =G34/G29 -> 0.80427231 | H35: =H34/H29 -> 0.80835593
A36: of which cash dividend | C36: =C29*Assumptions!B29 -> 6450.6481 | D36: =D29*Assumptions!C29 -> 6853.7283 | E36: =E29*Assumptions!D29 -> 7622.472 | F36: =F29*Assumptions!E29 -> 8188.924 | G36: =G29*Assumptions!F29 -> 8696.8958 | H36: =H29*Assumptions!G29 -> 9148.6786
A37: of which share buyback | C37: =C34-C36 -> 1290.1296 | D37: =D34-D36 -> 3236.4783 | E37: =E34-E36 -> 4413.4545 | F37: =F34-F36 -> 4883.636 | G37: =G34-G36 -> 5292.4492 | H37: =H34-H36 -> 5642.0985
A38: Shares outstanding, year-end (m) | B38: =Data!$B$4 -> 1100 | C38: =Data!$B$3 -> 1100.1 | D38: =C38-C37/(Assumptions!$B$30*C48) -> 1084.3719 | E38: =D38-D37/(Assumptions!$B$30*D48) -> 1046.7594 | F38: =E38-E37/(Assumptions!$B$30*E48) -> 998.65222 | G38: =F38-F37/(Assumptions!$B$30*F48) -> 949.30797 | H38: =G38-G37/(Assumptions!$B$30*G48) -> 899.91924
A39: EPS (EUR) | B39: =Data!$B$14 -> 10.29 | C39: =C29/AVERAGE(B38,C38) -> 11.727918 | D39: =D29/AVERAGE(C38,D38) -> 12.549904 | E39: =E29/AVERAGE(D38,E38) -> 14.306903 | F39: =F29/AVERAGE(E38,F38) -> 16.014232 | G39: =G29/AVERAGE(F38,G38) -> 17.858467 | H39: =H29/AVERAGE(G38,H38) -> 19.789193
A40: EPS growth | C40: =C39/B39-1 -> 0.13973936 | D40: =D39/C39-1 -> 0.070088008 | E40: =E39/D39-1 -> 0.14000091 | F40: =F39/E39-1 -> 0.11933604 | G40: =G39/F39-1 -> 0.11516229 | H40: =H39/G39-1 -> 0.10811263
A41: DPS (EUR) | B41: =Data!$B$16 -> 5.16 | C41: =C36/C38 -> 5.8636925 | D41: =D36/D38 -> 6.3204593 | E41: =E36/E38 -> 7.2819711 | F41: =F36/F38 -> 8.1999758 | G41: =G36/G38 -> 9.1613008 | H41: =H36/H38 -> 10.166111
A43: Tangible equity roll-forward (net of distribution accrual)
A44: Opening tangible equity | C44: =Data!$B$22*Data!$B$3 -> 108249.84 | D44: =C47 -> 106314.71 | E44: =D47 -> 109931.96 | F44: =E47 -> 113140.98 | G44: =F47 -> 116446.27 | H44: =G47 -> 119850.72
...

Sheet Cost_of_Equity
B1: BNP Paribas - Cost of Equity
A3: Label | B3: Value | C3: Comment
A4: CAPM
A5: Risk-free rate (French OAT 10Y) | B5: =Data!$B$10 -> 0.0493 | C5: OAT, not Bund: a French bank is priced off its sovereign (EUR 20bn French government bonds, domestic funding)
A6: Equity risk premium | B6: =Data!$B$12 -> 0.055 | C6: Same ERP as the Pernod Ricard and LVMH models
A7: Raw beta (1Y vs CAC 40) | B7: =Data!$B$9 -> 1.37 | C7: ABC Bourse
A8: Beta (Blume-adjusted) | B8: =0.67*B7+0.33 -> 1.2479 | C8: 0.67 x raw + 0.33
A9: Cost of equity (Ke) | B9: =B5+B8*B6 -> 0.1179345 | C9: Applied in the DDM and the justified P/TBV
A10: Cross-checks
A11: German Bund 10Y | B11: =Data!$B$11 -> 0.0337
A12: OAT - Bund spread | B12: =B5-B11 -> 0.0156 | C12: OAT above 5% on 21-22 Oct 2026, a first since 2002
A13: Ke on a Bund basis (memo) | B13: =B11+B8*B6 -> 0.1023345 | C13: What a German-domiciled bank with the same beta would cost
A14: Market-implied Ke at long-term RoTE | B14: =Assumptions!B34+(Assumptions!B33-Assumptions!B34)*DDM!C48/(Data!$B$2-DDM!B58/DDM!B67) -> 0.15942055 | C14: Ke solving P = TBV x (RoTE - g) / (Ke - g), price ex remaining FY26 distribution
A15: Market-implied Ke at FY26E RoTE | B15: =Assumptions!B34+(DDM!C49-Assumptions!B34)*DDM!C48/(Data!$B$2-DDM!B58/DDM!B67) -> 0.14732715 | C15: Even with no RoTE improvement, the market asks for this return
A16: Gap: market-implied less CAPM Ke | B16: =B14-B9 -> 0.041486051 | C16: Risk premium the market adds on top of an OAT-based CAPM
A17: Capital and liquidity (30-Jun-26)
A18: CET1 ratio | B18: =Data!$B$29 -> 0.13
A19: CET1 requirement (SREP) | B19: =Data!$B$30 -> 0.1043
A20: Buffer to requirement (bp) | B20: =(B18-B19)*10000 -> 257 | C20: EUR ~20bn of buffer on EUR 780bn RWA
A21: Leverage ratio | B21: =Data!$B$31 -> 0.044
A22: Liquidity coverage ratio | B22: =Data!$B$32 -> 1.49
A23: P/TBV at current price (Jun-26 TBVPS) | B23: =Data!$B$2/Data!$B$22 -> 0.84878049

Sheet Bridge
B1: BNP Paribas - Equity Value Bridge (31-Dec-2026E)
A3: EUR m | B3: Excess-capital DDM | C3: Gordon P/TBV
A4: Remaining FY26E distribution (t = 0) | B4: =DDM!B58 -> 4187.4547 | C4: =DDM!B75 -> 4187.4547
A5: PV of FY27E-FY31E distributions | B5: =DDM!B59 -> 45439.545 | C5: 0
A6: PV of terminal value / value of tangible equity | B6: =DDM!B65 -> 82955.498 | C6: =DDM!B74 -> 124840.5
A7: Equity value | B7: =SUM(B4:B6) -> 132582.5 | C7: =SUM(C4:C6) -> 129027.96
A8: Shares outstanding (m) | B8: =DDM!B67 -> 1100.1 | C8: =B8 -> 1100.1
A9: Implied value per share (EUR) | B9: =B7/B8 -> 120.51859 | C9: =C7/C8 -> 117.28748
A10: Current share price (EUR) | B10: =Data!$B$2 -> 83.52 | C10: =B10 -> 83.52
A11: Implied upside / (downside) | B11: =B9/B10-1 -> 0.44299075 | C11: =C9/C10-1 -> 0.40430411
A12: Implied P/TBV (Jun-26 TBVPS) | B12: =B9/Data!$B$22 -> 1.2247824 | C12: =C9/Data!$B$22 -> 1.1919459
A13: Implied P/E FY27E | B13: =B9/DDM!D39 -> 9.6031478 | C13: =C9/DDM!D39 -> 9.345687
A15: Check vs DDM tab (should be 0) | B15: =B9-DDM!B68 -> 0 | C15: =C9-DDM!B77 -> 0
A16: No net debt bridge for a bank: the valuation is directly on equity (distributions to shareholders).

Sheet Sensitivity
B1: BNP Paribas - Sensitivity Analysis (EUR per share)
A3: Excess-capital DDM - value per share (EUR) | C3: Long-term growth g ->
B4: Ke \ g | C4: =$E$4-0.01 -> 0.01 | D4: =$E$4-0.005 -> 0.015 | E4: =Assumptions!$B$34 -> 0.02 | F4: =$E$4+0.005 -> 0.025 | G4: =$E$4+0.01 -> 0.03
B5: =$B$8-0.015 -> 0.1029345 | C5: =(DDM!$B$58+SUMPRODUCT(DDM!$D$55:$H$55,(1+$B5)^(-DDM!$D$52:$H$52))+DDM!$H$47*(Assumptions!$B$33-C$4)/($B5-C$4)*(1+$B5)^(-DDM!$H$52))/DDM!$B$67 -> 139.21406 | D5: =(DDM!$B$58+SUMPRODUCT(DDM!$D$55:$H$55,(1+$B5)^(-DDM!$D$52:$H$52))+DDM!$H$47*(Assumptions!$B$33-D$4)/($B5-D$4)*(1+$B5)^(-DDM!$H$52))/DDM!$B$67 -> 140.56195 | E5: =(DDM!$B$58+SUMPRODUCT(DDM!$D$55:$H$55,(1+$B5)^(-DDM!$D$52:$H$52))+DDM!$H$47*(Assumptions!$B$33-E$4)/($B5-E$4)*(1+$B5)^(-DDM!$H$52))/DDM!$B$67 -> 142.07237 | F5: =(DDM!$B$58+SUMPRODUCT(DDM!$D$55:$H$55,(1+$B5)^(-DDM!$D$52:$H$52))+DDM!$H$47*(Assumptions!$B$33-F$4)/($B5-F$4)*(1+$B5)^(-DDM!$H$52))/DDM!$B$67 -> 143.7766 | G5: =(DDM!$B$58+SUMPRODUCT(DDM!$D$55:$H$55,(1+$B5)^(-DDM!$D$52:$H$52))+DDM!$H$47*(Assumptions!$B$33-G$4)/($B5-G$4)*(1+$B5)^(-DDM!$H$52))/DDM!$B$67 -> 145.71449
B6: =$B$8-0.01 -> 0.1079345 | C6: =(DDM!$B$58+SUMPRODUCT(DDM!$D$55:$H$55,(1+$B6)^(-DDM!$D$52:$H$52))+DDM!$H$47*(Assumptions!$B$33-C$4)/($B6-C$4)*(1+$B6)^(-DDM!$H$52))/DDM!$B$67 -> 131.95901 | D6: =(DDM!$B$58+SUMPRODUCT(DDM!$D$55:$H$55,(1+$B6)^(-DDM!$D$52:$H$52))+DDM!$H$47*(Assumptions!$B$33-D$4)/($B6-D$4)*(1+$B6)^(-DDM!$H$52))/DDM!$B$67 -> 132.95771 | E6: =(DDM!$B$58+SUMPRODUCT(DDM!$D$55:$H$55,(1+$B6)^(-DDM!$D$52:$H$52))+DDM!$H$47*(Assumptions!$B$33-E$4)/($B6-E$4)*(1+$B6)^(-DDM!$H$52))/DDM!$B$67 -> 134.06998 | F6: =(DDM!$B$58+SUMPRODUCT(DDM!$D$55:$H$55,(1+$B6)^(-DDM!$D$52:$H$52))+DDM!$H$47*(Assumptions!$B$33-F$4)/($B6-F$4)*(1+$B6)^(-DDM!$H$52))/DDM!$B$67 -> 135.31637 | G6: =(DDM!$B$58+SUMPRODUCT(DDM!$D$55:$H$55,(1+$B6)^(-DDM!$D$52:$H$52))+DDM!$H$47*(Assumptions!$B$33-G$4)/($B6-G$4)*(1+$B6)^(-DDM!$H$52))/DDM!$B$67 -> 136.72269
B7: =$B$8-0.005 -> 0.1129345 | C7: =(DDM!$B$58+SUMPRODUCT(DDM!$D$55:$H$55,(1+$B7)^(-DDM!$D$52:$H$52))+DDM!$H$47*(Assumptions!$B$33-C$4)/($B7-C$4)*(1+$B7)^(-DDM!$H$52))/DDM!$B$67 -> 125.41456 | D7: =(DDM!$B$58+SUMPRODUCT(DDM!$D$55:$H$55,(1+$B7)^(-DDM!$D$52:$H$52))+DDM!$H$47*(Assumptions!$B$33-D$4)/($B7-D$4)*(1+$B7)^(-DDM!$H$52))/DDM!$B$67 -> 126.1333 | E7: =(DDM!$B$58+SUMPRODUCT(DDM!$D$55:$H$55,(1+$B7)^(-DDM!$D$52:$H$52))+DDM!$H$47*(Assumptions!$B$33-E$4)/($B7-E$4)*(1+$B7)^(-DDM!$H$52))/DDM!$B$67 -> 126.92938 | F7: =(DDM!$B$58+SUMPRODUCT(DDM!$D$55:$H$55,(1+$B7)^(-DDM!$D$52:$H$52))+DDM!$H$47*(Assumptions!$B$33-F$4)/($B7-F$4)*(1+$B7)^(-DDM!$H$52))/DDM!$B$67 -> 127.81599 | G7: =(DDM!$B$58+SUMPRODUCT(DDM!$D$55:$H$55,(1+$B7)^(-DDM!$D$52:$H$52))+DDM!$H$47*(Assumptions!$B$33-G$4)/($B7-G$4)*(1+$B7)^(-DDM!$H$52))/DDM!$B$67 -> 128.8095
B8: =Cost_of_Equity!$B$9 -> 0.1179345 | C8: =(DDM!$B$58+SUMPRODUCT(DDM!$D$55:$H$55,(1+$B8)^(-DDM!$D$52:$H$52))+DDM!$H$47*(Assumptions!$B$33-C$4)/($B8-C$4)*(1+$B8)^(-DDM!$H$52))/DDM!$B$67 -> 119.48184 | D8: =(DDM!$B$58+SUMPRODUCT(DDM!$D$55:$H$55,(1+$B8)^(-DDM!$D$52:$H$52))+DDM!$H$47*(Assumptions!$B$33-D$4)/($B8-D$4)*(1+$B8)^(-DDM!$H$52))/DDM!$B$67 -> 119.97503 | E8: =(DDM!$B$58+SUMPRODUCT(DDM!$D$55:$H$55,(1+$B8)^(-DDM!$D$52:$H$52))+DDM!$H$47*(Assumptions!$B$33-E$4)/($B8-E$4)*(1+$B8)^(-DDM!$H$52))/DDM!$B$67 -> 120.51859 | F8: =(DDM!$B$58+SUMPRODUCT(DDM!$D$55:$H$55,(1+$B8)^(-DDM!$D$52:$H$52))+DDM!$H$47*(Assumptions!$B$33-F$4)/($B8-F$4)*(1+$B8)^(-DDM!$H$52))/DDM!$B$67 -> 121.12063 | G8: =(DDM!$B$58+SUMPRODUCT(DDM!$D$55:$H$55,(1+$B8)^(-DDM!$D$52:$H$52))+DDM!$H$47*(Assumptions!$B$33-G$4)/($B8-G$4)*(1+$B8)^(-DDM!$H$52))/DDM!$B$67 -> 121.79114
B9: =$B$8+0.005 -> 0.1229345 | C9: =(DDM!$B$58+SUMPRODUCT(DDM!$D$55:$H$55,(1+$B9)^(-DDM!$D$52:$H$52))+DDM!$H$47*(Assumptions!$B$33-C$4)/($B9-C$4)*(1+$B9)^(-DDM!$H$52))/DDM!$B$67 -> 114.07946 | D9: =(DDM!$B$58+SUMPRODUCT(DDM!$D$55:$H$55,(1+$B9)^(-DDM!$D$52:$H$52))+DDM!$H$47*(Assumptions!$B$33-D$4)/($B9-D$4)*(1+$B9)^(-DDM!$H$52))/DDM!$B$67 -> 114.39026 | E9: =(DDM!$B$58+SUMPRODUCT(DDM!$D$55:$H$55,(1+$B9)^(-DDM!$D$52:$H$52))+DDM!$H$47*(Assumptions!$B$33-E$4)/($B9-E$4)*(1+$B9)^(-DDM!$H$52))/DDM!$B$67 -> 114.73126 | F9: =(DDM!$B$58+SUMPRODUCT(DDM!$D$55:$H$55,(1+$B9)^(-DDM!$D$52:$H$52))+DDM!$H$47*(Assumptions!$B$33-F$4)/($B9-F$4)*(1+$B9)^(-DDM!$H$52))/DDM!$B$67 -> 115.10708 | G9: =(DDM!$B$58+SUMPRODUCT(DDM!$D$55:$H$55,(1+$B9)^(-DDM!$D$52:$H$52))+DDM!$H$47*(Assumptions!$B$33-G$4)/($B9-G$4)*(1+$B9)^(-DDM!$H$52))/DDM!$B$67 -> 115.52334
B10: =$B$8+0.01 -> 0.1279345 | C10: =(DDM!$B$58+SUMPRODUCT(DDM!$D$55:$H$55,(1+$B10)^(-DDM!$D$52:$H$52))+DDM!$H$47*(Assumptions!$B$33-C$4)/($B10-C$4)*(1+$B10)^(-DDM!$H$52))/DDM!$B$67 -> 109.13985 | D10: =(DDM!$B$58+SUMPRODUCT(DDM!$D$55:$H$55,(1+$B10)^(-DDM!$D$52:$H$52))+DDM!$H$47*(Assumptions!$B$33-D$4)/($B10-D$4)*(1+$B10)^(-DDM!$H$52))/DDM!$B$67 -> 109.30277 | E10: =(DDM!$B$58+SUMPRODUCT(DDM!$D$55:$H$55,(1+$B10)^(-DDM!$D$52:$H$52))+DDM!$H$47*(Assumptions!$B$33-E$4)/($B10-E$4)*(1+$B10)^(-DDM!$H$52))/DDM!$B$67 -> 109.48078 | F10: =(DDM!$B$58+SUMPRODUCT(DDM!$D$55:$H$55,(1+$B10)^(-DDM!$D$52:$H$52))+DDM!$H$47*(Assumptions!$B$33-F$4)/($B10-F$4)*(1+$B10)^(-DDM!$H$52))/DDM!$B$67 -> 109.67608 | G10: =(DDM!$B$58+SUMPRODUCT(DDM!$D$55:$H$55,(1+$B10)^(-DDM!$D$52:$H$52))+DDM!$H$47*(Assumptions!$B$33-G$4)/($B10-G$4)*(1+$B10)^(-DDM!$H$52))/DDM!$B$67 -> 109.89132
B11: =$B$8+0.015 -> 0.1329345 | C11: =(DDM!$B$58+SUMPRODUCT(DDM!$D$55:$H$55,(1+$B11)^(-DDM!$D$52:$H$52))+DDM!$H$47*(Assumptions!$B$33-C$4)/($B11-C$4)*(1+$B11)^(-DDM!$H$52))/DDM!$B$67 -> 104.60645 | D11: =(DDM!$B$58+SUMPRODUCT(DDM!$D$55:$H$55,(1+$B11)^(-DDM!$D$52:$H$52))+DDM!$H$47*(Assumptions!$B$33-D$4)/($B11-D$4)*(1+$B11)^(-DDM!$H$52))/DDM!$B$67 -> 104.64925 | E11: =(DDM!$B$58+SUMPRODUCT(DDM!$D$55:$H$55,(1+$B11)^(-DDM!$D$52:$H$52))+DDM!$H$47*(Assumptions!$B$33-E$4)/($B11-E$4)*(1+$B11)^(-DDM!$H$52))/DDM!$B$67 -> 104.69583 | F11: =(DDM!$B$58+SUMPRODUCT(DDM!$D$55:$H$55,(1+$B11)^(-DDM!$D$52:$H$52))+DDM!$H$47*(Assumptions!$B$33-F$4)/($B11-F$4)*(1+$B11)^(-DDM!$H$52))/DDM!$B$67 -> 104.74673 | G11: =(DDM!$B$58+SUMPRODUCT(DDM!$D$55:$H$55,(1+$B11)^(-DDM!$D$52:$H$52))+DDM!$H$47*(Assumptions!$B$33-G$4)/($B11-G$4)*(1+$B11)^(-DDM!$H$52))/DDM!$B$67 -> 104.80258
A13: Gordon justified P/TBV - value per share (EUR) | C13: Long-term RoTE ->
B14: Ke \ RoTE | C14: =$E$14-0.01 -> 0.125 | D14: =$E$14-0.005 -> 0.13 | E14: =Assumptions!$B$33 -> 0.135 | F14: =$E$14+0.005 -> 0.14 | G14: =$E$14+0.01 -> 0.145
B15: =$B$18-0.015 -> 0.1029345 | C15: =(DDM!$C$47*(C$14-Assumptions!$B$34)/($B15-Assumptions!$B$34)+DDM!$B$58)/DDM!$B$67 -> 126.15962 | D15: =(DDM!$C$47*(D$14-Assumptions!$B$34)/($B15-Assumptions!$B$34)+DDM!$B$58)/DDM!$B$67 -> 131.98596 | E15: =(DDM!$C$47*(E$14-Assumptions!$B$34)/($B15-Assumptions!$B$34)+DDM!$B$58)/DDM!$B$67 -> 137.8123 | F15: =(DDM!$C$47*(F$14-Assumptions!$B$34)/($B15-Assumptions!$B$34)+DDM!$B$58)/DDM!$B$67 -> 143.63864 | G15: =(DDM!$C$47*(G$14-Assumptions!$B$34)/($B15-Assumptions!$B$34)+DDM!$B$58)/DDM!$B$67 -> 149.46498
B16: =$B$18-0.01 -> 0.1079345 | C16: =(DDM!$C$47*(C$14-Assumptions!$B$34)/($B16-Assumptions!$B$34)+DDM!$B$58)/DDM!$B$67 -> 119.20255 | D16: =(DDM!$C$47*(D$14-Assumptions!$B$34)/($B16-Assumptions!$B$34)+DDM!$B$58)/DDM!$B$67 -> 124.6976 | E16: =(DDM!$C$47*(E$14-Assumptions!$B$34)/($B16-Assumptions!$B$34)+DDM!$B$58)/DDM!$B$67 -> 130.19266 | F16: =(DDM!$C$47*(F$14-Assumptions!$B$34)/($B16-Assumptions!$B$34)+DDM!$B$58)/DDM!$B$67 -> 135.68771 | G16: =(DDM!$C$47*(G$14-Assumptions!$B$34)/($B16-Assumptions!$B$34)+DDM!$B$58)/DDM!$B$67 -> 141.18277
B17: =$B$18-0.005 -> 0.1129345 | C17: =(DDM!$C$47*(C$14-Assumptions!$B$34)/($B17-Assumptions!$B$34)+DDM!$B$58)/DDM!$B$67 -> 112.99409 | D17: =(DDM!$C$47*(D$14-Assumptions!$B$34)/($B17-Assumptions!$B$34)+DDM!$B$58)/DDM!$B$67 -> 118.1935 | E17: =(DDM!$C$47*(E$14-Assumptions!$B$34)/($B17-Assumptions!$B$34)+DDM!$B$58)/DDM!$B$67 -> 123.39291 | F17: =(DDM!$C$47*(F$14-Assumptions!$B$34)/($B17-Assumptions!$B$34)+DDM!$B$58)/DDM!$B$67 -> 128.59232 | G17: =(DDM!$C$47*(G$14-Assumptions!$B$34)/($B17-Assumptions!$B$34)+DDM!$B$58)/DDM!$B$67 -> 133.79174
B18: =Cost_of_Equity!$B$9 -> 0.1179345 | C18: =(DDM!$C$47*(C$14-Assumptions!$B$34)/($B18-Assumptions!$B$34)+DDM!$B$58)/DDM!$B$67 -> 107.41956 | D18: =(DDM!$C$47*(D$14-Assumptions!$B$34)/($B18-Assumptions!$B$34)+DDM!$B$58)/DDM!$B$67 -> 112.35352 | E18: =(DDM!$C$47*(E$14-Assumptions!$B$34)/($B18-Assumptions!$B$34)+DDM!$B$58)/DDM!$B$67 -> 117.28748 | F18: =(DDM!$C$47*(F$14-Assumptions!$B$34)/($B18-Assumptions!$B$34)+DDM!$B$58)/DDM!$B$67 -> 122.22144 | G18: =(DDM!$C$47*(G$14-Assumptions!$B$34)/($B18-Assumptions!$B$34)+DDM!$B$58)/DDM!$B$67 -> 127.1554
B19: =$B$18+0.005 -> 0.1229345 | C19: =(DDM!$C$47*(C$14-Assumptions!$B$34)/($B19-Assumptions!$B$34)+DDM!$B$58)/DDM!$B$67 -> 102.3866 | D19: =(DDM!$C$47*(D$14-Assumptions!$B$34)/($B19-Assumptions!$B$34)+DDM!$B$58)/DDM!$B$67 -> 107.08089 | E19: =(DDM!$C$47*(E$14-Assumptions!$B$34)/($B19-Assumptions!$B$34)+DDM!$B$58)/DDM!$B$67 -> 111.77518 | F19: =(DDM!$C$47*(F$14-Assumptions!$B$34)/($B19-Assumptions!$B$34)+DDM!$B$58)/DDM!$B$67 -> 116.46948 | G19: =(DDM!$C$47*(G$14-Assumptions!$B$34)/($B19-Assumptions!$B$34)+DDM!$B$58)/DDM!$B$67 -> 121.16377
B20: =$B$18+0.01 -> 0.1279345 | C20: =(DDM!$C$47*(C$14-Assumptions!$B$34)/($B20-Assumptions!$B$34)+DDM!$B$58)/DDM!$B$67 -> 97.819931 | D20: =(DDM!$C$47*(D$14-Assumptions!$B$34)/($B20-Assumptions!$B$34)+DDM!$B$58)/DDM!$B$67 -> 102.29676 | E20: =(DDM!$C$47*(E$14-Assumptions!$B$34)/($B20-Assumptions!$B$34)+DDM!$B$58)/DDM!$B$67 -> 106.7736 | F20: =(DDM!$C$47*(F$14-Assumptions!$B$34)/($B20-Assumptions!$B$34)+DDM!$B$58)/DDM!$B$67 -> 111.25043 | G20: =(DDM!$C$47*(G$14-Assumptions!$B$34)/($B20-Assumptions!$B$34)+DDM!$B$58)/DDM!$B$67 -> 115.72726
B21: =$B$18+0.015 -> 0.1329345 | C21: =(DDM!$C$47*(C$14-Assumptions!$B$34)/($B21-Assumptions!$B$34)+DDM!$B$58)/DDM!$B$67 -> 93.657629 | D21: =(DDM!$C$47*(D$14-Assumptions!$B$34)/($B21-Assumptions!$B$34)+DDM!$B$58)/DDM!$B$67 -> 97.936258 | E21: =(DDM!$C$47*(E$14-Assumptions!$B$34)/($B21-Assumptions!$B$34)+DDM!$B$58)/DDM!$B$67 -> 102.21489 | F21: =(DDM!$C$47*(F$14-Assumptions!$B$34)/($B21-Assumptions!$B$34)+DDM!$B$58)/DDM!$B$67 -> 106.49351 | G21: =(DDM!$C$47*(G$14-Assumptions!$B$34)/($B21-Assumptions!$B$34)+DDM!$B$58)/DDM!$B$67 -> 110.77214
A23: Cost of equity implied by today's share price | C23: Long-term growth g ->
B24: RoTE \ g | C24: =$E$24-0.01 -> 0.01 | D24: =$E$24-0.005 -> 0.015 | E24: =Assumptions!$B$34 -> 0.02 | F24: =$E$24+0.005 -> 0.025 | G24: =$E$24+0.01 -> 0.03
B25: =$B$28-0.015 -> 0.12 | C25: =C$24+($B25-C$24)*DDM!$C$48/(Data!$B$2-DDM!$B$58/DDM!$B$67) -> 0.14335879 | D25: =D$24+($B25-D$24)*DDM!$C$48/(Data!$B$2-DDM!$B$58/DDM!$B$67) -> 0.14229702 | E25: =E$24+($B25-E$24)*DDM!$C$48/(Data!$B$2-DDM!$B$58/DDM!$B$67) -> 0.14123526 | F25: =F$24+($B25-F$24)*DDM!$C$48/(Data!$B$2-DDM!$B$58/DDM!$B$67) -> 0.1401735 | G25: =G$24+($B25-G$24)*DDM!$C$48/(Data!$B$2-DDM!$B$58/DDM!$B$67) -> 0.13911174
B26: =$B$28-0.01 -> 0.125 | C26: =C$24+($B26-C$24)*DDM!$C$48/(Data!$B$2-DDM!$B$58/DDM!$B$67) -> 0.14942055 | D26: =D$24+($B26-D$24)*DDM!$C$48/(Data!$B$2-DDM!$B$58/DDM!$B$67) -> 0.14835879 | E26: =E$24+($B26-E$24)*DDM!$C$48/(Data!$B$2-DDM!$B$58/DDM!$B$67) -> 0.14729702 | F26: =F$24+($B26-F$24)*DDM!$C$48/(Data!$B$2-DDM!$B$58/DDM!$B$67) -> 0.14623526 | G26: =G$24+($B26-G$24)*DDM!$C$48/(Data!$B$2-DDM!$B$58/DDM!$B$67) -> 0.1451735
B27: =$B$28-0.005 -> 0.13 | C27: =C$24+($B27-C$24)*DDM!$C$48/(Data!$B$2-DDM!$B$58/DDM!$B$67) -> 0.15548231 | D27: =D$24+($B27-D$24)*DDM!$C$48/(Data!$B$2-DDM!$B$58/DDM!$B$67) -> 0.15442055 | E27: =E$24+($B27-E$24)*DDM!$C$48/(Data!$B$2-DDM!$B$58/DDM!$B$67) -> 0.15335879 | F27: =F$24+($B27-F$24)*DDM!$C$48/(Data!$B$2-DDM!$B$58/DDM!$B$67) -> 0.15229702 | G27: =G$24+($B27-G$24)*DDM!$C$48/(Data!$B$2-DDM!$B$58/DDM!$B$67) -> 0.15123526
B28: =Assumptions!$B$33 -> 0.135 | C28: =C$24+($B28-C$24)*DDM!$C$48/(Data!$B$2-DDM!$B$58/DDM!$B$67) -> 0.16154408 | D28: =D$24+($B28-D$24)*DDM!$C$48/(Data!$B$2-DDM!$B$58/DDM!$B$67) -> 0.16048231 | E28: =E$24+($B28-E$24)*DDM!$C$48/(Data!$B$2-DDM!$B$58/DDM!$B$67) -> 0.15942055 | F28: =F$24+($B28-F$24)*DDM!$C$48/(Data!$B$2-DDM!$B$58/DDM!$B$67) -> 0.15835879 | G28: =G$24+($B28-G$24)*DDM!$C$48/(Data!$B$2-DDM!$B$58/DDM!$B$67) -> 0.15729702
B29: =$B$28+0.005 -> 0.14 | C29: =C$24+($B29-C$24)*DDM!$C$48/(Data!$B$2-DDM!$B$58/DDM!$B$67) -> 0.16760584 | D29: =D$24+($B29-D$24)*DDM!$C$48/(Data!$B$2-DDM!$B$58/DDM!$B$67) -> 0.16654408 | E29: =E$24+($B29-E$24)*DDM!$C$48/(Data!$B$2-DDM!$B$58/DDM!$B$67) -> 0.16548231 | F29: =F$24+($B29-F$24)*DDM!$C$48/(Data!$B$2-DDM!$B$58/DDM!$B$67) -> 0.16442055 | G29: =G$24+($B29-G$24)*DDM!$C$48/(Data!$B$2-DDM!$B$58/DDM!$B$67) -> 0.16335879
B30: =$B$28+0.01 -> 0.145 | C30: =C$24+($B30-C$24)*DDM!$C$48/(Data!$B$2-DDM!$B$58/DDM!$B$67) -> 0.1736676 | D30: =D$24+($B30-D$24)*DDM!$C$48/(Data!$B$2-DDM!$B$58/DDM!$B$67) -> 0.17260584 | E30: =E$24+($B30-E$24)*DDM!$C$48/(Data!$B$2-DDM!$B$58/DDM!$B$67) -> 0.17154408 | F30: =F$24+($B30-F$24)*DDM!$C$48/(Data!$B$2-DDM!$B$58/DDM!$B$67) -> 0.17048231 | G30: =G$24+($B30-G$24)*DDM!$C$48/(Data!$B$2-DDM!$B$58/DDM!$B$67) -> 0.16942055
B31: =$B$28+0.015 -> 0.15 | C31: =C$24+($B31-C$24)*DDM!$C$48/(Data!$B$2-DDM!$B$58/DDM!$B$67) -> 0.17972937 | D31: =D$24+($B31-D$24)*DDM!$C$48/(Data!$B$2-DDM!$B$58/DDM!$B$67) -> 0.1786676 | E31: =E$24+($B31-E$24)*DDM!$C$48/(Data!$B$2-DDM!$B$58/DDM!$B$67) -> 0.17760584 | F31: =F$24+($B31-F$24)*DDM!$C$48/(Data!$B$2-DDM!$B$58/DDM!$B$67) -> 0.17654408 | G31: =G$24+($B31-G$24)*DDM!$C$48/(Data!$B$2-DDM!$B$58/DDM!$B$67) -> 0.17548231
A33: Scenario analysis (DDM leg, g at base)
A34: Scenario | B34: Ke | C34: Long-term RoTE | D34: Excess-capital DDM | E34: Gordon P/TBV | F34: Average (DDM leg) | G34: vs price
A35: Bear - French risk premium persists, RoTE stalls | B35: =Cost_of_Equity!$B$9+0.01 -> 0.1279345 | C35: 0.12 | D35: =(DDM!$B$58+SUMPRODUCT(DDM!$D$55:$H$55,(1+$B35)^(-DDM!$D$52:$H$52))+DDM!$H$47*($C35-Assumptions!$B$34)/($B35-Assumptions!$B$34)*(1+$B35)^(-DDM!$H$52))/DDM!$B$67 -> 100.94498 | E35: =(DDM!$C$47*($C35-Assumptions!$B$34)/($B35-Assumptions!$B$34)+DDM!$B$58)/DDM!$B$67 -> 93.343098 | F35: =AVERAGE(D35:E35) -> 97.144037 | G35: =F35/Data!$B$2-1 -> 0.16312304
A36: Base | B36: =Cost_of_Equity!$B$9 -> 0.1179345 | C36: =Assumptions!$B$33 -> 0.135 | D36: =(DDM!$B$58+SUMPRODUCT(DDM!$D$55:$H$55,(1+$B36)^(-DDM!$D$52:$H$52))+DDM!$H$47*($C36-Assumptions!$B$34)/($B36-Assumptions!$B$34)*(1+$B36)^(-DDM!$H$52))/DDM!$B$67 -> 120.51859 | E36: =(DDM!$C$47*($C36-Assumptions!$B$34)/($B36-Assumptions!$B$34)+DDM!$B$58)/DDM!$B$67 -> 117.28748 | F36: =AVERAGE(D36:E36) -> 118.90303 | G36: =F36/Data!$B$2-1 -> 0.42364743
A37: Bull - spread normalises, 2028 plan delivered | B37: =Cost_of_Equity!$B$9-0.005 -> 0.1129345 | C37: 0.145 | D37: =(DDM!$B$58+SUMPRODUCT(DDM!$D$55:$H$55,(1+$B37)^(-DDM!$D$52:$H$52))+DDM!$H$47*($C37-Assumptions!$B$34)/($B37-Assumptions!$B$34)*(1+$B37)^(-DDM!$H$52))/DDM!$B$67 -> 133.99594 | E37: =(DDM!$C$47*($C37-Assumptions!$B$34)/($B37-Assumptions!$B$34)+DDM!$B$58)/DDM!$B$67 -> 133.79174 | F37: =AVERAGE(D37:E37) -> 133.89384 | G37: =F37/Data!$B$2-1 -> 0.603135
A39: Checks: base cells equal the DDM tab (should be 0) | E39: =E8-DDM!B68 -> 0 | F39: =E18-DDM!B77 -> 0 | G39: =E28-Cost_of_Equity!B14 -> 0

Sheet Trading_Comps
B1: BNP Paribas - Trading Comparables: P/TBV vs RoTE (European large banks)
A3: Bank | B3: Ticker | C3: Share price (EUR) | D3: Price date | E3: TBVPS (EUR) | F3: TBVPS date | G3: P/TBV | H3: RoTE | I3: RoTE basis | J3: Source
A4: Societe Generale | B4: GLE FP | C4: 62.8 | D4: 19-Oct-26 | E4: 74.5 | F4: Jun-26 | G4: =C4/E4 -> 0.84295302 | H4: 0.11 | I4: 2026 target (H1-26 12.0%) | J4: SG 2Q26 release; CET1 13.2%
A5: Deutsche Bank | B5: DBK GY | C5: 29.86 | D5: 07-Oct-26 | E5: 31.2 | F5: Jun-26 | G5: =C5/E5 -> 0.95705128 | H5: 0.119 | I5: H1-26 | J5: DB 2Q26 release
A6: Commerzbank | B6: CBK GY | C6: 37.83 | D6: 15-Oct-26 | E6: 30.96 | F6: TTM | G6: =C6/E6 -> 1.2218992 | H6: 0.127 | I6: Q1-26 | J6: Commerzbank Q1-26 release; TBVPS roic.ai
A7: Santander | B7: SAN SM | C7: 12.178 | D7: 14-Oct-26 | E7: 6.13 | F7: Mar-26 | G7: =C7/E7 -> 1.9866232 | H7: 0.156 | I7: H1-26 | J7: Santander H1-26 release (bolsamania price); CET1 14.0%
A8: BBVA | B8: BBVA SM | C8: 22.71 | D8: 27-Oct-26 | E8: 10.14 | F8: Jun-26 | G8: =C8/E8 -> 2.239645 | H8: 0.222 | I8: H1-26 | J8: BBVA H1-26 release; CET1 12.9%
A9: UniCredit | B9: UCG IM | C9: 71.27 | D9: 23-Oct-26 | E9: 44.2 | F9: Jun-26 | G9: =C9/E9 -> 1.6124434 | H9: 0.237 | I9: H1-26 | J9: UniCredit H1-26 release; TBVPS stockanalysis; CET1 14.3%
A10: Intesa Sanpaolo | B10: ISP IM | C10: 6.69 | D10: 02-Oct-26 | E10: 3.38 | F10: TTM | G10: =C10/E10 -> 1.9792899 | H10: 0.25 | I10: H1-26 | J10: Intesa H1-26 release; TBVPS roic.ai; CET1 13.1%
A12: BNP Paribas | B12: BNP FP | C12: =Data!$B$2 -> 83.52 | D12: 27-Oct-26 | E12: =Data!$B$22 -> 98.4 | F12: Jun-26 | G12: =C12/E12 -> 0.84878049 | H12: =DDM!C49 -> 0.12502485 | I12: Axone FY26E | J12: Not in the regression
A14: Peer statistics
A15: Median P/TBV | B15: =MEDIAN(G4:G10) -> 1.6124434
A16: Mean P/TBV | B16: =AVERAGE(G4:G10) -> 1.5485579
A17: Median RoTE | B17: =MEDIAN(H4:H10) -> 0.156
A18: Regression P/TBV = a + b x RoTE (7 peers)
A19: Slope b (x per 1.0 of RoTE) | B19: =SLOPE(G4:G10,H4:H10) -> 7.1465305
A20: Intercept a | B20: =INTERCEPT(G4:G10,H4:H10) -> 0.30199876
A21: R-squared | B21: =RSQ(G4:G10,H4:H10) -> 0.61115063
A22: BNP fitted P/TBV at its FY26E RoTE | B22: =B20+B19*H12 -> 1.1954927
A23: BNP actual P/TBV vs fitted line | B23: =G12/B22-1 -> -0.29001614
A24: French discount (SocGen residual scaled by France revenue exposure)
A25: Societe Generale fitted P/TBV | B25: =B20+B19*H4 -> 1.0881171
A26: Societe Generale residual vs line | B26: =G4/B25-1 -> -0.22531039
A27: France share of revenues - Societe Generale | B27: 0.46
A28: France share of revenues - BNP Paribas | B28: =Data!$B$35 -> 0.26
A29: French discount applied to BNP | B29: =B26*B28/B27 -> -0.12734935
A30: Adjusted P/TBV for BNP | B30: =B22*(1+B29) -> 1.0432474
A31: BNP TBVPS (Jun-26, same basis as peers) | B31: =Data!$B$22 -> 98.4
A32: Implied value per share (EUR) | B32: =B30*B31 -> 102.65555
A33: Low - full SocGen discount (EUR) | B33: =B22*(1+B26)*B31 -> 91.131756
A34: High - no French discount (EUR) | B34: =B22*B31 -> 117.63648
A36: Price-to-tangible-book is explained by profitability (RoTE). BNP trades in line with SocGen, well below the line, because the market applies a French sovereign / political discount. We apply SocGen's residual scaled by BNP's lower France exposure.
A37: Crédit Agricole SA and ING excluded: no verifiable October-2026 price / TBVPS pair at the pricing date.

Sheet Precedent_Transactions
B1: BNP Paribas - Precedent Transactions (European and US bank M&A, 2024-2026)
A3: Announced | B3: Acquirer | C3: Target | D3: Deal value (m) | E3: Ccy | F3: P/TBV paid | G3: Target RoTE | H3: P/TBV per RoTE point | I3: Basis of the multiple | J3: Source
A4: Feb-26 | B4: Santander | C4: Webster Financial | D4: 12300 | E4: USD | F4: 2 | G4: 0.17 | H4: =F4/(G4*100) -> 0.11764706 | I4: Q4-25 TBV; ROTCE FY25 | J4: Santander PR; Webster 425 filing
A5: Mar-26 | B5: UniCredit | C5: Commerzbank (offer) | D5: 35000 | E5: EUR | F5: 1 | G5: 0.112 | H5: =F5/(G5*100) -> 0.089285714 | I5: EUR 30.8 per share offer; 2026 RoTE target | J5: UniCredit offer announcement
A6: Jul-25 | B6: Santander | C6: TSB | D6: 2650 | E6: GBP | F6: 1.45 | G6: 0.106 | H6: =F6/(G6*100) -> 0.13679245 | I6: TNAV; RoTE FY24 | J6: Santander PR
A7: Jun-25 | B7: BPCE | C7: Novo Banco | D7: 6400 | E7: EUR | F7: 1.7 | G7: 0.2 | H7: =F7/(G7*100) -> 0.085 | I7: Breakingviews estimate; RoTE > 20% | J7: Reuters Breakingviews
A8: May-25 | B8: Erste Group | C8: Santander Bank Polska (49%) | D8: 13900 | E8: EUR | F8: 2.2 | G8: 0.16 | H8: =F8/(G8*100) -> 0.1375 | I8: Value for 100%; RoE 2024 as proxy | J8: Erste / Santander PR
A9: Jan-25 | B9: Monte dei Paschi | C9: Mediobanca | D9: 13300 | E9: EUR | F9: 1.3 | G9: 0.14 | H9: =F9/(G9*100) -> 0.092857143 | I9: EUR 15.99 vs TBVPS 12.34 | J9: MPS offer document
A10: Nov-24 | B10: UniCredit | C10: Banco BPM (withdrawn) | D10: 10100 | E10: EUR | F10: 0.79 | G10: 0.16 | H10: =F10/(G10*100) -> 0.049375 | I10: EUR 6.657 vs TEPS 8.38; adj. RoTE | J10: UniCredit offer document
A12: Statistics - P/TBV per point of target RoTE
A13: Median | B13: =MEDIAN(H4:H10) -> 0.092857143
A14: Mean | B14: =AVERAGE(H4:H10) -> 0.1012082
A15: First quartile | B15: =QUARTILE(H4:H10,1) -> 0.087142857
A16: Third quartile | B16: =QUARTILE(H4:H10,3) -> 0.12721976
A17: Minimum | B17: =MIN(H4:H10) -> 0.049375
A18: Maximum | B18: =MAX(H4:H10) -> 0.1375
A19: Median P/TBV paid (memo, not RoTE-adjusted) | B19: =MEDIAN(F4:F10) -> 1.45
A20: Implied value for BNP (control basis)
A21: BNP RoTE FY26E | B21: =DDM!C49 -> 0.12502485
A22: Implied P/TBV (median x RoTE points) | B22: =B13*B21*100 -> 1.160945
A23: BNP TBVPS (Jun-26) | B23: =Data!$B$22 -> 98.4
A24: Implied value per share (EUR) | B24: =B22*B23 -> 114.23699
A25: Low - first quartile (EUR) | B25: =B15*B21*100*B23 -> 107.20702
A26: High - third quartile (EUR) | B26: =B16*B21*100*B23 -> 156.51141
A28: Raw P/TBV multiples are not comparable across targets: a bank earning 20% on tangible equity is worth twice one earning 10%. Each multiple is therefore normalised by the target's RoTE before being applied to BNP. BBVA / Sabadell excluded (failed offer, TBV basis uncertain).

Sheet Football_Field
B1: BNP Paribas - Valuation Summary (EUR per share)
A3: Methodology | B3: Low | C3: High | D3: Basis
A4: Excess-capital DDM | B4: =Sensitivity!E9 -> 114.73126 | C4: =Sensitivity!E7 -> 126.92938 | D4: Ke +/- 0.5%, g at base
A5: Gordon justified P/TBV | B5: =Sensitivity!E19 -> 111.77518 | C5: =Sensitivity!E17 -> 123.39291 | D5: Ke +/- 0.5%, long-term RoTE at base
A6: Trading comps - P/TBV vs RoTE | B6: =Trading_Comps!B33 -> 91.131756 | C6: =Trading_Comps!B34 -> 117.63648 | D6: Full SocGen discount to no French discount
A7: Precedent transactions | B7: =Precedent_Transactions!B25 -> 107.20702 | C7: =Precedent_Transactions!B26 -> 156.51141 | D7: P/TBV per RoTE point, Q1-Q3
A8: 2026 trading range | B8: =Data!$B$7 -> 78.83 | C8: =Data!$B$8 -> 113.82 | D8: Euronext, year to date
A9: Analyst price targets | B9: =Data!$B$41 -> 100 | C9: =Data!$B$42 -> 136 | D9: Investing.com consensus
A11: Current share price | B11: =Data!$B$2 -> 83.52
A12: Blended target price | B12: =Cover!B16 -> 112.51651

Sheet Chart_Data
A1: Chart Data - staging area (green = links, black = formulas)
A3: FOOTBALL FIELD
A4: Method | B4: Low | C4: High | D4: Low_base | E4: Range
A5: =Football_Field!A4 -> Excess-capital DDM | B5: =Football_Field!B4 -> 114.73126 | C5: =Football_Field!C4 -> 126.92938 | D5: =B5 -> 114.73126 | E5: =C5-B5 -> 12.198118
A6: =Football_Field!A5 -> Gordon justified P/TBV | B6: =Football_Field!B5 -> 111.77518 | C6: =Football_Field!C5 -> 123.39291 | D6: =B6 -> 111.77518 | E6: =C6-B6 -> 11.617726
A7: =Football_Field!A6 -> Trading comps - P/TBV vs RoTE | B7: =Football_Field!B6 -> 91.131756 | C7: =Football_Field!C6 -> 117.63648 | D7: =B7 -> 91.131756 | E7: =C7-B7 -> 26.504721
A8: =Football_Field!A7 -> Precedent transactions | B8: =Football_Field!B7 -> 107.20702 | C8: =Football_Field!C7 -> 156.51141 | D8: =B8 -> 107.20702 | E8: =C8-B8 -> 49.304385
A9: =Football_Field!A8 -> 2026 trading range | B9: =Football_Field!B8 -> 78.83 | C9: =Football_Field!C8 -> 113.82 | D9: =B9 -> 78.83 | E9: =C9-B9 -> 34.99
A10: =Football_Field!A9 -> Analyst price targets | B10: =Football_Field!B9 -> 100 | C10: =Football_Field!C9 -> 136 | D10: =B10 -> 100 | E10: =C10-B10 -> 36
A12: DDM EQUITY VALUE BUILD (EUR m)
A13: Step | B13: Base | C13: Delta
A14: Remaining FY26E distribution | B14: 0 | C14: =Bridge!B4 -> 4187.4547
A15: PV FY27E-31E distributions | B15: =C14 -> 4187.4547 | C15: =Bridge!B5 -> 45439.545
A16: PV terminal value | B16: =B15+C15 -> 49627 | C16: =Bridge!B6 -> 82955.498
A17: Equity value | B17: 0 | C17: =Bridge!B7 -> 132582.5
A19: COST OF EQUITY BUILD-UP
A20: Step | B20: Base | C20: Delta
A21: OAT 10Y | B21: 0 | C21: =Cost_of_Equity!B5 -> 0.0493
A22: + Beta x ERP | B22: =C21 -> 0.0493 | C22: =Cost_of_Equity!B8*Cost_of_Equity!B6 -> 0.0686345
A23: CAPM cost of equity | B23: 0 | C23: =Cost_of_Equity!B9 -> 0.1179345
A24: Implied by share price | B24: 0 | C24: =Cost_of_Equity!B14 -> 0.15942055
A26: VALUATION BY METHOD (EUR / share)
A27: Method | B27: Price
A28: Excess-capital DDM | B28: =Bridge!B9 -> 120.51859
A29: Gordon P/TBV | B29: =Bridge!C9 -> 117.28748
A30: Trading comps | B30: =Trading_Comps!B32 -> 102.65555
A31: Precedents | B31: =Precedent_Transactions!B24 -> 114.23699
A32: Blended target | B32: =Cover!B16 -> 112.51651
A33: Consensus target | B33: =Data!$B$40 -> 118.06
A34: Current price | B34: =Data!$B$2 -> 83.52
A36: REVENUES BY DIVISION (EUR m)
A37: Division \ Year | B37: FY24A | C37: FY25A | D37: FY26E | E37: FY27E | F37: FY28E | G37: FY29E | H37: FY30E | I37: FY31E
A38: CPBS | B38: =Income_Statement!B27 -> 26050 | C38: =Income_Statement!C27 -> 26717 | D38: =DDM!C5 -> 27731.97 | E38: =DDM!D5 -> 28979.909 | F38: =DDM!E5 -> 30284.005 | G38: =DDM!F5 -> 31495.365 | H38: =DDM!G5 -> 32597.702 | I38: =DDM!H5 -> 33738.622
A39: IPS | B39: =Income_Statement!B28 -> 5793 | C39: =Income_Statement!C28 -> 6929 | D39: =DDM!C6 -> 7844 | E39: =DDM!D6 -> 8314.64 | F39: =DDM!E6 -> 8813.5184 | G39: =DDM!F6 -> 9254.1943 | H39: =DDM!G6 -> 9716.904 | I39: =DDM!H6 -> 10154.165
A40: CIB | B40: =Income_Statement!B29 -> 17993 | C40: =Income_Statement!C29 -> 18997 | D40: =DDM!C7 -> 19995.6 | E40: =DDM!D7 -> 20795.424 | F40: =DDM!E7 -> 21627.241 | G40: =DDM!F7 -> 22492.331 | H40: =DDM!G7 -> 23279.562 | I40: =DDM!H7 -> 24094.347
A41: Corporate Centre | B41: =Income_Statement!B30 -> -1005 | C41: =Income_Statement!C30 -> -1420 | D41: =DDM!C8 -> -546 | E41: =DDM!D8 -> -500 | F41: =DDM!E8 -> -500 | G41: =DDM!F8 -> -500 | H41: =DDM!G8 -> -500 | I41: =DDM!H8 -> -500
A42: Group | B42: =SUM(B38:B41) -> 48831 | C42: =SUM(C38:C41) -> 51223 | D42: =SUM(D38:D41) -> 55025.57 | E42: =SUM(E38:E41) -> 57589.973 | F42: =SUM(F38:F41) -> 60224.764 | G42: =SUM(G38:G41) -> 62741.89 | H42: =SUM(H38:H41) -> 65094.169 | I42: =SUM(I38:I41) -> 67487.134
A44: NET INCOME AND RoTE
A45: Year | B45: Net income | C45: RoTE
A46: FY24A | B46: =Income_Statement!B14 -> 11688 | C46: =Data!$B$25 -> 0.109
...
