Workbook

Sheet Cover
B1: LVMH Moet Hennessy Louis Vuitton SE - Equity Research Summary
A3: Company | B3: LVMH Moet Hennessy Louis Vuitton SE
A4: Ticker | B4: MC FP (Euronext Paris)
A5: Sector | B5: Luxury Goods (diversified)
A6: Pricing date | B6: 46322
A7: Recommendation | B7: =IF(B10>=0.15,"BUY",IF(B10<=-0.1,"SELL","HOLD")) -> BUY
A8: Current price (EUR) | B8: =WACC!B14 -> 388.1
A9: Target price (EUR, 12-month) | B9: =B16 -> 504.84187
A10: Upside / (downside) | B10: =B9/B8-1 -> 0.30080358
A11: TARGET PRICE METHODOLOGY | B11: EUR / share | C11: Weight
A12: DCF (average Gordon / Exit) | B12: =(Bridge!B12+Bridge!C12)/2 -> 501.66658 | C12: 0.5
A13: Trading comps - Sum-of-the-parts | B13: =Trading_Comps!G42 -> 449.69012 | C13: 0.35
A14: Precedent transactions (scale-relevant median) | B14: =Precedent_Transactions!B31 -> 644.11358 | C14: 0.15
A15: Weights check | B15: =SUM(C12:C14) -> 1
A16: Target price (EUR) | B16: =SUMPRODUCT(B12:B14,C12:C14) -> 504.84187
A17: VALUATION SUMMARY (EUR / share)
A18: DCF - Gordon | B18: =Bridge!B12 -> 480.3089
A19: DCF - Exit | B19: =Bridge!C12 -> 523.02426
A20: Trading comps - group EV/EBIT (median) | B20: =Trading_Comps!B27 -> 545.34915
A21: Sum-of-the-parts | B21: =Trading_Comps!G42 -> 449.69012
A22: Precedent transactions | B22: =Precedent_Transactions!B31 -> 644.11358
A23: 52-week low / high | B23: =Data!$B$7 -> 375.65 | C23: =Data!$B$8 -> 654.7
A24: Analyst consensus (avg / low / high) | B24: =Data!$B$25 -> 491.54 | C24: =Data!$B$26 -> 415 | D24: =Data!$B$27 -> 590
A25: KEY STATISTICS
A26: Market cap (EUR m) | B26: =WACC!B16 -> 192093.2
A27: Net financial debt, 30-Jun-26 (EUR m) | B27: =WACC!B17 -> 8245
A28: Enterprise value incl. minorities (EUR m) | B28: =Trading_Comps!I13 -> 205161.2
A29: Diluted shares (m) | B29: =WACC!B15 -> 494.958
A30: EV / EBIT FY26E | B30: =Trading_Comps!M13 -> 11.9286
A31: P/E FY26E | B31: =Trading_Comps!O13 -> 17.43232
A32: Dividend yield (FY25 DPS) | B32: =Data!$B$10/B8 -> 0.033496522
A33: WACC | B33: =WACC!B21 -> 0.081116803
A34: Credit rating (S&P / Moody's) | B34: =Data!$B$23&" / "&Data!$B$24 -> AA- / Aa3
A36: Disclaimer | B36: Educational use only - not investment advice. Built on public filings and consensus data as of 27-Oct-2026.
A37: Colour code | B37: Blue = hard-coded inputs | Green = links to other tabs | Black = formulas

Sheet Data
A1: field | B1: value | C1: unit | D1: currency | E1: as_of_date | F1: source | G1: auto
A2: share_price | B2: 388.1 | C2: per_share | D2: EUR | E2: 46322 | F2: Euronext Paris close 27-Oct-2026 (ABC Bourse) | G2: Y
A3: shares_diluted | B3: 494.958 | C3: million | E3: 46203 | F3: LVMH H1-2026 release: diluted weighted average shares 494,957,592 | G3: N
A4: shares_issued | B4: 497.687 | C4: million | E4: 46078 | F4: AMF notice 226C0219: share capital of 497,686,940 shares | G4: N
A5: isin | B5: FR0000121014 | F5: Euronext | G5: N
A6: ticker_bbg | B6: MC FP | F6: Bloomberg | G6: N
A7: 52w_low | B7: 375.65 | C7: per_share | D7: EUR | E7: 46308 | F7: Euronext intraday low 13-Oct-2026 (Boursorama / Investing.com) | G7: Y
A8: 52w_high | B8: 654.7 | C8: per_share | D8: EUR | E8: 46307 | F8: Investing.com 52-week high | G8: Y
A9: beta_raw | B9: 0.86 | E9: 46235 | F9: Lightyear market data (raw beta) | G9: Y
A10: dps_fy25 | B10: 13 | C10: per_share | D10: EUR | E10: 46022 | F10: LVMH FY-2025 release (5.50 interim + 7.50 final) | G10: N
A11: interim_dps_fy26 | B11: 5.5 | C11: per_share | D11: EUR | E11: 46230 | F11: LVMH H1-2026 release, payable 3-Dec-2026 | G11: N
A12: net_financial_debt | B12: 8245 | C12: million | D12: EUR | E12: 46203 | F12: LVMH H1-2026 release (excl. lease liabilities) | G12: N
A13: purchase_commitments_minorities | B13: 6416 | C13: million | D13: EUR | E13: 46203 | F13: H1-2026 balance sheet (incl. Diageo 34% of Moet Hennessy) | G13: N
A14: minority_interests | B14: 1599 | C14: million | D14: EUR | E14: 46203 | F14: H1-2026 balance sheet | G14: N
A15: investments_jv_associates | B15: 1225 | C15: million | D15: EUR | E15: 46203 | F15: H1-2026 balance sheet | G15: N
A16: non_current_afs_assets | B16: 1967 | C16: million | D16: EUR | E16: 46203 | F16: H1-2026 balance sheet (non-current available-for-sale financial assets) | G16: N
A17: lease_liabilities | B17: 16261 | C17: million | D17: EUR | E17: 46203 | F17: H1-2026 balance sheet (13,509 non-current + 2,752 current) - memo only | G17: N
A18: h1_26_operating_fcf | B18: 4100 | C18: million | D18: EUR | E18: 46203 | F18: LVMH H1-2026 release (operating free cash flow) | G18: N
A19: risk_free_bund_10y | B19: 3.37 | C19: % | E19: 46321 | F19: German Bund 10Y (Bundesbank via ideal-investisseur.fr) | G19: Y
A20: oat_10y | B20: 4.93 | C20: % | E20: 46321 | F20: French OAT 10Y (Banque de France) - memo, see WACC note | G20: Y
A21: erp | B21: 5.5 | C21: % | E21: 46296 | F21: Mature-market ERP + France premium (Damodaran), same as Pernod model | G21: N
A22: cost_of_debt_pre_tax | B22: 3.375 | C22: % | E22: 46076 | F22: LVMH EMTN 3.375% due 23-Feb-2036 (lvmh.com debt page) | G22: N
A23: credit_rating_sp | B23: AA- | F23: lvmh.com - S&P long-term, stable | G23: N
A24: credit_rating_moodys | B24: Aa3 | F24: lvmh.com - Moody's long-term, stable | G24: N
A25: consensus_tp_avg | B25: 491.54 | C25: per_share | D25: EUR | E25: 46321 | F25: MarketScreener consensus, 27 analysts | G25: Y
A26: consensus_tp_low | B26: 415 | C26: per_share | D26: EUR | E26: 46321 | F26: MarketScreener - lowest target | G26: Y
A27: consensus_tp_high | B27: 590 | C27: per_share | D27: EUR | E27: 46321 | F27: MarketScreener - highest target | G27: Y
A28: fx_usd_per_eur | B28: 1.1216 | C28: USD | E28: 46315 | F28: Mid-market EUR/USD (currencyconvert.online) | G28: Y
A29: fx_chf_per_eur | B29: 0.9396 | C29: CHF | E29: 46266 | F29: EUR/CHF close (poundsterlinglive) - latest available | G29: Y
A30: fx_hkd_per_usd | B30: 7.8 | C30: HKD | F30: HKD peg (7.75-7.85 band) | G30: N
A32: Primary sources
A33: LVMH FY-2025 results (27-Jan-2026) and Financial Documents 31-Dec-2025 - lvmh.com
A34: LVMH H1-2026 results (27-Jul-2026) - globenewswire / lvmh.com; Q3-2026 revenue release (12-Oct-2026)
A35: Peer filings: Hermes FY25, Richemont FY Mar-26, Kering FY25, Prada H1-26, Moncler H1-26, Pernod Ricard FY Jun-26, Diageo FY Jun-26 (SEC 6-K), Ulta Q2 FY26 (SEC 8-K)
A36: Consensus estimates 2026E: MarketScreener / Zonebourse (Sep-Oct 2026)
A37: Precedent transactions: Tiffany DEFM14A (SEC, 2020), KPMG Advisory, FT/BeautyMatter, BoF, BSIC

Sheet Assumptions
B1: LVMH - Key Assumptions
A3: Driver | B3: FY26E | C3: FY27E | D3: FY28E | E3: FY29E | F3: FY30E | G3: FY31E | H3: Rationale / source
A4: Net sales growth by business group (reported, % YoY)
A5: Wines & Spirits growth % | B5: =DCF!C5/DCF!B5-1 -> 0.03397723 | C5: 0.03 | D5: 0.04 | E5: 0.04 | F5: 0.04 | G5: 0.04 | H5: Champagne & cognac trough; 9M-26 organic +5%, depleted US/China trade stock rebuilds slowly
A6: Fashion & Leather Goods growth % | B6: =DCF!C6/DCF!B6-1 -> -0.043059571 | C6: 0.01 | D6: 0.05 | E6: 0.06 | F6: 0.06 | G6: 0.05 | H6: Q3-26 organic -5% (China). Creative reset (Dior, Celine, Loewe) assumed to pay from 2028
A7: Perfumes & Cosmetics growth % | B7: =DCF!C7/DCF!B7-1 -> -0.0092145828 | C7: 0.03 | D7: 0.04 | E7: 0.04 | F7: 0.04 | G7: 0.04 | H7: Prestige fragrance growth, selective distribution; 9M-26 organic +1%
A8: Watches & Jewelry growth % | B8: =DCF!C8/DCF!B8-1 -> 0.05067614 | C8: 0.06 | D8: 0.06 | E8: 0.06 | F8: 0.05 | G8: 0.05 | H8: Jewellery-led (Tiffany, Bulgari); 9M-26 organic +8%
A9: Selective Retailing growth % | B9: =DCF!C9/DCF!B9-1 -> -0.0012153913 | C9: 0.02 | D9: 0.05 | E9: 0.05 | F9: 0.05 | G9: 0.04 | H9: Sephora share gains; 2027 still carries DFS Greater China / airport disposals
A10: Other activities & eliminations growth % | B10: =DCF!C10/DCF!B10-1 -> 0.15946349 | C10: 0 | D10: 0 | E10: 0 | F10: 0 | G10: 0 | H10: Holding, media and eliminations held flat
A11: Group net sales growth % (memo) | B11: =DCF!C11/DCF!B11-1 -> -0.011181457 | C11: =DCF!D11/DCF!C11-1 -> 0.022504103 | D11: =DCF!E11/DCF!D11-1 -> 0.049233864 | E11: =DCF!F11/DCF!E11-1 -> 0.053757364 | F11: =DCF!G11/DCF!F11-1 -> 0.052385185 | G11: =DCF!H11/DCF!G11-1 -> 0.045652368
A12: PRO margin by business group (% of business-group sales)
A13: Wines & Spirits PRO margin % | B13: 0.205 | C13: 0.21 | D13: 0.22 | E13: 0.23 | F13: 0.24 | G13: 0.24 | H13: H1-26 22.4%; FY25 19.0%; recovery towards FY24 23.1% as volumes return
A14: Fashion & Leather Goods PRO margin % | B14: 0.34 | C14: 0.34 | D14: 0.35 | E14: 0.36 | F14: 0.365 | G14: 0.365 | H14: H1-26 34.1%, H2 dilution from Q3 sales decline; FY23 peak 39.9% not assumed
A15: Perfumes & Cosmetics PRO margin % | B15: 0.095 | C15: 0.095 | D15: 0.1 | E15: 0.105 | F15: 0.11 | G15: 0.11 | H15: H1-26 10.7%; FY25 8.9%; gradual operating leverage
A16: Watches & Jewelry PRO margin % | B16: 0.15 | C16: 0.155 | D16: 0.165 | E16: 0.175 | F16: 0.18 | G16: 0.18 | H16: H1-26 15.9%; Tiffany renovation capex rolls off; FY23 19.8%
A17: Selective Retailing PRO margin % | B17: 0.1 | C17: 0.1 | D17: 0.105 | E17: 0.105 | F17: 0.11 | G17: 0.11 | H17: H1-26 10.6%; DFS restructuring done, Sephora scale
A18: Other activities & eliminations PRO (EUR m) | B18: -480 | C18: -480 | D18: -490 | E18: -500 | F18: -510 | G18: -520 | H18: FY25 -491, H1-26 -228 (holding costs, media)
A19: Cash flow drivers (% of group net sales)
A20: D&A excl. right-of-use % | B20: 0.056 | C20: 0.056 | D20: 0.056 | E20: 0.056 | F20: 0.056 | G20: 0.056 | H20: FY25 6.0%, FY24 5.4%, FY23 4.8% (incl. provisions)
A21: Capex % | B21: 0.055 | C21: 0.058 | D21: 0.06 | E21: 0.06 | F21: 0.06 | G21: 0.06 | H21: FY25 5.7%, H1-26 5.3%; normalises for store renovations
A22: Change in NWC % (negative = cash outflow) | B22: -0.01 | C22: -0.008 | D22: -0.008 | E22: -0.008 | F22: -0.008 | G22: -0.008 | H22: FY25 -0.7%, FY24 -2.3%; inventory discipline assumed
A23: Net lease cost % (lease cash out - ROU dep.) | B23: 0.005 | C23: 0.005 | D23: 0.005 | E23: 0.005 | F23: 0.005 | G23: 0.005 | H23: FY25 0.47% of sales; keeps the DCF on a pre-IFRS 16 basis
A24: Tax rate on PRO % | B24: 0.3 | C24: 0.27 | D24: 0.27 | E24: 0.27 | F24: 0.27 | G24: 0.27 | H24: FY25 ETR 32.8% incl. French surtax; surtax assumed to lapse after 2026
A25: Capital return & financing (net debt roll-forward)
A26: Dividend paid in the year (EUR / share) | B26: =Data!$B$11 -> 5.5 | C26: 13 | D26: 13.5 | E26: 14 | F26: 14.5 | G26: 15 | H26: FY26E = H2 interim only; then final + interim, flat-to-rising payout
A27: Buybacks, minority buy-outs & M&A (EUR m) | B27: 500 | C27: 1500 | D27: 1500 | E27: 1500 | F27: 1500 | G27: 1500 | H27: FY25: 1,634 equity-related + 1,091 minorities; H2-26E only in FY26E column
A28: Net interest paid after tax (EUR m) | B28: 125 | C28: 250 | D28: 250 | E28: 250 | F28: 250 | G28: 250 | H28: FY25 cost of net financial debt 348 pre-tax
A29: Terminal value
A30: Perpetuity growth rate g % | B30: 0.025 | H30: Long-run nominal growth of global luxury demand (real ~1% + inflation ~1.5-2%)
A31: Exit EV/EBITDA multiple (pre-IFRS 16) | B31: 11 | H31: Modest re-rating from ~9.6x today, well below the ~15x 10-year average; implied g ~2.9% vs 2.5% Gordon
A32: FY26E P&L items below PRO (for EPS / P/E)
A33: Other operating income & expenses FY26E (EUR m) | B33: -300 | H33: H1-26 +23; FY25 -656 (restructuring, impairments)
A34: Net financial income / (expense) FY26E (EUR m) | B34: -300 | H34: H1-26 -112 incl. +341 other financial income; FY25 -401
A35: Minority interests FY26E (EUR m) | B35: -600 | H35: H1-26 -322; FY25 -344
A37: Blue = hard-coded input (edit these). Green = link to another tab. Black = formula. Grey fill = key scenario levers.

Sheet Income_Statement
B1: LVMH - Consolidated Income Statement (EUR m, FYE 31 December)
A3: EUR millions | B3: FY23A | C3: FY24A | D3: FY25A | E3: H1-25A | F3: H1-26A
A4: Revenue | B4: 86153 | C4: 84683 | D4: 80807 | E4: 39810 | F4: 38644
A5: Cost of sales | B5: -26876 | C5: -27918 | D5: -27279 | E5: -13200 | F5: -12708
A6: Gross margin | B6: =B4+B5 -> 59277 | C6: =C4+C5 -> 56765 | D6: =D4+D5 -> 53528 | E6: =E4+E5 -> 26610 | F6: =F4+F5 -> 25936
A7: Marketing & selling expenses | B7: -30768 | C7: -31002 | D7: -29914 | E7: -14732 | F7: -14392
A8: General & administrative expenses | B8: -5714 | C8: -6220 | D8: -5934 | E8: -2889 | F8: -2876
A9: Income from joint ventures & associates | B9: 7 | C9: 28 | D9: 75 | E9: 23 | F9: 23
A10: Profit from recurring operations (PRO) | B10: =B6+B7+B8+B9 -> 22802 | C10: =C6+C7+C8+C9 -> 19571 | D10: =D6+D7+D8+D9 -> 17755 | E10: =E6+E7+E8+E9 -> 9012 | F10: =F6+F7+F8+F9 -> 8691
A11: Other operating income & expenses | B11: -242 | C11: -664 | D11: -656 | E11: -14 | F11: 23
A12: Operating profit | B12: =B10+B11 -> 22560 | C12: =C10+C11 -> 18907 | D12: =D10+D11 -> 17099 | E12: =E10+E11 -> 8998 | F12: =F10+F11 -> 8714
A13: Cost of net financial debt | B13: -367 | C13: -442 | D13: -348 | E13: -211 | F13: -192
A14: Interest on lease liabilities | B14: -393 | C14: -510 | D14: -553 | E14: -278 | F14: -261
A15: Other financial income & expenses | B15: -175 | C15: 160 | D15: 500 | E15: 54 | F15: 341
A16: Net financial income / (expense) | B16: =SUM(B13:B15) -> -935 | C16: =SUM(C13:C15) -> -792 | D16: =SUM(D13:D15) -> -401 | E16: =SUM(E13:E15) -> -435 | F16: =SUM(F13:F15) -> -112
A17: Income taxes | B17: -5673 | C17: -5157 | D17: -5476 | E17: -2648 | F17: -2583
A18: Net profit | B18: =B12+B16+B17 -> 15952 | C18: =C12+C16+C17 -> 12958 | D18: =D12+D16+D17 -> 11222 | E18: =E12+E16+E17 -> 5915 | F18: =F12+F16+F17 -> 6019
A19: Minority interests | B19: -778 | C19: -408 | D19: -344 | E19: -217 | F19: -322
A20: Net profit, Group share | B20: =B18+B19 -> 15174 | C20: =C18+C19 -> 12550 | D20: =D18+D19 -> 10878 | E20: =E18+E19 -> 5698 | F20: =F18+F19 -> 5697
A21: Diluted shares (m, weighted average) | B21: 500.304 | C21: 499.681 | D21: 497.976 | E21: 498.738 | F21: 494.958
A22: Diluted EPS (EUR) | B22: =B20/B21 -> 30.32956 | C22: =C20/C21 -> 25.116024 | D22: =D20/D21 -> 21.844426 | E22: =E20/E21 -> 11.424836 | F22: =F20/F21 -> 11.510068
A24: Cash flow & lease items
A25: D&A and provisions (excl. right-of-use) | B25: 4146 | C25: 4568 | D25: 4858 | E25: 1866 | F25: 1767
A26: Depreciation of right-of-use assets | B26: 3031 | C26: 3228 | D26: 3143 | E26: 1595 | F26: 1550
A27: Repayment of lease liabilities | B27: -2818 | C27: -2915 | D27: -2974 | E27: -1489 | F27: -1486
A28: Lease interest paid (H1: P&L charge) | B28: -356 | C28: -483 | D28: -545 | E28: -278 | F28: -261 | G28: H1 columns use the P&L lease interest charge
A29: Operating investments (capex) | B29: -7478 | C29: -5531 | D29: -4567 | E29: -2360 | F29: -2061
A30: Change in working capital | B30: -4577 | C30: -1925 | D30: -576 | G30: H1 change in WC not disclosed in release
A31: Operating free cash flow (reported) | B31: 8104 | C31: 10478 | D31: 11333 | E31: 4032 | F31: 4100
A32: Net financial debt (period-end) | B32: 10746 | C32: 9228 | D32: 6857 | E32: 10176 | F32: 8245
A34: Key metrics
A35: Revenue growth (reported) | C35: =C4/B4-1 -> -0.017062668 | D35: =D4/C4-1 -> -0.045770698 | F35: =F4/E4-1 -> -0.029289123
A36: Gross margin % | B36: =B6/B4 -> 0.68804336 | C36: =C6/C4 -> 0.67032344 | D36: =D6/D4 -> 0.66241786 | E36: =E6/E4 -> 0.66842502 | F36: =F6/F4 -> 0.67115205
A37: PRO margin % | B37: =B10/B4 -> 0.26466867 | C37: =C10/C4 -> 0.23110896 | D37: =D10/D4 -> 0.21972106 | E37: =E10/E4 -> 0.22637528 | F37: =F10/F4 -> 0.22489908
A38: Net lease cost (lease cash out - ROU depreciation) | B38: =-(B27+B28)-B26 -> 143 | C38: =-(C27+C28)-C26 -> 170 | D38: =-(D27+D28)-D26 -> 376 | E38: =-(E27+E28)-E26 -> 172 | F38: =-(F27+F28)-F26 -> 197
A39: EBITDA, pre-IFRS 16 basis (PRO + D&A - net lease cost) | B39: =B10+B25-B38 -> 26805 | C39: =C10+C25-C38 -> 23969 | D39: =D10+D25-D38 -> 22237 | E39: =E10+E25-E38 -> 10706 | F39: =F10+F25-F38 -> 10261
A40: EBITDA margin % | B40: =B39/B4 -> 0.31113252 | C40: =C39/C4 -> 0.28304382 | D40: =D39/D4 -> 0.27518656 | E40: =E39/E4 -> 0.26892741 | F40: =F39/F4 -> 0.26552634
A41: Effective tax rate % | B41: =-B17/(B12+B16) -> 0.26233526 | C41: =-C17/(C12+C16) -> 0.2846812 | D41: =-D17/(D12+D16) -> 0.32794347 | E41: =-E17/(E12+E16) -> 0.30923742 | F41: =-F17/(F12+F16) -> 0.300279
A42: Net financial debt / EBITDA (x) | B42: =B32/B39 -> 0.40089536 | C42: =C32/C39 -> 0.38499729 | D42: =D32/D39 -> 0.30835994
A44: Revenue by business group (EUR m)
...

Sheet DCF
B1: LVMH - DCF Model (valuation at 31-Dec-2026, EUR m)
A3: EUR m | B3: FY25A | C3: FY26E | D3: FY27E | E3: FY28E | F3: FY29E | G3: FY30E | H3: FY31E
A4: Net sales by business group | J4: FY26E build | K4: 9M-26A | L4: Q4-25A | M4: Q4-26E growth | N4: Q4-26E | O4: FY26E
A5: Wines & Spirits | B5: =Income_Statement!D46 -> 5358 | C5: =O5 -> 5540.05 | D5: =C5*(1+Assumptions!C5) -> 5706.2515 | E5: =D5*(1+Assumptions!D5) -> 5934.5016 | F5: =E5*(1+Assumptions!E5) -> 6171.8816 | G5: =F5*(1+Assumptions!F5) -> 6418.7569 | H5: =G5*(1+Assumptions!G5) -> 6675.5072 | J5: W&S | K5: 4027 | L5: 1441 | M5: 0.05 | N5: =L5*(1+M5) -> 1513.05 | O5: =K5+N5 -> 5540.05
A6: Fashion & Leather Goods | B6: =Income_Statement!D47 -> 37770 | C6: =O6 -> 36143.64 | D6: =C6*(1+Assumptions!C6) -> 36505.076 | E6: =D6*(1+Assumptions!D6) -> 38330.33 | F6: =E6*(1+Assumptions!E6) -> 40630.15 | G6: =F6*(1+Assumptions!F6) -> 43067.959 | H6: =G6*(1+Assumptions!G6) -> 45221.357 | J6: F&LG | K6: 26391 | L6: 10159 | M6: -0.04 | N6: =L6*(1+M6) -> 9752.64 | O6: =K6+N6 -> 36143.64
A7: Perfumes & Cosmetics | B7: =Income_Statement!D48 -> 8174 | C7: =O7 -> 8098.68 | D7: =C7*(1+Assumptions!C7) -> 8341.6404 | E7: =D7*(1+Assumptions!D7) -> 8675.306 | F7: =E7*(1+Assumptions!E7) -> 9022.3183 | G7: =F7*(1+Assumptions!F7) -> 9383.211 | H7: =G7*(1+Assumptions!G7) -> 9758.5394 | J7: P&C | K7: 5922 | L7: 2134 | M7: 0.02 | N7: =L7*(1+M7) -> 2176.68 | O7: =K7+N7 -> 8098.68
A8: Watches & Jewelry | B8: =Income_Statement!D49 -> 10486 | C8: =O8 -> 11017.39 | D8: =C8*(1+Assumptions!C8) -> 11678.433 | E8: =D8*(1+Assumptions!D8) -> 12379.139 | F8: =E8*(1+Assumptions!E8) -> 13121.888 | G8: =F8*(1+Assumptions!F8) -> 13777.982 | H8: =G8*(1+Assumptions!G8) -> 14466.881 | J8: W&J | K8: 7725 | L8: 3077 | M8: 0.07 | N8: =L8*(1+M8) -> 3292.39 | O8: =K8+N8 -> 11017.39
A9: Selective Retailing | B9: =Income_Statement!D50 -> 18348 | C9: =O9 -> 18325.7 | D9: =C9*(1+Assumptions!C9) -> 18692.214 | E9: =D9*(1+Assumptions!D9) -> 19626.825 | F9: =E9*(1+Assumptions!E9) -> 20608.166 | G9: =F9*(1+Assumptions!F9) -> 21638.574 | H9: =G9*(1+Assumptions!G9) -> 22504.117 | J9: SR | K9: 12476 | L9: 5735 | M9: 0.02 | N9: =L9*(1+M9) -> 5849.7 | O9: =K9+N9 -> 18325.7
A10: Other activities & eliminations | B10: =Income_Statement!D51 -> 671 | C10: =O10 -> 778 | D10: =C10*(1+Assumptions!C10) -> 778 | E10: =D10*(1+Assumptions!D10) -> 778 | F10: =E10*(1+Assumptions!E10) -> 778 | G10: =F10*(1+Assumptions!F10) -> 778 | H10: =G10*(1+Assumptions!G10) -> 778 | J10: Other | K10: 607 | L10: 171 | M10: 0 | N10: =L10*(1+M10) -> 171 | O10: =K10+N10 -> 778
A11: Total net sales | B11: =SUM(B5:B10) -> 80807 | C11: =SUM(C5:C10) -> 79903.46 | D11: =SUM(D5:D10) -> 81701.616 | E11: =SUM(E5:E10) -> 85724.102 | F11: =SUM(F5:F10) -> 90332.404 | G11: =SUM(G5:G10) -> 95064.483 | H11: =SUM(H5:H10) -> 99404.402 | J11: Total | K11: =SUM(K5:K10) -> 57148 | L11: =SUM(L5:L10) -> 22717 | M11: =N11/L11-1 -> 0.0016930052 | N11: =SUM(N5:N10) -> 22755.46 | O11: =SUM(O5:O10) -> 79903.46
A12: Growth % (reported) | C12: =C11/B11-1 -> -0.011181457 | D12: =D11/C11-1 -> 0.022504103 | E12: =E11/D11-1 -> 0.049233864 | F12: =F11/E11-1 -> 0.053757364 | G12: =G11/F11-1 -> 0.052385185 | H12: =H11/G11-1 -> 0.045652368 | J12: Source: LVMH Q3-2026 revenue release (9M-26 = 57,148), FY-2025 quarterly table (Q4-25 = 22,717)
A14: Profit from recurring operations (PRO) by business group
A15: Wines & Spirits | B15: =Income_Statement!D57 -> 1016 | C15: =C5*Assumptions!B13 -> 1135.7103 | D15: =D5*Assumptions!C13 -> 1198.3128 | E15: =E5*Assumptions!D13 -> 1305.5903 | F15: =F5*Assumptions!E13 -> 1419.5328 | G15: =G5*Assumptions!F13 -> 1540.5017 | H15: =H5*Assumptions!G13 -> 1602.1217
A16: Fashion & Leather Goods | B16: =Income_Statement!D58 -> 13209 | C16: =C6*Assumptions!B14 -> 12288.838 | D16: =D6*Assumptions!C14 -> 12411.726 | E16: =E6*Assumptions!D14 -> 13415.616 | F16: =F6*Assumptions!E14 -> 14626.854 | G16: =G6*Assumptions!F14 -> 15719.805 | H16: =H6*Assumptions!G14 -> 16505.795
A17: Perfumes & Cosmetics | B17: =Income_Statement!D59 -> 727 | C17: =C7*Assumptions!B15 -> 769.3746 | D17: =D7*Assumptions!C15 -> 792.45584 | E17: =E7*Assumptions!D15 -> 867.5306 | F17: =F7*Assumptions!E15 -> 947.34342 | G17: =G7*Assumptions!F15 -> 1032.1532 | H17: =H7*Assumptions!G15 -> 1073.4393
A18: Watches & Jewelry | B18: =Income_Statement!D60 -> 1514 | C18: =C8*Assumptions!B16 -> 1652.6085 | D18: =D8*Assumptions!C16 -> 1810.1572 | E18: =E8*Assumptions!D16 -> 2042.558 | F18: =F8*Assumptions!E16 -> 2296.3304 | G18: =G8*Assumptions!F16 -> 2480.0368 | H18: =H8*Assumptions!G16 -> 2604.0386
A19: Selective Retailing | B19: =Income_Statement!D61 -> 1780 | C19: =C9*Assumptions!B17 -> 1832.57 | D19: =D9*Assumptions!C17 -> 1869.2214 | E19: =E9*Assumptions!D17 -> 2060.8166 | F19: =F9*Assumptions!E17 -> 2163.8574 | G19: =G9*Assumptions!F17 -> 2380.2432 | H19: =H9*Assumptions!G17 -> 2475.4529
A20: Other activities & eliminations | B20: =Income_Statement!D62 -> -491 | C20: =Assumptions!B18 -> -480 | D20: =Assumptions!C18 -> -480 | E20: =Assumptions!D18 -> -490 | F20: =Assumptions!E18 -> -500 | G20: =Assumptions!F18 -> -510 | H20: =Assumptions!G18 -> -520
A21: Group PRO (EBIT) | B21: =SUM(B15:B20) -> 17755 | C21: =SUM(C15:C20) -> 17199.101 | D21: =SUM(D15:D20) -> 17601.873 | E21: =SUM(E15:E20) -> 19202.111 | F21: =SUM(F15:F20) -> 20953.918 | G21: =SUM(G15:G20) -> 22642.74 | H21: =SUM(H15:H20) -> 23740.848
A22: PRO margin % | B22: =B21/B11 -> 0.21972106 | C22: =C21/C11 -> 0.21524851 | D22: =D21/D11 -> 0.21544094 | E22: =E21/E11 -> 0.22399898 | F22: =F21/F11 -> 0.23196458 | G22: =G21/G11 -> 0.23818296 | H22: =H21/H11 -> 0.23883095
A24: Unlevered free cash flow (pre-IFRS 16 basis: lease payments treated as operating costs)
A25: PRO (EBIT) | C25: =C21 -> 17199.101 | D25: =D21 -> 17601.873 | E25: =E21 -> 19202.111 | F25: =F21 -> 20953.918 | G25: =G21 -> 22642.74 | H25: =H21 -> 23740.848
A26: (-) Taxes on PRO | C26: =-C25*Assumptions!B24 -> -5159.7303 | D26: =-D25*Assumptions!C24 -> -4752.5058 | E26: =-E25*Assumptions!D24 -> -5184.57 | F26: =-F25*Assumptions!E24 -> -5657.5579 | G26: =-G25*Assumptions!F24 -> -6113.5398 | H26: =-H25*Assumptions!G24 -> -6410.0289
A27: NOPAT | C27: =C25+C26 -> 12039.371 | D27: =D25+D26 -> 12849.367 | E27: =E25+E26 -> 14017.541 | F27: =F25+F26 -> 15296.36 | G27: =G25+G26 -> 16529.2 | H27: =H25+H26 -> 17330.819
A28: (+) D&A excl. right-of-use | C28: =C11*Assumptions!B20 -> 4474.5938 | D28: =D11*Assumptions!C20 -> 4575.2905 | E28: =E11*Assumptions!D20 -> 4800.5497 | F28: =F11*Assumptions!E20 -> 5058.6146 | G28: =G11*Assumptions!F20 -> 5323.6111 | H28: =H11*Assumptions!G20 -> 5566.6465
A29: (-) Capex | C29: =-C11*Assumptions!B21 -> -4394.6903 | D29: =-D11*Assumptions!C21 -> -4738.6937 | E29: =-E11*Assumptions!D21 -> -5143.4461 | F29: =-F11*Assumptions!E21 -> -5419.9442 | G29: =-G11*Assumptions!F21 -> -5703.869 | H29: =-H11*Assumptions!G21 -> -5964.2641
A30: (+/-) Change in NWC | C30: =C11*Assumptions!B22 -> -799.0346 | D30: =D11*Assumptions!C22 -> -653.61293 | E30: =E11*Assumptions!D22 -> -685.79282 | F30: =F11*Assumptions!E22 -> -722.65923 | G30: =G11*Assumptions!F22 -> -760.51587 | H30: =H11*Assumptions!G22 -> -795.23522
A31: (-) Net lease cost | C31: =-C11*Assumptions!B23 -> -399.5173 | D31: =-D11*Assumptions!C23 -> -408.50808 | E31: =-E11*Assumptions!D23 -> -428.62051 | F31: =-F11*Assumptions!E23 -> -451.66202 | G31: =-G11*Assumptions!F23 -> -475.32242 | H31: =-H11*Assumptions!G23 -> -497.02201
A32: Unlevered FCF | C32: =SUM(C27:C31) -> 10920.722 | D32: =SUM(D27:D31) -> 11623.843 | E32: =SUM(E27:E31) -> 12560.231 | F32: =SUM(F27:F31) -> 13760.709 | G32: =SUM(G27:G31) -> 14913.104 | H32: =SUM(H27:H31) -> 15640.944
A33: Cash conversion (UFCF / NOPAT) | C33: =C32/C27 -> 0.90708414 | D33: =D32/D27 -> 0.90462377 | E33: =E32/E27 -> 0.89603671 | F33: =F32/F27 -> 0.89960678 | G33: =G32/G27 -> 0.9022278 | H33: =H32/H27 -> 0.90249308
A34: EBITDA, pre-IFRS 16 (PRO + D&A - net lease cost) | B34: =Income_Statement!D39 -> 22237 | C34: =C25+C28+C31 -> 21274.177 | D34: =D25+D28+D31 -> 21768.656 | E34: =E25+E28+E31 -> 23574.04 | F34: =F25+F28+F31 -> 25560.871 | G34: =G25+G28+G31 -> 27491.029 | H34: =H25+H28+H31 -> 28810.472
A35: EBITDA margin % | C35: =C34/C11 -> 0.26624851 | D35: =D34/D11 -> 0.26644094 | E35: =E34/E11 -> 0.27499898 | F35: =F34/F11 -> 0.28296458 | G35: =G34/G11 -> 0.28918296 | H35: =H34/H11 -> 0.28983095
A37: Discount period (years from 31-Dec-2026) | C37: base | D37: 1 | E37: 2 | F37: 3 | G37: 4 | H37: 5
A38: Discount factor | D38: =1/(1+WACC!$B$21)^D37 -> 0.92496944 | E38: =1/(1+WACC!$B$21)^E37 -> 0.85556846 | F38: =1/(1+WACC!$B$21)^F37 -> 0.79137468 | G38: =1/(1+WACC!$B$21)^G37 -> 0.73199739 | H38: =1/(1+WACC!$B$21)^H37 -> 0.67707521
A39: PV of FCF | D39: =D32*D38 -> 10751.7 | E39: =E32*E38 -> 10746.138 | F39: =F32*F38 -> 10889.877 | G39: =G32*G38 -> 10916.353 | H39: =H32*H38 -> 10590.096
A41: PV of explicit FCF (FY27E-FY31E) | B41: =SUM(D39:H39) -> 53894.163
A42: Terminal value (Gordon growth) | B42: =H32*(1+Assumptions!$B$30)/(WACC!$B$21-Assumptions!$B$30) -> 285689.26
A43: EBITDA FY31E (pre-IFRS 16) | B43: =H34 -> 28810.472
A44: Terminal value (exit multiple) | B44: =B43*Assumptions!$B$31 -> 316915.2
A45: PV of terminal value (Gordon) | B45: =B42*H38 -> 193433.12
...

Sheet WACC
B1: LVMH - WACC Model
A3: Label | B3: Value | C3: Comment
A4: Cost of equity
A5: Risk-free rate (10Y Bund) | B5: =Data!$B$19/100 -> 0.0337 | C5: Bund used: LVMH (AA-) borrows below the French sovereign (OAT 4.93%)
A6: Equity risk premium (ERP) | B6: =Data!$B$21/100 -> 0.055 | C6: Same ERP as the Pernod Ricard model
A7: Beta (Blume-adjusted) | B7: =0.67*Data!$B$9+0.33 -> 0.9062 | C7: 0.67 x raw beta 0.86 + 0.33
A8: Cost of equity (Ke) | B8: =B5+B7*B6 -> 0.083541 | C8: CAPM
A9: Cost of debt
A10: Pre-tax cost of debt (Kd) | B10: =Data!$B$22/100 -> 0.03375 | C10: Coupon of the latest 10-year EMTN (Feb-2036)
A11: Tax rate | B11: =Assumptions!C24 -> 0.27 | C11: Normalised rate from FY27E
A12: After-tax cost of debt | B12: =B10*(1-B11) -> 0.0246375
A13: Capital structure
A14: Share price (EUR) | B14: =Data!$B$2 -> 388.1 | C14: Close 27-Oct-2026
A15: Diluted shares (m) | B15: =Data!$B$3 -> 494.958
A16: Market cap (E) | B16: =B14*B15 -> 192093.2 | C16: EUR m
A17: Net financial debt (D) | B17: =Data!$B$12 -> 8245 | C17: 30-Jun-2026, excl. leases
A18: Total capital (V) | B18: =B16+B17 -> 200338.2
A19: Equity weight (E/V) | B19: =B16/B18 -> 0.95884459
A20: Debt weight (D/V) | B20: =B17/B18 -> 0.041155406
A21: WACC | B21: =B19*B8+B20*B12 -> 0.081116803
A23: Memo - WACC with the French OAT as risk-free rate
A24: OAT 10Y | B24: =Data!$B$20/100 -> 0.0493
A25: WACC using OAT | B25: =B19*(B24+B7*B6)+B20*B12 -> 0.096074778 | C25: Shown for transparency; the OAT now embeds a ~156bp French sovereign spread over the Bund

Sheet Bridge
B1: LVMH - EV to Equity Bridge (31-Dec-2026E)
A3: EUR m | B3: Gordon Growth | C3: Exit Multiple
A4: Enterprise value | B4: =DCF!B47 -> 247327.28 | C4: =DCF!B48 -> 268469.59
A5: (-) Net financial debt (31-Dec-26E) | B5: =-DCF!C75 -> -4771.5468 | C5: =B5 -> -4771.5468
A6: (-) Purchase commitments for minority interests | B6: =-Data!$B$13 -> -6416 | C6: =B6 -> -6416
A7: (-) Minority interests | B7: =-Data!$B$14 -> -1599 | C7: =B7 -> -1599
A8: (+) Investments in JV & associates | B8: =Data!$B$15 -> 1225 | C8: =B8 -> 1225
A9: (+) Non-current financial assets | B9: =Data!$B$16 -> 1967 | C9: =B9 -> 1967
A10: Equity value | B10: =SUM(B4:B9) -> 237732.73 | C10: =SUM(C4:C9) -> 258875.04
A11: Diluted shares (m) | B11: =WACC!B15 -> 494.958 | C11: =B11 -> 494.958
A12: Implied value per share (EUR) | B12: =B10/B11 -> 480.3089 | C12: =C10/C11 -> 523.02426
A13: Current share price (EUR) | B13: =WACC!B14 -> 388.1 | C13: =B13 -> 388.1
A14: Implied upside / (downside) | B14: =B12/B13-1 -> 0.23759056 | C14: =C12/C13-1 -> 0.34765333
A16: Memo: lease liabilities (not deducted, see DCF note) | B16: =Data!$B$17 -> 16261

Sheet Sensitivity
B1: LVMH - DCF Sensitivity (EUR per share)
A3: Implied value per share (EUR) - Gordon | C3: Perpetuity growth (g) ->
B4: WACC \ g | C4: =$E$4-0.01 -> 0.015 | D4: =$E$4-0.005 -> 0.02 | E4: =Assumptions!B30 -> 0.025 | F4: =$E$4+0.005 -> 0.03 | G4: =$E$4+0.01 -> 0.035
B5: =$B$8-0.015 -> 0.066116803 | C5: =(SUMPRODUCT(DCF!$D$32:$H$32,(1+$B5)^(-DCF!$D$37:$H$37))+DCF!$H$32*(1+C$4)/($B5-C$4)*(1+$B5)^(-DCF!$H$37)+SUM(Bridge!$B$5:$B$9))/WACC!$B$15 -> 549.76905 | D5: =(SUMPRODUCT(DCF!$D$32:$H$32,(1+$B5)^(-DCF!$D$37:$H$37))+DCF!$H$32*(1+D$4)/($B5-D$4)*(1+$B5)^(-DCF!$H$37)+SUM(Bridge!$B$5:$B$9))/WACC!$B$15 -> 601.65176 | E5: =(SUMPRODUCT(DCF!$D$32:$H$32,(1+$B5)^(-DCF!$D$37:$H$37))+DCF!$H$32*(1+E$4)/($B5-E$4)*(1+$B5)^(-DCF!$H$37)+SUM(Bridge!$B$5:$B$9))/WACC!$B$15 -> 666.15283 | F5: =(SUMPRODUCT(DCF!$D$32:$H$32,(1+$B5)^(-DCF!$D$37:$H$37))+DCF!$H$32*(1+F$4)/($B5-F$4)*(1+$B5)^(-DCF!$H$37)+SUM(Bridge!$B$5:$B$9))/WACC!$B$15 -> 748.51293 | G5: =(SUMPRODUCT(DCF!$D$32:$H$32,(1+$B5)^(-DCF!$D$37:$H$37))+DCF!$H$32*(1+G$4)/($B5-G$4)*(1+$B5)^(-DCF!$H$37)+SUM(Bridge!$B$5:$B$9))/WACC!$B$15 -> 857.34107
B6: =$B$8-0.01 -> 0.071116803 | C6: =(SUMPRODUCT(DCF!$D$32:$H$32,(1+$B6)^(-DCF!$D$37:$H$37))+DCF!$H$32*(1+C$4)/($B6-C$4)*(1+$B6)^(-DCF!$H$37)+SUM(Bridge!$B$5:$B$9))/WACC!$B$15 -> 497.98653 | D6: =(SUMPRODUCT(DCF!$D$32:$H$32,(1+$B6)^(-DCF!$D$37:$H$37))+DCF!$H$32*(1+D$4)/($B6-D$4)*(1+$B6)^(-DCF!$H$37)+SUM(Bridge!$B$5:$B$9))/WACC!$B$15 -> 539.83318 | E6: =(SUMPRODUCT(DCF!$D$32:$H$32,(1+$B6)^(-DCF!$D$37:$H$37))+DCF!$H$32*(1+E$4)/($B6-E$4)*(1+$B6)^(-DCF!$H$37)+SUM(Bridge!$B$5:$B$9))/WACC!$B$15 -> 590.75388 | F6: =(SUMPRODUCT(DCF!$D$32:$H$32,(1+$B6)^(-DCF!$D$37:$H$37))+DCF!$H$32*(1+F$4)/($B6-F$4)*(1+$B6)^(-DCF!$H$37)+SUM(Bridge!$B$5:$B$9))/WACC!$B$15 -> 654.05899 | G6: =(SUMPRODUCT(DCF!$D$32:$H$32,(1+$B6)^(-DCF!$D$37:$H$37))+DCF!$H$32*(1+G$4)/($B6-G$4)*(1+$B6)^(-DCF!$H$37)+SUM(Bridge!$B$5:$B$9))/WACC!$B$15 -> 734.89199
B7: =$B$8-0.005 -> 0.076116803 | C7: =(SUMPRODUCT(DCF!$D$32:$H$32,(1+$B7)^(-DCF!$D$37:$H$37))+DCF!$H$32*(1+C$4)/($B7-C$4)*(1+$B7)^(-DCF!$H$37)+SUM(Bridge!$B$5:$B$9))/WACC!$B$15 -> 454.69373 | D7: =(SUMPRODUCT(DCF!$D$32:$H$32,(1+$B7)^(-DCF!$D$37:$H$37))+DCF!$H$32*(1+D$4)/($B7-D$4)*(1+$B7)^(-DCF!$H$37)+SUM(Bridge!$B$5:$B$9))/WACC!$B$15 -> 489.04742 | E7: =(SUMPRODUCT(DCF!$D$32:$H$32,(1+$B7)^(-DCF!$D$37:$H$37))+DCF!$H$32*(1+E$4)/($B7-E$4)*(1+$B7)^(-DCF!$H$37)+SUM(Bridge!$B$5:$B$9))/WACC!$B$15 -> 530.12174 | F7: =(SUMPRODUCT(DCF!$D$32:$H$32,(1+$B7)^(-DCF!$D$37:$H$37))+DCF!$H$32*(1+F$4)/($B7-F$4)*(1+$B7)^(-DCF!$H$37)+SUM(Bridge!$B$5:$B$9))/WACC!$B$15 -> 580.10264 | G7: =(SUMPRODUCT(DCF!$D$32:$H$32,(1+$B7)^(-DCF!$D$37:$H$37))+DCF!$H$32*(1+G$4)/($B7-G$4)*(1+$B7)^(-DCF!$H$37)+SUM(Bridge!$B$5:$B$9))/WACC!$B$15 -> 642.23938
B8: =WACC!B21 -> 0.081116803 | C8: =(SUMPRODUCT(DCF!$D$32:$H$32,(1+$B8)^(-DCF!$D$37:$H$37))+DCF!$H$32*(1+C$4)/($B8-C$4)*(1+$B8)^(-DCF!$H$37)+SUM(Bridge!$B$5:$B$9))/WACC!$B$15 -> 417.96422 | D8: =(SUMPRODUCT(DCF!$D$32:$H$32,(1+$B8)^(-DCF!$D$37:$H$37))+DCF!$H$32*(1+D$4)/($B8-D$4)*(1+$B8)^(-DCF!$H$37)+SUM(Bridge!$B$5:$B$9))/WACC!$B$15 -> 446.58633 | E8: =(SUMPRODUCT(DCF!$D$32:$H$32,(1+$B8)^(-DCF!$D$37:$H$37))+DCF!$H$32*(1+E$4)/($B8-E$4)*(1+$B8)^(-DCF!$H$37)+SUM(Bridge!$B$5:$B$9))/WACC!$B$15 -> 480.3089 | F8: =(SUMPRODUCT(DCF!$D$32:$H$32,(1+$B8)^(-DCF!$D$37:$H$37))+DCF!$H$32*(1+F$4)/($B8-F$4)*(1+$B8)^(-DCF!$H$37)+SUM(Bridge!$B$5:$B$9))/WACC!$B$15 -> 520.62862 | G8: =(SUMPRODUCT(DCF!$D$32:$H$32,(1+$B8)^(-DCF!$D$37:$H$37))+DCF!$H$32*(1+G$4)/($B8-G$4)*(1+$B8)^(-DCF!$H$37)+SUM(Bridge!$B$5:$B$9))/WACC!$B$15 -> 569.6913
B9: =$B$8+0.005 -> 0.086116803 | C9: =(SUMPRODUCT(DCF!$D$32:$H$32,(1+$B9)^(-DCF!$D$37:$H$37))+DCF!$H$32*(1+C$4)/($B9-C$4)*(1+$B9)^(-DCF!$H$37)+SUM(Bridge!$B$5:$B$9))/WACC!$B$15 -> 386.41334 | D9: =(SUMPRODUCT(DCF!$D$32:$H$32,(1+$B9)^(-DCF!$D$37:$H$37))+DCF!$H$32*(1+D$4)/($B9-D$4)*(1+$B9)^(-DCF!$H$37)+SUM(Bridge!$B$5:$B$9))/WACC!$B$15 -> 410.56097 | E9: =(SUMPRODUCT(DCF!$D$32:$H$32,(1+$B9)^(-DCF!$D$37:$H$37))+DCF!$H$32*(1+E$4)/($B9-E$4)*(1+$B9)^(-DCF!$H$37)+SUM(Bridge!$B$5:$B$9))/WACC!$B$15 -> 438.65966 | F9: =(SUMPRODUCT(DCF!$D$32:$H$32,(1+$B9)^(-DCF!$D$37:$H$37))+DCF!$H$32*(1+F$4)/($B9-F$4)*(1+$B9)^(-DCF!$H$37)+SUM(Bridge!$B$5:$B$9))/WACC!$B$15 -> 471.76552 | G9: =(SUMPRODUCT(DCF!$D$32:$H$32,(1+$B9)^(-DCF!$D$37:$H$37))+DCF!$H$32*(1+G$4)/($B9-G$4)*(1+$B9)^(-DCF!$H$37)+SUM(Bridge!$B$5:$B$9))/WACC!$B$15 -> 511.3479
B10: =$B$8+0.01 -> 0.091116803 | C10: =(SUMPRODUCT(DCF!$D$32:$H$32,(1+$B10)^(-DCF!$D$37:$H$37))+DCF!$H$32*(1+C$4)/($B10-C$4)*(1+$B10)^(-DCF!$H$37)+SUM(Bridge!$B$5:$B$9))/WACC!$B$15 -> 359.02027 | D10: =(SUMPRODUCT(DCF!$D$32:$H$32,(1+$B10)^(-DCF!$D$37:$H$37))+DCF!$H$32*(1+D$4)/($B10-D$4)*(1+$B10)^(-DCF!$H$37)+SUM(Bridge!$B$5:$B$9))/WACC!$B$15 -> 379.61362 | E10: =(SUMPRODUCT(DCF!$D$32:$H$32,(1+$B10)^(-DCF!$D$37:$H$37))+DCF!$H$32*(1+E$4)/($B10-E$4)*(1+$B10)^(-DCF!$H$37)+SUM(Bridge!$B$5:$B$9))/WACC!$B$15 -> 403.32165 | F10: =(SUMPRODUCT(DCF!$D$32:$H$32,(1+$B10)^(-DCF!$D$37:$H$37))+DCF!$H$32*(1+F$4)/($B10-F$4)*(1+$B10)^(-DCF!$H$37)+SUM(Bridge!$B$5:$B$9))/WACC!$B$15 -> 430.90883 | G10: =(SUMPRODUCT(DCF!$D$32:$H$32,(1+$B10)^(-DCF!$D$37:$H$37))+DCF!$H$32*(1+G$4)/($B10-G$4)*(1+$B10)^(-DCF!$H$37)+SUM(Bridge!$B$5:$B$9))/WACC!$B$15 -> 463.41202
B11: =$B$8+0.015 -> 0.096116803 | C11: =(SUMPRODUCT(DCF!$D$32:$H$32,(1+$B11)^(-DCF!$D$37:$H$37))+DCF!$H$32*(1+C$4)/($B11-C$4)*(1+$B11)^(-DCF!$H$37)+SUM(Bridge!$B$5:$B$9))/WACC!$B$15 -> 335.01588 | D11: =(SUMPRODUCT(DCF!$D$32:$H$32,(1+$B11)^(-DCF!$D$37:$H$37))+DCF!$H$32*(1+D$4)/($B11-D$4)*(1+$B11)^(-DCF!$H$37)+SUM(Bridge!$B$5:$B$9))/WACC!$B$15 -> 352.74332 | E11: =(SUMPRODUCT(DCF!$D$32:$H$32,(1+$B11)^(-DCF!$D$37:$H$37))+DCF!$H$32*(1+E$4)/($B11-E$4)*(1+$B11)^(-DCF!$H$37)+SUM(Bridge!$B$5:$B$9))/WACC!$B$15 -> 372.96348 | F11: =(SUMPRODUCT(DCF!$D$32:$H$32,(1+$B11)^(-DCF!$D$37:$H$37))+DCF!$H$32*(1+F$4)/($B11-F$4)*(1+$B11)^(-DCF!$H$37)+SUM(Bridge!$B$5:$B$9))/WACC!$B$15 -> 396.24188 | G11: =(SUMPRODUCT(DCF!$D$32:$H$32,(1+$B11)^(-DCF!$D$37:$H$37))+DCF!$H$32*(1+G$4)/($B11-G$4)*(1+$B11)^(-DCF!$H$37)+SUM(Bridge!$B$5:$B$9))/WACC!$B$15 -> 423.32912
A13: Implied value per share (EUR) - Exit multiple | C13: Exit EV/EBITDA ->
B14: WACC \ x | C14: =$E$14-2 -> 9 | D14: =$E$14-1 -> 10 | E14: =Assumptions!B31 -> 11 | F14: =$E$14+1 -> 12 | G14: =$E$14+2 -> 13
B15: =$B$18-0.015 -> 0.066116803 | C15: =(SUMPRODUCT(DCF!$D$32:$H$32,(1+$B15)^(-DCF!$D$37:$H$37))+DCF!$H$34*C$14*(1+$B15)^(-DCF!$H$37)+SUM(Bridge!$B$5:$B$9))/WACC!$B$15 -> 474.5453 | D15: =(SUMPRODUCT(DCF!$D$32:$H$32,(1+$B15)^(-DCF!$D$37:$H$37))+DCF!$H$34*D$14*(1+$B15)^(-DCF!$H$37)+SUM(Bridge!$B$5:$B$9))/WACC!$B$15 -> 516.80808 | E15: =(SUMPRODUCT(DCF!$D$32:$H$32,(1+$B15)^(-DCF!$D$37:$H$37))+DCF!$H$34*E$14*(1+$B15)^(-DCF!$H$37)+SUM(Bridge!$B$5:$B$9))/WACC!$B$15 -> 559.07087 | F15: =(SUMPRODUCT(DCF!$D$32:$H$32,(1+$B15)^(-DCF!$D$37:$H$37))+DCF!$H$34*F$14*(1+$B15)^(-DCF!$H$37)+SUM(Bridge!$B$5:$B$9))/WACC!$B$15 -> 601.33365 | G15: =(SUMPRODUCT(DCF!$D$32:$H$32,(1+$B15)^(-DCF!$D$37:$H$37))+DCF!$H$34*G$14*(1+$B15)^(-DCF!$H$37)+SUM(Bridge!$B$5:$B$9))/WACC!$B$15 -> 643.59643
B16: =$B$18-0.01 -> 0.071116803 | C16: =(SUMPRODUCT(DCF!$D$32:$H$32,(1+$B16)^(-DCF!$D$37:$H$37))+DCF!$H$34*C$14*(1+$B16)^(-DCF!$H$37)+SUM(Bridge!$B$5:$B$9))/WACC!$B$15 -> 464.15646 | D16: =(SUMPRODUCT(DCF!$D$32:$H$32,(1+$B16)^(-DCF!$D$37:$H$37))+DCF!$H$34*D$14*(1+$B16)^(-DCF!$H$37)+SUM(Bridge!$B$5:$B$9))/WACC!$B$15 -> 505.44199 | E16: =(SUMPRODUCT(DCF!$D$32:$H$32,(1+$B16)^(-DCF!$D$37:$H$37))+DCF!$H$34*E$14*(1+$B16)^(-DCF!$H$37)+SUM(Bridge!$B$5:$B$9))/WACC!$B$15 -> 546.72752 | F16: =(SUMPRODUCT(DCF!$D$32:$H$32,(1+$B16)^(-DCF!$D$37:$H$37))+DCF!$H$34*F$14*(1+$B16)^(-DCF!$H$37)+SUM(Bridge!$B$5:$B$9))/WACC!$B$15 -> 588.01305 | G16: =(SUMPRODUCT(DCF!$D$32:$H$32,(1+$B16)^(-DCF!$D$37:$H$37))+DCF!$H$34*G$14*(1+$B16)^(-DCF!$H$37)+SUM(Bridge!$B$5:$B$9))/WACC!$B$15 -> 629.29858
B17: =$B$18-0.005 -> 0.076116803 | C17: =(SUMPRODUCT(DCF!$D$32:$H$32,(1+$B17)^(-DCF!$D$37:$H$37))+DCF!$H$34*C$14*(1+$B17)^(-DCF!$H$37)+SUM(Bridge!$B$5:$B$9))/WACC!$B$15 -> 454.04493 | D17: =(SUMPRODUCT(DCF!$D$32:$H$32,(1+$B17)^(-DCF!$D$37:$H$37))+DCF!$H$34*D$14*(1+$B17)^(-DCF!$H$37)+SUM(Bridge!$B$5:$B$9))/WACC!$B$15 -> 494.3802 | E17: =(SUMPRODUCT(DCF!$D$32:$H$32,(1+$B17)^(-DCF!$D$37:$H$37))+DCF!$H$34*E$14*(1+$B17)^(-DCF!$H$37)+SUM(Bridge!$B$5:$B$9))/WACC!$B$15 -> 534.71547 | F17: =(SUMPRODUCT(DCF!$D$32:$H$32,(1+$B17)^(-DCF!$D$37:$H$37))+DCF!$H$34*F$14*(1+$B17)^(-DCF!$H$37)+SUM(Bridge!$B$5:$B$9))/WACC!$B$15 -> 575.05074 | G17: =(SUMPRODUCT(DCF!$D$32:$H$32,(1+$B17)^(-DCF!$D$37:$H$37))+DCF!$H$34*G$14*(1+$B17)^(-DCF!$H$37)+SUM(Bridge!$B$5:$B$9))/WACC!$B$15 -> 615.38601
B18: =WACC!B21 -> 0.081116803 | C18: =(SUMPRODUCT(DCF!$D$32:$H$32,(1+$B18)^(-DCF!$D$37:$H$37))+DCF!$H$34*C$14*(1+$B18)^(-DCF!$H$37)+SUM(Bridge!$B$5:$B$9))/WACC!$B$15 -> 444.20199 | D18: =(SUMPRODUCT(DCF!$D$32:$H$32,(1+$B18)^(-DCF!$D$37:$H$37))+DCF!$H$34*D$14*(1+$B18)^(-DCF!$H$37)+SUM(Bridge!$B$5:$B$9))/WACC!$B$15 -> 483.61312 | E18: =(SUMPRODUCT(DCF!$D$32:$H$32,(1+$B18)^(-DCF!$D$37:$H$37))+DCF!$H$34*E$14*(1+$B18)^(-DCF!$H$37)+SUM(Bridge!$B$5:$B$9))/WACC!$B$15 -> 523.02426 | F18: =(SUMPRODUCT(DCF!$D$32:$H$32,(1+$B18)^(-DCF!$D$37:$H$37))+DCF!$H$34*F$14*(1+$B18)^(-DCF!$H$37)+SUM(Bridge!$B$5:$B$9))/WACC!$B$15 -> 562.43539 | G18: =(SUMPRODUCT(DCF!$D$32:$H$32,(1+$B18)^(-DCF!$D$37:$H$37))+DCF!$H$34*G$14*(1+$B18)^(-DCF!$H$37)+SUM(Bridge!$B$5:$B$9))/WACC!$B$15 -> 601.84653
B19: =$B$18+0.005 -> 0.086116803 | C19: =(SUMPRODUCT(DCF!$D$32:$H$32,(1+$B19)^(-DCF!$D$37:$H$37))+DCF!$H$34*C$14*(1+$B19)^(-DCF!$H$37)+SUM(Bridge!$B$5:$B$9))/WACC!$B$15 -> 434.61919 | D19: =(SUMPRODUCT(DCF!$D$32:$H$32,(1+$B19)^(-DCF!$D$37:$H$37))+DCF!$H$34*D$14*(1+$B19)^(-DCF!$H$37)+SUM(Bridge!$B$5:$B$9))/WACC!$B$15 -> 473.13149 | E19: =(SUMPRODUCT(DCF!$D$32:$H$32,(1+$B19)^(-DCF!$D$37:$H$37))+DCF!$H$34*E$14*(1+$B19)^(-DCF!$H$37)+SUM(Bridge!$B$5:$B$9))/WACC!$B$15 -> 511.64378 | F19: =(SUMPRODUCT(DCF!$D$32:$H$32,(1+$B19)^(-DCF!$D$37:$H$37))+DCF!$H$34*F$14*(1+$B19)^(-DCF!$H$37)+SUM(Bridge!$B$5:$B$9))/WACC!$B$15 -> 550.15607 | G19: =(SUMPRODUCT(DCF!$D$32:$H$32,(1+$B19)^(-DCF!$D$37:$H$37))+DCF!$H$34*G$14*(1+$B19)^(-DCF!$H$37)+SUM(Bridge!$B$5:$B$9))/WACC!$B$15 -> 588.66836
B20: =$B$18+0.01 -> 0.091116803 | C20: =(SUMPRODUCT(DCF!$D$32:$H$32,(1+$B20)^(-DCF!$D$37:$H$37))+DCF!$H$34*C$14*(1+$B20)^(-DCF!$H$37)+SUM(Bridge!$B$5:$B$9))/WACC!$B$15 -> 425.28844 | D20: =(SUMPRODUCT(DCF!$D$32:$H$32,(1+$B20)^(-DCF!$D$37:$H$37))+DCF!$H$34*D$14*(1+$B20)^(-DCF!$H$37)+SUM(Bridge!$B$5:$B$9))/WACC!$B$15 -> 462.92637 | E20: =(SUMPRODUCT(DCF!$D$32:$H$32,(1+$B20)^(-DCF!$D$37:$H$37))+DCF!$H$34*E$14*(1+$B20)^(-DCF!$H$37)+SUM(Bridge!$B$5:$B$9))/WACC!$B$15 -> 500.56431 | F20: =(SUMPRODUCT(DCF!$D$32:$H$32,(1+$B20)^(-DCF!$D$37:$H$37))+DCF!$H$34*F$14*(1+$B20)^(-DCF!$H$37)+SUM(Bridge!$B$5:$B$9))/WACC!$B$15 -> 538.20225 | G20: =(SUMPRODUCT(DCF!$D$32:$H$32,(1+$B20)^(-DCF!$D$37:$H$37))+DCF!$H$34*G$14*(1+$B20)^(-DCF!$H$37)+SUM(Bridge!$B$5:$B$9))/WACC!$B$15 -> 575.84019
B21: =$B$18+0.015 -> 0.096116803 | C21: =(SUMPRODUCT(DCF!$D$32:$H$32,(1+$B21)^(-DCF!$D$37:$H$37))+DCF!$H$34*C$14*(1+$B21)^(-DCF!$H$37)+SUM(Bridge!$B$5:$B$9))/WACC!$B$15 -> 416.20188 | D21: =(SUMPRODUCT(DCF!$D$32:$H$32,(1+$B21)^(-DCF!$D$37:$H$37))+DCF!$H$34*D$14*(1+$B21)^(-DCF!$H$37)+SUM(Bridge!$B$5:$B$9))/WACC!$B$15 -> 452.98918 | E21: =(SUMPRODUCT(DCF!$D$32:$H$32,(1+$B21)^(-DCF!$D$37:$H$37))+DCF!$H$34*E$14*(1+$B21)^(-DCF!$H$37)+SUM(Bridge!$B$5:$B$9))/WACC!$B$15 -> 489.77647 | F21: =(SUMPRODUCT(DCF!$D$32:$H$32,(1+$B21)^(-DCF!$D$37:$H$37))+DCF!$H$34*F$14*(1+$B21)^(-DCF!$H$37)+SUM(Bridge!$B$5:$B$9))/WACC!$B$15 -> 526.56377 | G21: =(SUMPRODUCT(DCF!$D$32:$H$32,(1+$B21)^(-DCF!$D$37:$H$37))+DCF!$H$34*G$14*(1+$B21)^(-DCF!$H$37)+SUM(Bridge!$B$5:$B$9))/WACC!$B$15 -> 563.35106
A23: Check: base cells E8 / E18 equal Bridge!B12 / C12 (difference should be 0) | E23: =E8-Bridge!B12 -> 0 | F23: =E18-Bridge!C12 -> 0

Sheet Trading_Comps
B1: LVMH - Trading Comparables and Sum-of-the-Parts (2026E)
A3: Company | B3: Segment reference | C3: Share price (local) | D3: Ccy | E3: FX (EUR per 1 local) | F3: Shares (m) | G3: Market cap (EUR m) | H3: Net debt / (cash) (EUR m) | I3: EV (EUR m) | J3: Revenue 26E (EUR m) | K3: EBIT 26E (EUR m) | L3: Net income 26E (EUR m) | M3: EV/EBIT | N3: EV/Sales | O3: P/E | P3: Basis & source
A4: Hermes | B4: Luxury core / F&LG | C4: 1276.5 | D4: EUR | E4: 1 | F4: 104.742 | G4: =C4*E4*F4 -> 133703.16 | H4: -12773 | I4: =G4+H4 -> 120930.16 | J4: 16766 | K4: 6721 | L4: 4632 | M4: =IFERROR(I4/K4,0) -> 17.992882 | N4: =IFERROR(I4/J4,0) -> 7.2128214 | O4: =IFERROR(G4/L4,0) -> 28.865104 | P4: Price ~26-Oct-26 (Zonebourse). Net cash Dec-25 (restated). 2026E: Zonebourse consensus
A5: Richemont | B5: Luxury core / W&J | C5: 164.28 | D5: CHF | E5: =1/Data!$B$29 -> 1.0642827 | F5: 589.8 | G5: =C5*E5*F5 -> 103120.84 | H5: -8496 | I5: =G5+H5 -> 94624.843 | J5: 25176 | K5: 5536 | L5: 4430 | M5: =IFERROR(I5/K5,0) -> 17.092638 | N5: =IFERROR(I5/J5,0) -> 3.7585336 | O5: =IFERROR(G5/L5,0) -> 23.277843 | P5: Price ~26-Oct-26. A-share equivalent (537.6m A + 522m B/10). Net cash Mar-26. FY Mar-27E consensus
A6: Kering | B6: Luxury core / F&LG | C6: 179.66 | D6: EUR | E6: 1 | F6: 122.6 | G6: =C6*E6*F6 -> 22026.316 | H6: 8759 | I6: =G6+H6 -> 30785.316 | J6: 14781 | K6: 1871 | L6: 646 | M6: =IFERROR(I6/K6,0) -> 16.453937 | N6: =IFERROR(I6/J6,0) -> 2.0827627 | O6: =IFERROR(G6/L6,0) -> 34.096464 | P6: Price ~26-Oct-26 (post Q3 -11%). Net debt and 2026E: Zonebourse consensus
A7: Prada | B7: Luxury core / F&LG | C7: 40.88 | D7: HKD | E7: =1/(Data!$B$28*Data!$B$30) -> 0.11430557 | F7: 2559.6 | G7: =C7*E7*F7 -> 11960.529 | H7: 693 | I7: =G7+H7 -> 12653.529 | J7: 6468 | K7: 1227 | L7: 783 | M7: =IFERROR(I7/K7,0) -> 10.312575 | N7: =IFERROR(I7/J7,0) -> 1.9563279 | O7: =IFERROR(G7/L7,0) -> 15.27526 | P7: Price Oct-26 (Simply Wall St). Net debt Jun-26 (H1 release). 2026E: Zonebourse consensus
A8: Moncler | B8: Luxury core / F&LG | C8: 42.32 | D8: EUR | E8: 1 | F8: 272 | G8: =C8*E8*F8 -> 11511.04 | H8: -1112 | I8: =G8+H8 -> 10399.04 | J8: 3283 | K8: 967 | L8: 652 | M8: =IFERROR(I8/K8,0) -> 10.753919 | N8: =IFERROR(I8/J8,0) -> 3.1675419 | O8: =IFERROR(G8/L8,0) -> 17.654969 | P8: Price ~26-Oct-26. Net cash Jun-26 excl. leases (H1 release). 2026E: Zonebourse consensus
A9: Pernod Ricard | B9: W&S reference | C9: 67.36 | D9: EUR | E9: 1 | F9: 251.59 | G9: =C9*E9*F9 -> 16947.102 | H9: 10662 | I9: =G9+H9 -> 27609.102 | J9: 9404 | K9: 2423 | L9: 1476 | M9: =IFERROR(I9/K9,0) -> 11.394594 | N9: =IFERROR(I9/J9,0) -> 2.9358892 | O9: =IFERROR(G9/L9,0) -> 11.481777 | P9: Price 16-Oct-26. FY Jun-26A: sales, ROC, recurring net income, net debt (FY results 27-Aug-26)
A10: Diageo | B10: W&S reference | C10: 92.09 | D10: USD | E10: =1/Data!$B$28 -> 0.89158345 | F10: 555.6 | G10: =C10*E10*F10 -> 45618.049 | H10: =B49*1/Data!$B$28 -> 18277.461 | I10: =G10+H10 -> 63895.51 | J10: =C49*1/Data!$B$28 -> 17513.374 | K10: =D49*1/Data!$B$28 -> 5061.5193 | L10: =E49*1/Data!$B$28 -> 3277.4608 | M10: =IFERROR(I10/K10,0) -> 12.623781 | N10: =IFERROR(I10/J10,0) -> 3.6483839 | O10: =IFERROR(G10/L10,0) -> 13.918717 | P10: ADR price Oct-26 (stockanalysis). ADR-equivalent shares (2,222m ord / 4). FY Jun-26A pre-exceptional
A11: L'Oreal | B11: P&C reference | C11: 388.6 | D11: EUR | E11: 1 | F11: 533.8 | G11: =C11*E11*F11 -> 207434.68 | H11: 8149 | I11: =G11+H11 -> 215583.68 | J11: 46965 | K11: 9600 | L11: 7019 | M11: =IFERROR(I11/K11,0) -> 22.456633 | N11: =IFERROR(I11/J11,0) -> 4.5903051 | O11: =IFERROR(G11/L11,0) -> 29.55331 | P11: Price Oct-26 (Zonebourse). 2026E consensus; net debt incl. Kering Beaute acquisition
A12: Ulta Beauty | B12: SR reference | C12: 545.26 | D12: USD | E12: =1/Data!$B$28 -> 0.89158345 | F12: 42.76 | G12: =C12*E12*F12 -> 20787.551 | H12: =B50*1/Data!$B$28 -> 112.33951 | I12: =G12+H12 -> 20899.891 | J12: =C50*1/Data!$B$28 -> 10689.194 | K12: =D50*1/Data!$B$28 -> 1462.1969 | L12: =E50*1/Data!$B$28 -> 1114.4793 | M12: =IFERROR(I12/K12,0) -> 14.293486 | N12: =IFERROR(I12/J12,0) -> 1.9552354 | O12: =IFERROR(G12/L12,0) -> 18.652254 | P12: Price 5-Oct-26 (Google Finance). Net debt Aug-26 (8-K). FY Jan-27E from guidance midpoint
A13: LVMH (self) | B13: Axone estimates | C13: =Data!$B$2 -> 388.1 | D13: EUR | E13: 1 | F13: =WACC!B15 -> 494.958 | G13: =C13*E13*F13 -> 192093.2 | H13: =Data!$B$12+Data!$B$13+Data!$B$14-Data!$B$15-Data!$B$16 -> 13068 | I13: =G13+H13 -> 205161.2 | J13: =DCF!C11 -> 79903.46 | K13: =DCF!C21 -> 17199.101 | L13: =DCF!B59 -> 11019.371 | M13: =I13/K13 -> 11.9286 | N13: =I13/J13 -> 2.5676135 | O13: =G13/L13 -> 17.43232 | P13: Axone FY26E (DCF tab); EV includes minorities and purchase commitments
A15: Median (core luxury peers) | M15: =MEDIAN(M4:M8) -> 16.453937 | N15: =MEDIAN(N4:N8) -> 3.1675419 | O15: =MEDIAN(O4:O8) -> 23.277843
A16: Mean (core luxury peers) | M16: =AVERAGE(M4:M8) -> 14.52119 | N16: =AVERAGE(N4:N8) -> 3.6355975 | O16: =AVERAGE(O4:O8) -> 23.833928
A17: Q1 (core luxury peers) | M17: =QUARTILE(M4:M8,1) -> 10.753919 | N17: =QUARTILE(N4:N8,1) -> 2.0827627 | O17: =QUARTILE(O4:O8,1) -> 17.654969
A18: Q3 (core luxury peers) | M18: =QUARTILE(M4:M8,3) -> 17.092638 | N18: =QUARTILE(N4:N8,3) -> 3.7585336 | O18: =QUARTILE(O4:O8,3) -> 28.865104
A19: LVMH premium / (discount) to core median | M19: =M13/M15-1 -> -0.27503063 | N19: =N13/N15-1 -> -0.18939873 | O19: =O13/O15-1 -> -0.25111959
A21: Implied value - group EV/EBIT (core luxury median)
A22: LVMH PRO 2026E (EUR m) | B22: =DCF!C21 -> 17199.101
A23: Applied EV/EBIT (median) | B23: =M15 -> 16.453937
A24: Implied EV (EUR m) | B24: =B22*B23 -> 282992.92
A25: (-) Net debt & minorities, (+) associates & financial assets (30-Jun-26) | B25: =-Data!$B$12-Data!$B$13-Data!$B$14+Data!$B$15+Data!$B$16 -> -13068
A26: Implied equity value (EUR m) | B26: =B24+B25 -> 269924.92
A27: Implied value per share (EUR) | B27: =B26/WACC!$B$15 -> 545.34915
A28: Implied value - Q1 multiple (EUR) | B28: =(B22*M17+B25)/WACC!$B$15 -> 347.28148
A29: Implied value - Q3 multiple (EUR) | B29: =(B22*M18+B25)/WACC!$B$15 -> 567.54311
A31: Sum-of-the-parts - EV/EBIT 2026E by business group (35% leg of the target price)
A32: Business group | B32: Peer reference | C32: PRO 26E (EUR m) | D32: Peer EV/EBIT | E32: Premium / (discount) | F32: Applied multiple | G32: EV (EUR m) | H32: % of EV | I32: Rationale
A33: Wines & Spirits | B33: Pernod Ricard, Diageo | C33: =DCF!C15 -> 1135.7103 | D33: =MEDIAN(M9:M10) -> 12.009188 | E33: 0 | F33: =D33*(1+E33) -> 12.009188 | G33: =C33*F33 -> 13638.958 | H33: =G33/$G$39 -> 0.057879079 | I33: Pure spirits peers, both at cyclical lows
A34: Fashion & Leather Goods | B34: Hermes, Kering, Prada, Moncler | C34: =DCF!C16 -> 12288.838 | D34: =MEDIAN(M4,M6,M7,M8) -> 13.603928 | E34: 0 | F34: =D34*(1+E34) -> 13.603928 | G34: =C34*F34 -> 167176.46 | H34: =G34/$G$39 -> 0.70943984 | I34: Louis Vuitton and Dior are the two largest luxury brands; no discount
A35: Perfumes & Cosmetics | B35: L'Oreal | C35: =DCF!C17 -> 769.3746 | D35: =M11 -> 22.456633 | E35: -0.2 | F35: =D35*(1+E35) -> 17.965307 | G35: =C35*F35 -> 13822.051 | H35: =G35/$G$39 -> 0.058656064 | I35: LVMH P&C margin (~10%) is half L'Oreal's; prestige-only exposure
A36: Watches & Jewelry | B36: Richemont | C36: =DCF!C18 -> 1652.6085 | D36: =M5 -> 17.092638 | E36: -0.15 | F36: =D36*(1+E36) -> 14.528742 | G36: =C36*F36 -> 24010.323 | H36: =G36/$G$39 -> 0.10189161 | I36: Margin ~15% vs Richemont Jewellery Maisons 30.5%; Tiffany still in turnaround
A37: Selective Retailing | B37: Ulta Beauty | C37: =DCF!C19 -> 1832.57 | D37: =M12 -> 14.293486 | E37: -0.1 | F37: =D37*(1+E37) -> 12.864138 | G37: =C37*F37 -> 23574.433 | H37: =G37/$G$39 -> 0.10004184 | I37: Sephora is best-in-class but DFS travel retail drags
A38: Other activities & eliminations | B38: Capitalised at the weighted multiple | C38: =DCF!C20 -> -480 | D38: =SUMPRODUCT(F33:F37,C33:C37)/SUM(C33:C37) -> 13.701049 | E38: 0 | F38: =D38*(1+E38) -> 13.701049 | G38: =C38*F38 -> -6576.5035 | H38: =G38/$G$39 -> -0.027908436 | I38: Holding costs reduce value at the group's blended multiple
A39: Total enterprise value | C39: =SUM(C33:C38) -> 17199.101 | F39: =G39/C39 -> 13.701049 | G39: =SUM(G33:G38) -> 235645.72 | H39: =SUM(H33:H38) -> 1
A40: (-) Net debt & minorities, (+) associates & financial assets (30-Jun-26) | G40: =B25 -> -13068
A41: SOTP equity value (EUR m) | G41: =G39+G40 -> 222577.72
A42: SOTP value per share (EUR) | G42: =G41/WACC!$B$15 -> 449.69012
A43: SOTP - low (all multiples -1.0x) | G43: =(G39-C39*1+G40)/WACC!$B$15 -> 414.94152
A44: SOTP - high (all multiples +1.0x) | G44: =(G39+C39*1+G40)/WACC!$B$15 -> 484.43873
...

Sheet Precedent_Transactions
B1: LVMH - Precedent Transactions (luxury)
A3: Date | B3: Acquirer | C3: Target | D3: Deal EV (m) | E3: Ccy | F3: EV / LTM EBITDA | G3: Scale-relevant (EV >= EUR 5bn) | H3: Multiple if scale-relevant | I3: Segment | J3: Source
A4: 2023 | B4: Kering | C4: Creed | D4: 3500 | E4: EUR | F4: 23.3 | G4: N | H4: =IF(G4="Y",F4,"") | I4: P&C | J4: FT via BeautyMatter: EV EUR 3.5bn, EBITDA EUR 150m
A5: 2023 | B5: Tapestry | C5: Capri Holdings (terminated 2024) | D5: 8500 | E5: USD | F5: 9 | G5: Y | H5: =IF(G5="Y",F5,"") -> 9 | I5: F&LG | J5: Business of Fashion: 9x adjusted EBITDA
A6: 2021 | B6: LVMH | C6: Tiffany & Co. | D6: 15800 | E6: USD | F6: 18.5 | G6: Y | H6: =IF(G6="Y",F6,"") -> 18.5 | I6: W&J | J6: Stockopine: implied EV/EBITDA at revised USD 15.8bn price
A7: 2018 | B7: Michael Kors | C7: Versace | D7: 1830 | E7: EUR | F7: 22 | G7: N | H7: =IF(G7="Y",F7,"") | I7: F&LG | J7: BSIC / Wells Fargo: 2.5x sales, 22x EBITDA
A8: 2017 | B8: Michael Kors | C8: Jimmy Choo | D8: 1158 | E8: EUR | F8: 17.5 | G8: N | H8: =IF(G8="Y",F8,"") | I8: F&LG | J8: Tiffany DEFM14A (SEC, 2020); EV per KPMG Advisory
A9: 2017 | B9: Coach | C9: Kate Spade | D9: 2400 | E9: USD | F9: 10.4 | G9: N | H9: =IF(G9="Y",F9,"") | I9: F&LG | J9: Tiffany DEFM14A (SEC, 2020)
A10: 2017 | B10: LVMH | C10: Christian Dior Couture | D10: 6500 | E10: EUR | F10: 15.6 | G10: Y | H10: =IF(G10="Y",F10,"") -> 15.6 | I10: F&LG | J10: KPMG Advisory; Tiffany DEFM14A
A11: 2016 | B11: Samsonite | C11: Tumi | D11: 1800 | E11: USD | F11: 13.6 | G11: N | H11: =IF(G11="Y",F11,"") | I11: F&LG | J11: Tiffany DEFM14A (SEC, 2020)
A12: 2013 | B12: LVMH | C12: Loro Piana (80%) | D12: 2700 | E12: EUR | F12: 21 | G12: N | H12: =IF(G12="Y",F12,"") | I12: F&LG | J12: Tiffany DEFM14A; EV grossed up from EUR 2.0bn for 80%
A13: 2013 | B13: Swatch Group | C13: Harry Winston | D13: 1000 | E13: USD | F13: 24.4 | G13: N | H13: =IF(G13="Y",F13,"") | I13: W&J | J13: Tiffany DEFM14A (SEC, 2020)
A14: 2012 | B14: Mayhoola | C14: Valentino | D14: 700 | E14: EUR | F14: 31.6 | G14: N | H14: =IF(G14="Y",F14,"") | I14: F&LG | J14: KPMG Advisory Italy research
A15: 2011 | B15: LVMH | C15: Bulgari | D15: 4300 | E15: EUR | F15: 25.8 | G15: N | H15: =IF(G15="Y",F15,"") | I15: W&J | J15: Tiffany DEFM14A (SEC, 2020)
A17: Median - all deals | B17: =MEDIAN(F4:F15) -> 19.75
A18: Mean - all deals | B18: =AVERAGE(F4:F15) -> 19.391667
A19: Q1 - all deals | B19: =QUARTILE(F4:F15,1) -> 15.1
A20: Q3 - all deals | B20: =QUARTILE(F4:F15,3) -> 23.575
A21: Median - scale-relevant deals (applied) | B21: =MEDIAN(H4:H15) -> 15.6
A22: Min - scale-relevant deals | B22: =MIN(H4:H15) -> 9
A23: Max - scale-relevant deals | B23: =MAX(H4:H15) -> 18.5
A25: Implied value (control basis)
A26: LVMH EBITDA FY26E, pre-IFRS 16 (EUR m) | B26: =DCF!C34 -> 21274.177
A27: Applied EV/EBITDA (scale-relevant median) | B27: =B21 -> 15.6
A28: Implied EV (EUR m) | B28: =B26*B27 -> 331877.17
A29: (-) Net debt & minorities, (+) associates & financial assets (30-Jun-26) | B29: =Trading_Comps!B25 -> -13068
A30: Implied equity value (EUR m) | B30: =B28+B29 -> 318809.17
A31: Implied value per share (EUR) | B31: =B30/WACC!$B$15 -> 644.11358
A32: Implied value - min multiple (EUR) | B32: =(B26*B22+B29)/WACC!$B$15 -> 360.43381
A33: Implied value - max multiple (EUR) | B33: =(B26*B23+B29)/WACC!$B$15 -> 768.76075
A35: Only deals with EV >= EUR 5bn are applied: small, fast-growing brands command scarcity premia (Valentino 31.6x, Bulgari 25.8x) that are not transferable to an EUR 80bn group. The full median is shown for reference.

Sheet Football_Field
B1: LVMH - Valuation Summary (EUR per share)
A3: Methodology | B3: Low | C3: High | D3: Basis
A4: DCF - Gordon growth | B4: =Sensitivity!E9 -> 438.65966 | C4: =Sensitivity!E7 -> 530.12174 | D4: WACC +/- 0.5%, g at base
A5: DCF - Exit multiple | B5: =Sensitivity!E19 -> 511.64378 | C5: =Sensitivity!E17 -> 534.71547 | D5: WACC +/- 0.5%, exit multiple at base
A6: Trading comps - EV/EBIT | B6: =Trading_Comps!B28 -> 347.28148 | C6: =Trading_Comps!B29 -> 567.54311 | D6: Core luxury peers, Q1-Q3 multiple
A7: Sum-of-the-parts | B7: =Trading_Comps!G43 -> 414.94152 | C7: =Trading_Comps!G44 -> 484.43873 | D7: Segment multiples -/+ 1.0x
A8: Precedent transactions | B8: =Precedent_Transactions!B32 -> 360.43381 | C8: =Precedent_Transactions!B33 -> 768.76075 | D8: Scale-relevant deals, min-max
A9: 52-week trading range | B9: =Data!$B$7 -> 375.65 | C9: =Data!$B$8 -> 654.7 | D9: Euronext
A10: Analyst price targets | B10: =Data!$B$26 -> 415 | C10: =Data!$B$27 -> 590 | D10: MarketScreener, 27 analysts
A12: Current share price | B12: =WACC!B14 -> 388.1
A13: Blended target price | B13: =Cover!B16 -> 504.84187

Sheet Chart_Data
A1: Chart Data - staging area (green = links, black = formulas)
A3: FOOTBALL FIELD
A4: Method | B4: Low | C4: High | D4: Low_base | E4: Range
A5: =Football_Field!A4 -> DCF - Gordon growth | B5: =Football_Field!B4 -> 438.65966 | C5: =Football_Field!C4 -> 530.12174 | D5: =B5 -> 438.65966 | E5: =C5-B5 -> 91.462085
A6: =Football_Field!A5 -> DCF - Exit multiple | B6: =Football_Field!B5 -> 511.64378 | C6: =Football_Field!C5 -> 534.71547 | D6: =B6 -> 511.64378 | E6: =C6-B6 -> 23.071692
A7: =Football_Field!A6 -> Trading comps - EV/EBIT | B7: =Football_Field!B6 -> 347.28148 | C7: =Football_Field!C6 -> 567.54311 | D7: =B7 -> 347.28148 | E7: =C7-B7 -> 220.26164
A8: =Football_Field!A7 -> Sum-of-the-parts | B8: =Football_Field!B7 -> 414.94152 | C8: =Football_Field!C7 -> 484.43873 | D8: =B8 -> 414.94152 | E8: =C8-B8 -> 69.497214
A9: =Football_Field!A8 -> Precedent transactions | B9: =Football_Field!B8 -> 360.43381 | C9: =Football_Field!C8 -> 768.76075 | D9: =B9 -> 360.43381 | E9: =C9-B9 -> 408.32694
A10: =Football_Field!A9 -> 52-week trading range | B10: =Football_Field!B9 -> 375.65 | C10: =Football_Field!C9 -> 654.7 | D10: =B10 -> 375.65 | E10: =C10-B10 -> 279.05
A11: =Football_Field!A10 -> Analyst price targets | B11: =Football_Field!B10 -> 415 | C11: =Football_Field!C10 -> 590 | D11: =B11 -> 415 | E11: =C11-B11 -> 175
A14: EV -> EQUITY BRIDGE (Gordon, EUR m)
A15: Step | B15: Base | C15: Delta
A16: EV | B16: 0 | C16: =Bridge!B4 -> 247327.28
A17: (-) Net debt | B17: =Bridge!B4+Bridge!B5 -> 242555.73 | C17: =-Bridge!B5 -> 4771.5468
A18: (-) Purchase commitments | B18: =B17+Bridge!B6 -> 236139.73 | C18: =-Bridge!B6 -> 6416
A19: (-) Minorities | B19: =B18+Bridge!B7 -> 234540.73 | C19: =-Bridge!B7 -> 1599
A20: (+) Associates & fin. assets | B20: =B19 -> 234540.73 | C20: =Bridge!B8+Bridge!B9 -> 3192
A21: Equity | B21: 0 | C21: =Bridge!B10 -> 237732.73
A23: WACC BUILD-UP
A24: Step | B24: Base | C24: Delta
A25: Risk-free (Bund) | B25: 0 | C25: =WACC!B5 -> 0.0337
A26: + Beta x ERP | B26: =C25 -> 0.0337 | C26: =WACC!B7*WACC!B6 -> 0.049841
A27: Cost of equity | B27: 0 | C27: =WACC!B8 -> 0.083541
A28: WACC | B28: 0 | C28: =WACC!B21 -> 0.081116803
A30: VALUATION BY METHOD (EUR / share)
A31: Method | B31: Price
A32: DCF Gordon | B32: =Bridge!B12 -> 480.3089
A33: DCF Exit | B33: =Bridge!C12 -> 523.02426
A34: Trading comps (group) | B34: =Trading_Comps!B27 -> 545.34915
A35: Sum-of-the-parts | B35: =Trading_Comps!G42 -> 449.69012
A36: Precedents | B36: =Precedent_Transactions!B31 -> 644.11358
A37: Blended target | B37: =Cover!B16 -> 504.84187
A38: Current price | B38: =WACC!B14 -> 388.1
A40: NET SALES BY BUSINESS GROUP (EUR m)
A41: Group \ Year | B41: FY23A | C41: FY24A | D41: FY25A | E41: FY26E | F41: FY27E | G41: FY28E | H41: FY29E | I41: FY30E | J41: FY31E
A42: W&S | B42: =Income_Statement!B46 -> 6602 | C42: =Income_Statement!C46 -> 5862 | D42: =Income_Statement!D46 -> 5358 | E42: =DCF!C5 -> 5540.05 | F42: =DCF!D5 -> 5706.2515 | G42: =DCF!E5 -> 5934.5016 | H42: =DCF!F5 -> 6171.8816 | I42: =DCF!G5 -> 6418.7569 | J42: =DCF!H5 -> 6675.5072
A43: F&LG | B43: =Income_Statement!B47 -> 42169 | C43: =Income_Statement!C47 -> 41060 | D43: =Income_Statement!D47 -> 37770 | E43: =DCF!C6 -> 36143.64 | F43: =DCF!D6 -> 36505.076 | G43: =DCF!E6 -> 38330.33 | H43: =DCF!F6 -> 40630.15 | I43: =DCF!G6 -> 43067.959 | J43: =DCF!H6 -> 45221.357
A44: P&C | B44: =Income_Statement!B48 -> 8271 | C44: =Income_Statement!C48 -> 8418 | D44: =Income_Statement!D48 -> 8174 | E44: =DCF!C7 -> 8098.68 | F44: =DCF!D7 -> 8341.6404 | G44: =DCF!E7 -> 8675.306 | H44: =DCF!F7 -> 9022.3183 | I44: =DCF!G7 -> 9383.211 | J44: =DCF!H7 -> 9758.5394
A45: W&J | B45: =Income_Statement!B49 -> 10902 | C45: =Income_Statement!C49 -> 10577 | D45: =Income_Statement!D49 -> 10486 | E45: =DCF!C8 -> 11017.39 | F45: =DCF!D8 -> 11678.433 | G45: =DCF!E8 -> 12379.139 | H45: =DCF!F8 -> 13121.888 | I45: =DCF!G8 -> 13777.982 | J45: =DCF!H8 -> 14466.881
A46: SR | B46: =Income_Statement!B50 -> 17885 | C46: =Income_Statement!C50 -> 18262 | D46: =Income_Statement!D50 -> 18348 | E46: =DCF!C9 -> 18325.7 | F46: =DCF!D9 -> 18692.214 | G46: =DCF!E9 -> 19626.825 | H46: =DCF!F9 -> 20608.166 | I46: =DCF!G9 -> 21638.574 | J46: =DCF!H9 -> 22504.117
...
